Workbook

Sheet Gruppespill
B2: Dato | C2: Kl. | D2: Gruppe A | G2: Resultat | J2: Erling | N2: Rune | R2: Håkon | V2: Geir | Z2: Tore | AD2: Tor Arne
B3: 46184 | C3: 21:00 | D3: Mexico | E3: - | F3: Sør-Afrika | H3: - | J3: 2 | K3: - | L3: 0 | M3: =IF(ISBLANK($I3)=TRUE,"",IF(SIGN(J3-L3)=SIGN($G3-$I3),1,0)+IF(J3=$G3,IF(L3=$I3,2,0),0)) | N3: 2 | O3: - | P3: 0 | Q3: =IF(ISBLANK($I3)=TRUE,"",IF(SIGN(N3-P3)=SIGN($G3-$I3),1,0)+IF(N3=$G3,IF(P3=$I3,2,0),0)) | R3: 2 | S3: - | T3: 0 | U3: =IF(ISBLANK($I3)=TRUE,"",IF(SIGN(R3-T3)=SIGN($G3-$I3),1,0)+IF(R3=$G3,IF(T3=$I3,2,0),0)) | W3: - | Y3: =IF(ISBLANK($I3)=TRUE,"",IF(SIGN(V3-X3)=SIGN($G3-$I3),1,0)+IF(V3=$G3,IF(X3=$I3,2,0),0)) | Z3: 2 | AA3: - | AB3: 1 | AC3: =IF(ISBLANK($I3)=TRUE,"",IF(SIGN(Z3-AB3)=SIGN($G3-$I3),1,0)+IF(Z3=$G3,IF(AB3=$I3,2,0),0)) | AD3: 3 | AE3: - | AF3: 1 | AG3: =IF(ISBLANK($I3)=TRUE,"",IF(SIGN(AD3-AF3)=SIGN($G3-$I3),1,0)+IF(AD3=$G3,IF(AF3=$I3,2,0),0))
B4: 46185 | C4: 04:00 | D4: Sør-Korea | E4: - | F4: Tsjekkia | H4: - | J4: 1 | K4: - | L4: 1 | M4: =IF(ISBLANK($G4)=TRUE,"",IF(SIGN(J4-L4)=SIGN($G4-$I4),1,0)+IF(J4=$G4,IF(L4=$I4,2,0),0)) | N4: 2 | O4: - | P4: 1 | Q4: =IF(ISBLANK($G4)=TRUE,"",IF(SIGN(N4-P4)=SIGN($G4-$I4),1,0)+IF(N4=$G4,IF(P4=$I4,2,0),0)) | R4: 2 | S4: - | T4: 1 | U4: =IF(ISBLANK($G4)=TRUE,"",IF(SIGN(R4-T4)=SIGN($G4-$I4),1,0)+IF(R4=$G4,IF(T4=$I4,2,0),0)) | W4: - | Y4: =IF(ISBLANK($G4)=TRUE,"",IF(SIGN(V4-X4)=SIGN($G4-$I4),1,0)+IF(V4=$G4,IF(X4=$I4,2,0),0)) | Z4: 1 | AA4: - | AB4: 1 | AC4: =IF(ISBLANK($G4)=TRUE,"",IF(SIGN(Z4-AB4)=SIGN($G4-$I4),1,0)+IF(Z4=$G4,IF(AB4=$I4,2,0),0)) | AD4: 1 | AE4: - | AF4: 1 | AG4: =IF(ISBLANK($G4)=TRUE,"",IF(SIGN(AD4-AF4)=SIGN($G4-$I4),1,0)+IF(AD4=$G4,IF(AF4=$I4,2,0),0))
B5: 46191 | C5: 18:00 | D5: Tsjekkia | E5: - | F5: Sør-Afrika | H5: - | J5: 2 | K5: - | L5: 0 | M5: =IF(ISBLANK($G5)=TRUE,"",IF(SIGN(J5-L5)=SIGN($G5-$I5),1,0)+IF(J5=$G5,IF(L5=$I5,2,0),0)) | N5: 1 | O5: - | P5: 0 | Q5: =IF(ISBLANK($G5)=TRUE,"",IF(SIGN(N5-P5)=SIGN($G5-$I5),1,0)+IF(N5=$G5,IF(P5=$I5,2,0),0)) | R5: 1 | S5: - | T5: 1 | U5: =IF(ISBLANK($G5)=TRUE,"",IF(SIGN(R5-T5)=SIGN($G5-$I5),1,0)+IF(R5=$G5,IF(T5=$I5,2,0),0)) | W5: - | Y5: =IF(ISBLANK($G5)=TRUE,"",IF(SIGN(V5-X5)=SIGN($G5-$I5),1,0)+IF(V5=$G5,IF(X5=$I5,2,0),0)) | Z5: 1 | AA5: - | AB5: 3 | AC5: =IF(ISBLANK($G5)=TRUE,"",IF(SIGN(Z5-AB5)=SIGN($G5-$I5),1,0)+IF(Z5=$G5,IF(AB5=$I5,2,0),0)) | AD5: 1 | AE5: - | AF5: 0 | AG5: =IF(ISBLANK($G5)=TRUE,"",IF(SIGN(AD5-AF5)=SIGN($G5-$I5),1,0)+IF(AD5=$G5,IF(AF5=$I5,2,0),0))
B6: 46192 | C6: 03:00 | D6: Mexico | E6: - | F6: Sør-Korea | H6: - | J6: 1 | K6: - | L6: 0 | M6: =IF(ISBLANK($G6)=TRUE,"",IF(SIGN(J6-L6)=SIGN($G6-$I6),1,0)+IF(J6=$G6,IF(L6=$I6,2,0),0)) | N6: 2 | O6: - | P6: 1 | Q6: =IF(ISBLANK($G6)=TRUE,"",IF(SIGN(N6-P6)=SIGN($G6-$I6),1,0)+IF(N6=$G6,IF(P6=$I6,2,0),0)) | R6: 2 | S6: - | T6: 1 | U6: =IF(ISBLANK($G6)=TRUE,"",IF(SIGN(R6-T6)=SIGN($G6-$I6),1,0)+IF(R6=$G6,IF(T6=$I6,2,0),0)) | W6: - | Y6: =IF(ISBLANK($G6)=TRUE,"",IF(SIGN(V6-X6)=SIGN($G6-$I6),1,0)+IF(V6=$G6,IF(X6=$I6,2,0),0)) | Z6: 2 | AA6: - | AB6: 0 | AC6: =IF(ISBLANK($G6)=TRUE,"",IF(SIGN(Z6-AB6)=SIGN($G6-$I6),1,0)+IF(Z6=$G6,IF(AB6=$I6,2,0),0)) | AD6: 2 | AE6: - | AF6: 0 | AG6: =IF(ISBLANK($G6)=TRUE,"",IF(SIGN(AD6-AF6)=SIGN($G6-$I6),1,0)+IF(AD6=$G6,IF(AF6=$I6,2,0),0))
B7: 46198 | C7: 03:00 | D7: Tsjekkia | E7: - | F7: Mexico | H7: - | J7: 1 | K7: - | L7: 2 | M7: =IF(ISBLANK($G7)=TRUE,"",IF(SIGN(J7-L7)=SIGN($G7-$I7),1,0)+IF(J7=$G7,IF(L7=$I7,2,0),0)) | N7: 1 | O7: - | P7: 2 | Q7: =IF(ISBLANK($G7)=TRUE,"",IF(SIGN(N7-P7)=SIGN($G7-$I7),1,0)+IF(N7=$G7,IF(P7=$I7,2,0),0)) | R7: 0 | S7: - | T7: 3 | U7: =IF(ISBLANK($G7)=TRUE,"",IF(SIGN(R7-T7)=SIGN($G7-$I7),1,0)+IF(R7=$G7,IF(T7=$I7,2,0),0)) | W7: - | Y7: =IF(ISBLANK($G7)=TRUE,"",IF(SIGN(V7-X7)=SIGN($G7-$I7),1,0)+IF(V7=$G7,IF(X7=$I7,2,0),0)) | Z7: 0 | AA7: - | AB7: 2 | AC7: =IF(ISBLANK($G7)=TRUE,"",IF(SIGN(Z7-AB7)=SIGN($G7-$I7),1,0)+IF(Z7=$G7,IF(AB7=$I7,2,0),0)) | AD7: 0 | AE7: - | AF7: 2 | AG7: =IF(ISBLANK($G7)=TRUE,"",IF(SIGN(AD7-AF7)=SIGN($G7-$I7),1,0)+IF(AD7=$G7,IF(AF7=$I7,2,0),0))
B8: 46198 | C8: 03:00 | D8: Sør-Afrika | E8: - | F8: Sør-Korea | H8: - | J8: 1 | K8: - | L8: 2 | M8: =IF(ISBLANK($G8)=TRUE,"",IF(SIGN(J8-L8)=SIGN($G8-$I8),1,0)+IF(J8=$G8,IF(L8=$I8,2,0),0)) | N8: 1 | O8: - | P8: 1 | Q8: =IF(ISBLANK($G8)=TRUE,"",IF(SIGN(N8-P8)=SIGN($G8-$I8),1,0)+IF(N8=$G8,IF(P8=$I8,2,0),0)) | R8: 1 | S8: - | T8: 2 | U8: =IF(ISBLANK($G8)=TRUE,"",IF(SIGN(R8-T8)=SIGN($G8-$I8),1,0)+IF(R8=$G8,IF(T8=$I8,2,0),0)) | W8: - | Y8: =IF(ISBLANK($G8)=TRUE,"",IF(SIGN(V8-X8)=SIGN($G8-$I8),1,0)+IF(V8=$G8,IF(X8=$I8,2,0),0)) | Z8: 2 | AA8: - | AB8: 2 | AC8: =IF(ISBLANK($G8)=TRUE,"",IF(SIGN(Z8-AB8)=SIGN($G8-$I8),1,0)+IF(Z8=$G8,IF(AB8=$I8,2,0),0)) | AD8: 1 | AE8: - | AF8: 2 | AG8: =IF(ISBLANK($G8)=TRUE,"",IF(SIGN(AD8-AF8)=SIGN($G8-$I8),1,0)+IF(AD8=$G8,IF(AF8=$I8,2,0),0))
B9: Dato | C9: Kl. | D9: Gruppe B | G9: Resultat
B10: 46185 | C10: 21:00 | D10: Canada | E10: - | F10: Bosnia-Hercegovina | H10: - | J10: 2 | K10: - | L10: 1 | M10: =IF(ISBLANK($I10)=TRUE,"",IF(SIGN(J10-L10)=SIGN($G10-$I10),1,0)+IF(J10=$G10,IF(L10=$I10,2,0),0)) | N10: 1 | O10: - | P10: 2 | Q10: =IF(ISBLANK($I10)=TRUE,"",IF(SIGN(N10-P10)=SIGN($G10-$I10),1,0)+IF(N10=$G10,IF(P10=$I10,2,0),0)) | R10: 1 | S10: - | T10: 1 | U10: =IF(ISBLANK($I10)=TRUE,"",IF(SIGN(R10-T10)=SIGN($G10-$I10),1,0)+IF(R10=$G10,IF(T10=$I10,2,0),0)) | W10: - | Y10: =IF(ISBLANK($I10)=TRUE,"",IF(SIGN(V10-X10)=SIGN($G10-$I10),1,0)+IF(V10=$G10,IF(X10=$I10,2,0),0)) | Z10: 2 | AA10: - | AB10: 0 | AC10: =IF(ISBLANK($I10)=TRUE,"",IF(SIGN(Z10-AB10)=SIGN($G10-$I10),1,0)+IF(Z10=$G10,IF(AB10=$I10,2,0),0)) | AD10: 1 | AE10: - | AF10: 1 | AG10: =IF(ISBLANK($I10)=TRUE,"",IF(SIGN(AD10-AF10)=SIGN($G10-$I10),1,0)+IF(AD10=$G10,IF(AF10=$I10,2,0),0))
B11: 46186 | C11: 21:00 | D11: Qatar | E11: - | F11: Sveits | H11: - | J11: 0 | K11: - | L11: 2 | M11: =IF(ISBLANK($G11)=TRUE,"",IF(SIGN(J11-L11)=SIGN($G11-$I11),1,0)+IF(J11=$G11,IF(L11=$I11,2,0),0)) | N11: 0 | O11: - | P11: 2 | Q11: =IF(ISBLANK($G11)=TRUE,"",IF(SIGN(N11-P11)=SIGN($G11-$I11),1,0)+IF(N11=$G11,IF(P11=$I11,2,0),0)) | R11: 0 | S11: - | T11: 2 | U11: =IF(ISBLANK($G11)=TRUE,"",IF(SIGN(R11-T11)=SIGN($G11-$I11),1,0)+IF(R11=$G11,IF(T11=$I11,2,0),0)) | W11: - | Y11: =IF(ISBLANK($G11)=TRUE,"",IF(SIGN(V11-X11)=SIGN($G11-$I11),1,0)+IF(V11=$G11,IF(X11=$I11,2,0),0)) | Z11: 1 | AA11: - | AB11: 3 | AC11: =IF(ISBLANK($G11)=TRUE,"",IF(SIGN(Z11-AB11)=SIGN($G11-$I11),1,0)+IF(Z11=$G11,IF(AB11=$I11,2,0),0)) | AD11: 0 | AE11: - | AF11: 2 | AG11: =IF(ISBLANK($G11)=TRUE,"",IF(SIGN(AD11-AF11)=SIGN($G11-$I11),1,0)+IF(AD11=$G11,IF(AF11=$I11,2,0),0))
B12: 46191 | C12: 21:00 | D12: Sveits | E12: - | F12: Bosnia-Hercegovina | H12: - | J12: 1 | K12: - | L12: 0 | M12: =IF(ISBLANK($G12)=TRUE,"",IF(SIGN(J12-L12)=SIGN($G12-$I12),1,0)+IF(J12=$G12,IF(L12=$I12,2,0),0)) | N12: 2 | O12: - | P12: 1 | Q12: =IF(ISBLANK($G12)=TRUE,"",IF(SIGN(N12-P12)=SIGN($G12-$I12),1,0)+IF(N12=$G12,IF(P12=$I12,2,0),0)) | R12: 2 | S12: - | T12: 1 | U12: =IF(ISBLANK($G12)=TRUE,"",IF(SIGN(R12-T12)=SIGN($G12-$I12),1,0)+IF(R12=$G12,IF(T12=$I12,2,0),0)) | W12: - | Y12: =IF(ISBLANK($G12)=TRUE,"",IF(SIGN(V12-X12)=SIGN($G12-$I12),1,0)+IF(V12=$G12,IF(X12=$I12,2,0),0)) | Z12: 2 | AA12: - | AB12: 0 | AC12: =IF(ISBLANK($G12)=TRUE,"",IF(SIGN(Z12-AB12)=SIGN($G12-$I12),1,0)+IF(Z12=$G12,IF(AB12=$I12,2,0),0)) | AD12: 2 | AE12: - | AF12: 1 | AG12: =IF(ISBLANK($G12)=TRUE,"",IF(SIGN(AD12-AF12)=SIGN($G12-$I12),1,0)+IF(AD12=$G12,IF(AF12=$I12,2,0),0))
B13: 46192 | C13: 00:00 | D13: Canada | E13: - | F13: Qatar | H13: - | J13: 2 | K13: - | L13: 0 | M13: =IF(ISBLANK($G13)=TRUE,"",IF(SIGN(J13-L13)=SIGN($G13-$I13),1,0)+IF(J13=$G13,IF(L13=$I13,2,0),0)) | N13: 2 | O13: - | P13: 0 | Q13: =IF(ISBLANK($G13)=TRUE,"",IF(SIGN(N13-P13)=SIGN($G13-$I13),1,0)+IF(N13=$G13,IF(P13=$I13,2,0),0)) | R13: 2 | S13: - | T13: 1 | U13: =IF(ISBLANK($G13)=TRUE,"",IF(SIGN(R13-T13)=SIGN($G13-$I13),1,0)+IF(R13=$G13,IF(T13=$I13,2,0),0)) | W13: - | Y13: =IF(ISBLANK($G13)=TRUE,"",IF(SIGN(V13-X13)=SIGN($G13-$I13),1,0)+IF(V13=$G13,IF(X13=$I13,2,0),0)) | Z13: 3 | AA13: - | AB13: 1 | AC13: =IF(ISBLANK($G13)=TRUE,"",IF(SIGN(Z13-AB13)=SIGN($G13-$I13),1,0)+IF(Z13=$G13,IF(AB13=$I13,2,0),0)) | AD13: 2 | AE13: - | AF13: 0 | AG13: =IF(ISBLANK($G13)=TRUE,"",IF(SIGN(AD13-AF13)=SIGN($G13-$I13),1,0)+IF(AD13=$G13,IF(AF13=$I13,2,0),0))
B14: 46197 | C14: 21:00 | D14: Sveits | E14: - | F14: Canada | H14: - | J14: 1 | K14: - | L14: 1 | M14: =IF(ISBLANK($G14)=TRUE,"",IF(SIGN(J14-L14)=SIGN($G14-$I14),1,0)+IF(J14=$G14,IF(L14=$I14,2,0),0)) | N14: 2 | O14: - | P14: 1 | Q14: =IF(ISBLANK($G14)=TRUE,"",IF(SIGN(N14-P14)=SIGN($G14-$I14),1,0)+IF(N14=$G14,IF(P14=$I14,2,0),0)) | R14: 1 | S14: - | T14: 1 | U14: =IF(ISBLANK($G14)=TRUE,"",IF(SIGN(R14-T14)=SIGN($G14-$I14),1,0)+IF(R14=$G14,IF(T14=$I14,2,0),0)) | W14: - | Y14: =IF(ISBLANK($G14)=TRUE,"",IF(SIGN(V14-X14)=SIGN($G14-$I14),1,0)+IF(V14=$G14,IF(X14=$I14,2,0),0)) | Z14: 2 | AA14: - | AB14: 0 | AC14: =IF(ISBLANK($G14)=TRUE,"",IF(SIGN(Z14-AB14)=SIGN($G14-$I14),1,0)+IF(Z14=$G14,IF(AB14=$I14,2,0),0)) | AD14: 3 | AE14: - | AF14: 1 | AG14: =IF(ISBLANK($G14)=TRUE,"",IF(SIGN(AD14-AF14)=SIGN($G14-$I14),1,0)+IF(AD14=$G14,IF(AF14=$I14,2,0),0))
B15: 46197 | C15: 21:00 | D15: Bosnia-Hercegovina | E15: - | F15: Qatar | H15: - | J15: 1 | K15: - | L15: 0 | M15: =IF(ISBLANK($G15)=TRUE,"",IF(SIGN(J15-L15)=SIGN($G15-$I15),1,0)+IF(J15=$G15,IF(L15=$I15,2,0),0)) | N15: 2 | O15: - | P15: 0 | Q15: =IF(ISBLANK($G15)=TRUE,"",IF(SIGN(N15-P15)=SIGN($G15-$I15),1,0)+IF(N15=$G15,IF(P15=$I15,2,0),0)) | R15: 1 | S15: - | T15: 0 | U15: =IF(ISBLANK($G15)=TRUE,"",IF(SIGN(R15-T15)=SIGN($G15-$I15),1,0)+IF(R15=$G15,IF(T15=$I15,2,0),0)) | W15: - | Y15: =IF(ISBLANK($G15)=TRUE,"",IF(SIGN(V15-X15)=SIGN($G15-$I15),1,0)+IF(V15=$G15,IF(X15=$I15,2,0),0)) | Z15: 2 | AA15: - | AB15: 4 | AC15: =IF(ISBLANK($G15)=TRUE,"",IF(SIGN(Z15-AB15)=SIGN($G15-$I15),1,0)+IF(Z15=$G15,IF(AB15=$I15,2,0),0)) | AD15: 2 | AE15: - | AF15: 0 | AG15: =IF(ISBLANK($G15)=TRUE,"",IF(SIGN(AD15-AF15)=SIGN($G15-$I15),1,0)+IF(AD15=$G15,IF(AF15=$I15,2,0),0))
B16: Dato | C16: Kl. | D16: Gruppe C | G16: Resultat
B17: 46187 | C17: 00:00 | D17: Brasil | E17: - | F17: Marokko | H17: - | J17: 2 | K17: - | L17: 0 | M17: =IF(ISBLANK($I17)=TRUE,"",IF(SIGN(J17-L17)=SIGN($G17-$I17),1,0)+IF(J17=$G17,IF(L17=$I17,2,0),0)) | N17: 2 | O17: - | P17: 0 | Q17: =IF(ISBLANK($I17)=TRUE,"",IF(SIGN(N17-P17)=SIGN($G17-$I17),1,0)+IF(N17=$G17,IF(P17=$I17,2,0),0)) | R17: 2 | S17: - | T17: 1 | U17: =IF(ISBLANK($I17)=TRUE,"",IF(SIGN(R17-T17)=SIGN($G17-$I17),1,0)+IF(R17=$G17,IF(T17=$I17,2,0),0)) | W17: - | Y17: =IF(ISBLANK($I17)=TRUE,"",IF(SIGN(V17-X17)=SIGN($G17-$I17),1,0)+IF(V17=$G17,IF(X17=$I17,2,0),0)) | Z17: 2 | AA17: - | AB17: 2 | AC17: =IF(ISBLANK($I17)=TRUE,"",IF(SIGN(Z17-AB17)=SIGN($G17-$I17),1,0)+IF(Z17=$G17,IF(AB17=$I17,2,0),0)) | AD17: 2 | AE17: - | AF17: 2 | AG17: =IF(ISBLANK($I17)=TRUE,"",IF(SIGN(AD17-AF17)=SIGN($G17-$I17),1,0)+IF(AD17=$G17,IF(AF17=$I17,2,0),0))
B18: 46187 | C18: 03:00 | D18: Haiti | E18: - | F18: Skottland | H18: - | J18: 0 | K18: - | L18: 2 | M18: =IF(ISBLANK($G18)=TRUE,"",IF(SIGN(J18-L18)=SIGN($G18-$I18),1,0)+IF(J18=$G18,IF(L18=$I18,2,0),0)) | N18: 1 | O18: - | P18: 3 | Q18: =IF(ISBLANK($G18)=TRUE,"",IF(SIGN(N18-P18)=SIGN($G18-$I18),1,0)+IF(N18=$G18,IF(P18=$I18,2,0),0)) | R18: 1 | S18: - | T18: 4 | U18: =IF(ISBLANK($G18)=TRUE,"",IF(SIGN(R18-T18)=SIGN($G18-$I18),1,0)+IF(R18=$G18,IF(T18=$I18,2,0),0)) | W18: - | Y18: =IF(ISBLANK($G18)=TRUE,"",IF(SIGN(V18-X18)=SIGN($G18-$I18),1,0)+IF(V18=$G18,IF(X18=$I18,2,0),0)) | Z18: 0 | AA18: - | AB18: 3 | AC18: =IF(ISBLANK($G18)=TRUE,"",IF(SIGN(Z18-AB18)=SIGN($G18-$I18),1,0)+IF(Z18=$G18,IF(AB18=$I18,2,0),0)) | AD18: 0 | AE18: - | AF18: 1 | AG18: =IF(ISBLANK($G18)=TRUE,"",IF(SIGN(AD18-AF18)=SIGN($G18-$I18),1,0)+IF(AD18=$G18,IF(AF18=$I18,2,0),0))
B19: 46193 | C19: 00:00 | D19: Skottland | E19: - | F19: Marokko | H19: - | J19: 0 | K19: - | L19: 1 | M19: =IF(ISBLANK($G19)=TRUE,"",IF(SIGN(J19-L19)=SIGN($G19-$I19),1,0)+IF(J19=$G19,IF(L19=$I19,2,0),0)) | N19: 1 | O19: - | P19: 2 | Q19: =IF(ISBLANK($G19)=TRUE,"",IF(SIGN(N19-P19)=SIGN($G19-$I19),1,0)+IF(N19=$G19,IF(P19=$I19,2,0),0)) | R19: 1 | S19: - | T19: 2 | U19: =IF(ISBLANK($G19)=TRUE,"",IF(SIGN(R19-T19)=SIGN($G19-$I19),1,0)+IF(R19=$G19,IF(T19=$I19,2,0),0)) | W19: - | Y19: =IF(ISBLANK($G19)=TRUE,"",IF(SIGN(V19-X19)=SIGN($G19-$I19),1,0)+IF(V19=$G19,IF(X19=$I19,2,0),0)) | Z19: 0 | AA19: - | AB19: 2 | AC19: =IF(ISBLANK($G19)=TRUE,"",IF(SIGN(Z19-AB19)=SIGN($G19-$I19),1,0)+IF(Z19=$G19,IF(AB19=$I19,2,0),0)) | AD19: 0 | AE19: - | AF19: 3 | AG19: =IF(ISBLANK($G19)=TRUE,"",IF(SIGN(AD19-AF19)=SIGN($G19-$I19),1,0)+IF(AD19=$G19,IF(AF19=$I19,2,0),0))
B20: 46193 | C20: 02:30 | D20: Brasil | E20: - | F20: Haiti | H20: - | J20: 3 | K20: - | L20: 0 | M20: =IF(ISBLANK($G20)=TRUE,"",IF(SIGN(J20-L20)=SIGN($G20-$I20),1,0)+IF(J20=$G20,IF(L20=$I20,2,0),0)) | N20: 3 | O20: - | P20: 0 | Q20: =IF(ISBLANK($G20)=TRUE,"",IF(SIGN(N20-P20)=SIGN($G20-$I20),1,0)+IF(N20=$G20,IF(P20=$I20,2,0),0)) | R20: 4 | S20: - | T20: 0 | U20: =IF(ISBLANK($G20)=TRUE,"",IF(SIGN(R20-T20)=SIGN($G20-$I20),1,0)+IF(R20=$G20,IF(T20=$I20,2,0),0)) | W20: - | Y20: =IF(ISBLANK($G20)=TRUE,"",IF(SIGN(V20-X20)=SIGN($G20-$I20),1,0)+IF(V20=$G20,IF(X20=$I20,2,0),0)) | Z20: 2 | AA20: - | AB20: 0 | AC20: =IF(ISBLANK($G20)=TRUE,"",IF(SIGN(Z20-AB20)=SIGN($G20-$I20),1,0)+IF(Z20=$G20,IF(AB20=$I20,2,0),0)) | AD20: 2 | AE20: - | AF20: 0 | AG20: =IF(ISBLANK($G20)=TRUE,"",IF(SIGN(AD20-AF20)=SIGN($G20-$I20),1,0)+IF(AD20=$G20,IF(AF20=$I20,2,0),0))
B21: 46198 | C21: 00:00 | D21: Skottland | E21: - | F21: Brasil | H21: - | J21: 0 | K21: - | L21: 2 | M21: =IF(ISBLANK($G21)=TRUE,"",IF(SIGN(J21-L21)=SIGN($G21-$I21),1,0)+IF(J21=$G21,IF(L21=$I21,2,0),0)) | N21: 1 | O21: - | P21: 2 | Q21: =IF(ISBLANK($G21)=TRUE,"",IF(SIGN(N21-P21)=SIGN($G21-$I21),1,0)+IF(N21=$G21,IF(P21=$I21,2,0),0)) | R21: 1 | S21: - | T21: 1 | U21: =IF(ISBLANK($G21)=TRUE,"",IF(SIGN(R21-T21)=SIGN($G21-$I21),1,0)+IF(R21=$G21,IF(T21=$I21,2,0),0)) | W21: - | Y21: =IF(ISBLANK($G21)=TRUE,"",IF(SIGN(V21-X21)=SIGN($G21-$I21),1,0)+IF(V21=$G21,IF(X21=$I21,2,0),0)) | Z21: 1 | AA21: - | AB21: 3 | AC21: =IF(ISBLANK($G21)=TRUE,"",IF(SIGN(Z21-AB21)=SIGN($G21-$I21),1,0)+IF(Z21=$G21,IF(AB21=$I21,2,0),0)) | AD21: 0 | AE21: - | AF21: 3 | AG21: =IF(ISBLANK($G21)=TRUE,"",IF(SIGN(AD21-AF21)=SIGN($G21-$I21),1,0)+IF(AD21=$G21,IF(AF21=$I21,2,0),0))
B22: 46198 | C22: 00:00 | D22: Marokko | E22: - | F22: Haiti | H22: - | J22: 2 | K22: - | L22: 0 | M22: =IF(ISBLANK($G22)=TRUE,"",IF(SIGN(J22-L22)=SIGN($G22-$I22),1,0)+IF(J22=$G22,IF(L22=$I22,2,0),0)) | N22: 3 | O22: - | P22: 1 | Q22: =IF(ISBLANK($G22)=TRUE,"",IF(SIGN(N22-P22)=SIGN($G22-$I22),1,0)+IF(N22=$G22,IF(P22=$I22,2,0),0)) | R22: 2 | S22: - | T22: 0 | U22: =IF(ISBLANK($G22)=TRUE,"",IF(SIGN(R22-T22)=SIGN($G22-$I22),1,0)+IF(R22=$G22,IF(T22=$I22,2,0),0)) | W22: - | Y22: =IF(ISBLANK($G22)=TRUE,"",IF(SIGN(V22-X22)=SIGN($G22-$I22),1,0)+IF(V22=$G22,IF(X22=$I22,2,0),0)) | Z22: 4 | AA22: - | AB22: 1 | AC22: =IF(ISBLANK($G22)=TRUE,"",IF(SIGN(Z22-AB22)=SIGN($G22-$I22),1,0)+IF(Z22=$G22,IF(AB22=$I22,2,0),0)) | AD22: 3 | AE22: - | AF22: 0 | AG22: =IF(ISBLANK($G22)=TRUE,"",IF(SIGN(AD22-AF22)=SIGN($G22-$I22),1,0)+IF(AD22=$G22,IF(AF22=$I22,2,0),0))
B23: Dato | C23: Kl. | D23: Gruppe D | G23: Resultat
B24: 46186 | C24: 03:00 | D24: USA | E24: - | F24: Paraguay | H24: - | J24: 1 | K24: - | L24: 0 | M24: =IF(ISBLANK($I24)=TRUE,"",IF(SIGN(J24-L24)=SIGN($G24-$I24),1,0)+IF(J24=$G24,IF(L24=$I24,2,0),0)) | N24: 3 | O24: - | P24: 1 | Q24: =IF(ISBLANK($I24)=TRUE,"",IF(SIGN(N24-P24)=SIGN($G24-$I24),1,0)+IF(N24=$G24,IF(P24=$I24,2,0),0)) | R24: 2 | S24: - | T24: 1 | U24: =IF(ISBLANK($I24)=TRUE,"",IF(SIGN(R24-T24)=SIGN($G24-$I24),1,0)+IF(R24=$G24,IF(T24=$I24,2,0),0)) | W24: - | Y24: =IF(ISBLANK($I24)=TRUE,"",IF(SIGN(V24-X24)=SIGN($G24-$I24),1,0)+IF(V24=$G24,IF(X24=$I24,2,0),0)) | Z24: 2 | AA24: - | AB24: 0 | AC24: =IF(ISBLANK($I24)=TRUE,"",IF(SIGN(Z24-AB24)=SIGN($G24-$I24),1,0)+IF(Z24=$G24,IF(AB24=$I24,2,0),0)) | AD24: 2 | AE24: - | AF24: 0 | AG24: =IF(ISBLANK($I24)=TRUE,"",IF(SIGN(AD24-AF24)=SIGN($G24-$I24),1,0)+IF(AD24=$G24,IF(AF24=$I24,2,0),0))
B25: 46187 | C25: 06:00 | D25: Australia | E25: - | F25: Tyrkia | H25: - | J25: 0 | K25: - | L25: 2 | M25: =IF(ISBLANK($G25)=TRUE,"",IF(SIGN(J25-L25)=SIGN($G25-$I25),1,0)+IF(J25=$G25,IF(L25=$I25,2,0),0)) | N25: 1 | O25: - | P25: 2 | Q25: =IF(ISBLANK($G25)=TRUE,"",IF(SIGN(N25-P25)=SIGN($G25-$I25),1,0)+IF(N25=$G25,IF(P25=$I25,2,0),0)) | R25: 1 | S25: - | T25: 1 | U25: =IF(ISBLANK($G25)=TRUE,"",IF(SIGN(R25-T25)=SIGN($G25-$I25),1,0)+IF(R25=$G25,IF(T25=$I25,2,0),0)) | W25: - | Y25: =IF(ISBLANK($G25)=TRUE,"",IF(SIGN(V25-X25)=SIGN($G25-$I25),1,0)+IF(V25=$G25,IF(X25=$I25,2,0),0)) | Z25: 2 | AA25: - | AB25: 0 | AC25: =IF(ISBLANK($G25)=TRUE,"",IF(SIGN(Z25-AB25)=SIGN($G25-$I25),1,0)+IF(Z25=$G25,IF(AB25=$I25,2,0),0)) | AD25: 0 | AE25: - | AF25: 2 | AG25: =IF(ISBLANK($G25)=TRUE,"",IF(SIGN(AD25-AF25)=SIGN($G25-$I25),1,0)+IF(AD25=$G25,IF(AF25=$I25,2,0),0))
B26: 46192 | C26: 21:00 | D26: USA | E26: - | F26: Australia | H26: - | J26: 2 | K26: - | L26: 0 | M26: =IF(ISBLANK($G26)=TRUE,"",IF(SIGN(J26-L26)=SIGN($G26-$I26),1,0)+IF(J26=$G26,IF(L26=$I26,2,0),0)) | N26: 2 | O26: - | P26: 1 | Q26: =IF(ISBLANK($G26)=TRUE,"",IF(SIGN(N26-P26)=SIGN($G26-$I26),1,0)+IF(N26=$G26,IF(P26=$I26,2,0),0)) | R26: 1 | S26: - | T26: 0 | U26: =IF(ISBLANK($G26)=TRUE,"",IF(SIGN(R26-T26)=SIGN($G26-$I26),1,0)+IF(R26=$G26,IF(T26=$I26,2,0),0)) | W26: - | Y26: =IF(ISBLANK($G26)=TRUE,"",IF(SIGN(V26-X26)=SIGN($G26-$I26),1,0)+IF(V26=$G26,IF(X26=$I26,2,0),0)) | Z26: 3 | AA26: - | AB26: 2 | AC26: =IF(ISBLANK($G26)=TRUE,"",IF(SIGN(Z26-AB26)=SIGN($G26-$I26),1,0)+IF(Z26=$G26,IF(AB26=$I26,2,0),0)) | AD26: 2 | AE26: - | AF26: 1 | AG26: =IF(ISBLANK($G26)=TRUE,"",IF(SIGN(AD26-AF26)=SIGN($G26-$I26),1,0)+IF(AD26=$G26,IF(AF26=$I26,2,0),0))
B27: 46193 | C27: 05:00 | D27: Tyrkia | E27: - | F27: Paraguay | H27: - | J27: 1 | K27: - | L27: 1 | M27: =IF(ISBLANK($G27)=TRUE,"",IF(SIGN(J27-L27)=SIGN($G27-$I27),1,0)+IF(J27=$G27,IF(L27=$I27,2,0),0)) | N27: 2 | O27: - | P27: 1 | Q27: =IF(ISBLANK($G27)=TRUE,"",IF(SIGN(N27-P27)=SIGN($G27-$I27),1,0)+IF(N27=$G27,IF(P27=$I27,2,0),0)) | R27: 1 | S27: - | T27: 2 | U27: =IF(ISBLANK($G27)=TRUE,"",IF(SIGN(R27-T27)=SIGN($G27-$I27),1,0)+IF(R27=$G27,IF(T27=$I27,2,0),0)) | W27: - | Y27: =IF(ISBLANK($G27)=TRUE,"",IF(SIGN(V27-X27)=SIGN($G27-$I27),1,0)+IF(V27=$G27,IF(X27=$I27,2,0),0)) | Z27: 1 | AA27: - | AB27: 3 | AC27: =IF(ISBLANK($G27)=TRUE,"",IF(SIGN(Z27-AB27)=SIGN($G27-$I27),1,0)+IF(Z27=$G27,IF(AB27=$I27,2,0),0)) | AD27: 2 | AE27: - | AF27: 2 | AG27: =IF(ISBLANK($G27)=TRUE,"",IF(SIGN(AD27-AF27)=SIGN($G27-$I27),1,0)+IF(AD27=$G27,IF(AF27=$I27,2,0),0))
B28: 46199 | C28: 04:00 | D28: Tyrkia | E28: - | F28: USA | H28: - | J28: 1 | K28: - | L28: 1 | M28: =IF(ISBLANK($G28)=TRUE,"",IF(SIGN(J28-L28)=SIGN($G28-$I28),1,0)+IF(J28=$G28,IF(L28=$I28,2,0),0)) | N28: 2 | O28: - | P28: 1 | Q28: =IF(ISBLANK($G28)=TRUE,"",IF(SIGN(N28-P28)=SIGN($G28-$I28),1,0)+IF(N28=$G28,IF(P28=$I28,2,0),0)) | R28: 1 | S28: - | T28: 1 | U28: =IF(ISBLANK($G28)=TRUE,"",IF(SIGN(R28-T28)=SIGN($G28-$I28),1,0)+IF(R28=$G28,IF(T28=$I28,2,0),0)) | W28: - | Y28: =IF(ISBLANK($G28)=TRUE,"",IF(SIGN(V28-X28)=SIGN($G28-$I28),1,0)+IF(V28=$G28,IF(X28=$I28,2,0),0)) | Z28: 0 | AA28: - | AB28: 3 | AC28: =IF(ISBLANK($G28)=TRUE,"",IF(SIGN(Z28-AB28)=SIGN($G28-$I28),1,0)+IF(Z28=$G28,IF(AB28=$I28,2,0),0)) | AD28: 3 | AE28: - | AF28: 2 | AG28: =IF(ISBLANK($G28)=TRUE,"",IF(SIGN(AD28-AF28)=SIGN($G28-$I28),1,0)+IF(AD28=$G28,IF(AF28=$I28,2,0),0))
B29: 46199 | C29: 04:00 | D29: Paraguay | E29: - | F29: Australia | H29: - | J29: 1 | K29: - | L29: 1 | M29: =IF(ISBLANK($G29)=TRUE,"",IF(SIGN(J29-L29)=SIGN($G29-$I29),1,0)+IF(J29=$G29,IF(L29=$I29,2,0),0)) | N29: 2 | O29: - | P29: 1 | Q29: =IF(ISBLANK($G29)=TRUE,"",IF(SIGN(N29-P29)=SIGN($G29-$I29),1,0)+IF(N29=$G29,IF(P29=$I29,2,0),0)) | R29: 1 | S29: - | T29: 1 | U29: =IF(ISBLANK($G29)=TRUE,"",IF(SIGN(R29-T29)=SIGN($G29-$I29),1,0)+IF(R29=$G29,IF(T29=$I29,2,0),0)) | W29: - | Y29: =IF(ISBLANK($G29)=TRUE,"",IF(SIGN(V29-X29)=SIGN($G29-$I29),1,0)+IF(V29=$G29,IF(X29=$I29,2,0),0)) | Z29: 1 | AA29: - | AB29: 1 | AC29: =IF(ISBLANK($G29)=TRUE,"",IF(SIGN(Z29-AB29)=SIGN($G29-$I29),1,0)+IF(Z29=$G29,IF(AB29=$I29,2,0),0)) | AD29: 1 | AE29: - | AF29: 1 | AG29: =IF(ISBLANK($G29)=TRUE,"",IF(SIGN(AD29-AF29)=SIGN($G29-$I29),1,0)+IF(AD29=$G29,IF(AF29=$I29,2,0),0))
B30: Dato | C30: Kl. | D30: Gruppe E | G30: Resultat
B31: 46187 | C31: 19:00 | D31: Tyskland | E31: - | F31: Curaçao | H31: - | J31: 4 | K31: - | L31: 0 | M31: =IF(ISBLANK($I31)=TRUE,"",IF(SIGN(J31-L31)=SIGN($G31-$I31),1,0)+IF(J31=$G31,IF(L31=$I31,2,0),0)) | N31: 4 | O31: - | P31: 0 | Q31: =IF(ISBLANK($I31)=TRUE,"",IF(SIGN(N31-P31)=SIGN($G31-$I31),1,0)+IF(N31=$G31,IF(P31=$I31,2,0),0)) | R31: 7 | S31: - | T31: 0 | U31: =IF(ISBLANK($I31)=TRUE,"",IF(SIGN(R31-T31)=SIGN($G31-$I31),1,0)+IF(R31=$G31,IF(T31=$I31,2,0),0)) | W31: - | Y31: =IF(ISBLANK($I31)=TRUE,"",IF(SIGN(V31-X31)=SIGN($G31-$I31),1,0)+IF(V31=$G31,IF(X31=$I31,2,0),0)) | Z31: 2 | AA31: - | AB31: 1 | AC31: =IF(ISBLANK($I31)=TRUE,"",IF(SIGN(Z31-AB31)=SIGN($G31-$I31),1,0)+IF(Z31=$G31,IF(AB31=$I31,2,0),0)) | AD31: 3 | AE31: - | AF31: 0 | AG31: =IF(ISBLANK($I31)=TRUE,"",IF(SIGN(AD31-AF31)=SIGN($G31-$I31),1,0)+IF(AD31=$G31,IF(AF31=$I31,2,0),0))
B32: 46188 | C32: 01:00 | D32: Elfenbenskysten | E32: - | F32: Ecuador | H32: - | J32: 0 | K32: - | L32: 1 | M32: =IF(ISBLANK($G32)=TRUE,"",IF(SIGN(J32-L32)=SIGN($G32-$I32),1,0)+IF(J32=$G32,IF(L32=$I32,2,0),0)) | N32: 1 | O32: - | P32: 2 | Q32: =IF(ISBLANK($G32)=TRUE,"",IF(SIGN(N32-P32)=SIGN($G32-$I32),1,0)+IF(N32=$G32,IF(P32=$I32,2,0),0)) | R32: 2 | S32: - | T32: 1 | U32: =IF(ISBLANK($G32)=TRUE,"",IF(SIGN(R32-T32)=SIGN($G32-$I32),1,0)+IF(R32=$G32,IF(T32=$I32,2,0),0)) | W32: - | Y32: =IF(ISBLANK($G32)=TRUE,"",IF(SIGN(V32-X32)=SIGN($G32-$I32),1,0)+IF(V32=$G32,IF(X32=$I32,2,0),0)) | Z32: 3 | AA32: - | AB32: 2 | AC32: =IF(ISBLANK($G32)=TRUE,"",IF(SIGN(Z32-AB32)=SIGN($G32-$I32),1,0)+IF(Z32=$G32,IF(AB32=$I32,2,0),0)) | AD32: 1 | AE32: - | AF32: 1 | AG32: =IF(ISBLANK($G32)=TRUE,"",IF(SIGN(AD32-AF32)=SIGN($G32-$I32),1,0)+IF(AD32=$G32,IF(AF32=$I32,2,0),0))
B33: 46193 | C33: 22:00 | D33: Tyskland | E33: - | F33: Elfenbenskysten | H33: - | J33: 2 | K33: - | L33: 0 | M33: =IF(ISBLANK($G33)=TRUE,"",IF(SIGN(J33-L33)=SIGN($G33-$I33),1,0)+IF(J33=$G33,IF(L33=$I33,2,0),0)) | N33: 2 | O33: - | P33: 1 | Q33: =IF(ISBLANK($G33)=TRUE,"",IF(SIGN(N33-P33)=SIGN($G33-$I33),1,0)+IF(N33=$G33,IF(P33=$I33,2,0),0)) | R33: 2 | S33: - | T33: 1 | U33: =IF(ISBLANK($G33)=TRUE,"",IF(SIGN(R33-T33)=SIGN($G33-$I33),1,0)+IF(R33=$G33,IF(T33=$I33,2,0),0)) | W33: - | Y33: =IF(ISBLANK($G33)=TRUE,"",IF(SIGN(V33-X33)=SIGN($G33-$I33),1,0)+IF(V33=$G33,IF(X33=$I33,2,0),0)) | Z33: 1 | AA33: - | AB33: 0 | AC33: =IF(ISBLANK($G33)=TRUE,"",IF(SIGN(Z33-AB33)=SIGN($G33-$I33),1,0)+IF(Z33=$G33,IF(AB33=$I33,2,0),0)) | AD33: 1 | AE33: - | AF33: 0 | AG33: =IF(ISBLANK($G33)=TRUE,"",IF(SIGN(AD33-AF33)=SIGN($G33-$I33),1,0)+IF(AD33=$G33,IF(AF33=$I33,2,0),0))
B34: 46194 | C34: 02:00 | D34: Ecuador | E34: - | F34: Curaçao | H34: - | J34: 3 | K34: - | L34: 0 | M34: =IF(ISBLANK($G34)=TRUE,"",IF(SIGN(J34-L34)=SIGN($G34-$I34),1,0)+IF(J34=$G34,IF(L34=$I34,2,0),0)) | N34: 3 | O34: - | P34: 0 | Q34: =IF(ISBLANK($G34)=TRUE,"",IF(SIGN(N34-P34)=SIGN($G34-$I34),1,0)+IF(N34=$G34,IF(P34=$I34,2,0),0)) | R34: 3 | S34: - | T34: 0 | U34: =IF(ISBLANK($G34)=TRUE,"",IF(SIGN(R34-T34)=SIGN($G34-$I34),1,0)+IF(R34=$G34,IF(T34=$I34,2,0),0)) | W34: - | Y34: =IF(ISBLANK($G34)=TRUE,"",IF(SIGN(V34-X34)=SIGN($G34-$I34),1,0)+IF(V34=$G34,IF(X34=$I34,2,0),0)) | Z34: 2 | AA34: - | AB34: 2 | AC34: =IF(ISBLANK($G34)=TRUE,"",IF(SIGN(Z34-AB34)=SIGN($G34-$I34),1,0)+IF(Z34=$G34,IF(AB34=$I34,2,0),0)) | AD34: 2 | AE34: - | AF34: 0 | AG34: =IF(ISBLANK($G34)=TRUE,"",IF(SIGN(AD34-AF34)=SIGN($G34-$I34),1,0)+IF(AD34=$G34,IF(AF34=$I34,2,0),0))
B35: 46198 | C35: 22:00 | D35: Curaçao | E35: - | F35: Elfenbenskysten | H35: - | J35: 0 | K35: - | L35: 2 | M35: =IF(ISBLANK($G35)=TRUE,"",IF(SIGN(J35-L35)=SIGN($G35-$I35),1,0)+IF(J35=$G35,IF(L35=$I35,2,0),0)) | N35: 0 | O35: - | P35: 3 | Q35: =IF(ISBLANK($G35)=TRUE,"",IF(SIGN(N35-P35)=SIGN($G35-$I35),1,0)+IF(N35=$G35,IF(P35=$I35,2,0),0)) | R35: 0 | S35: - | T35: 6 | U35: =IF(ISBLANK($G35)=TRUE,"",IF(SIGN(R35-T35)=SIGN($G35-$I35),1,0)+IF(R35=$G35,IF(T35=$I35,2,0),0)) | W35: - | Y35: =IF(ISBLANK($G35)=TRUE,"",IF(SIGN(V35-X35)=SIGN($G35-$I35),1,0)+IF(V35=$G35,IF(X35=$I35,2,0),0)) | Z35: 1 | AA35: - | AB35: 4 | AC35: =IF(ISBLANK($G35)=TRUE,"",IF(SIGN(Z35-AB35)=SIGN($G35-$I35),1,0)+IF(Z35=$G35,IF(AB35=$I35,2,0),0)) | AD35: 0 | AE35: - | AF35: 4 | AG35: =IF(ISBLANK($G35)=TRUE,"",IF(SIGN(AD35-AF35)=SIGN($G35-$I35),1,0)+IF(AD35=$G35,IF(AF35=$I35,2,0),0))
B36: 46198 | C36: 22:00 | D36: Ecuador | E36: - | F36: Tyskland | H36: - | J36: 1 | K36: - | L36: 2 | M36: =IF(ISBLANK($G36)=TRUE,"",IF(SIGN(J36-L36)=SIGN($G36-$I36),1,0)+IF(J36=$G36,IF(L36=$I36,2,0),0)) | N36: 1 | O36: - | P36: 2 | Q36: =IF(ISBLANK($G36)=TRUE,"",IF(SIGN(N36-P36)=SIGN($G36-$I36),1,0)+IF(N36=$G36,IF(P36=$I36,2,0),0)) | R36: 1 | S36: - | T36: 1 | U36: =IF(ISBLANK($G36)=TRUE,"",IF(SIGN(R36-T36)=SIGN($G36-$I36),1,0)+IF(R36=$G36,IF(T36=$I36,2,0),0)) | W36: - | Y36: =IF(ISBLANK($G36)=TRUE,"",IF(SIGN(V36-X36)=SIGN($G36-$I36),1,0)+IF(V36=$G36,IF(X36=$I36,2,0),0)) | Z36: 2 | AA36: - | AB36: 3 | AC36: =IF(ISBLANK($G36)=TRUE,"",IF(SIGN(Z36-AB36)=SIGN($G36-$I36),1,0)+IF(Z36=$G36,IF(AB36=$I36,2,0),0)) | AD36: 1 | AE36: - | AF36: 1 | AG36: =IF(ISBLANK($G36)=TRUE,"",IF(SIGN(AD36-AF36)=SIGN($G36-$I36),1,0)+IF(AD36=$G36,IF(AF36=$I36,2,0),0))
B37: Dato | C37: Kl. | D37: Gruppe F | G37: Resultat
B38: 46187 | C38: 22:00 | D38: Nederland | E38: - | F38: Japan | H38: - | J38: 2 | K38: - | L38: 1 | M38: =IF(ISBLANK($I38)=TRUE,"",IF(SIGN(J38-L38)=SIGN($G38-$I38),1,0)+IF(J38=$G38,IF(L38=$I38,2,0),0)) | N38: 2 | O38: - | P38: 1 | Q38: =IF(ISBLANK($I38)=TRUE,"",IF(SIGN(N38-P38)=SIGN($G38-$I38),1,0)+IF(N38=$G38,IF(P38=$I38,2,0),0)) | R38: 2 | S38: - | T38: 2 | U38: =IF(ISBLANK($I38)=TRUE,"",IF(SIGN(R38-T38)=SIGN($G38-$I38),1,0)+IF(R38=$G38,IF(T38=$I38,2,0),0)) | W38: - | Y38: =IF(ISBLANK($I38)=TRUE,"",IF(SIGN(V38-X38)=SIGN($G38-$I38),1,0)+IF(V38=$G38,IF(X38=$I38,2,0),0)) | Z38: 1 | AA38: - | AB38: 1 | AC38: =IF(ISBLANK($I38)=TRUE,"",IF(SIGN(Z38-AB38)=SIGN($G38-$I38),1,0)+IF(Z38=$G38,IF(AB38=$I38,2,0),0)) | AD38: 1 | AE38: - | AF38: 1 | AG38: =IF(ISBLANK($I38)=TRUE,"",IF(SIGN(AD38-AF38)=SIGN($G38-$I38),1,0)+IF(AD38=$G38,IF(AF38=$I38,2,0),0))
B39: 46188 | C39: 04:00 | D39: Sverige | E39: - | F39: Tunisia | H39: - | J39: 1 | K39: - | L39: 1 | M39: =IF(ISBLANK($G39)=TRUE,"",IF(SIGN(J39-L39)=SIGN($G39-$I39),1,0)+IF(J39=$G39,IF(L39=$I39,2,0),0)) | N39: 2 | O39: - | P39: 0 | Q39: =IF(ISBLANK($G39)=TRUE,"",IF(SIGN(N39-P39)=SIGN($G39-$I39),1,0)+IF(N39=$G39,IF(P39=$I39,2,0),0)) | R39: 2 | S39: - | T39: 0 | U39: =IF(ISBLANK($G39)=TRUE,"",IF(SIGN(R39-T39)=SIGN($G39-$I39),1,0)+IF(R39=$G39,IF(T39=$I39,2,0),0)) | W39: - | Y39: =IF(ISBLANK($G39)=TRUE,"",IF(SIGN(V39-X39)=SIGN($G39-$I39),1,0)+IF(V39=$G39,IF(X39=$I39,2,0),0)) | Z39: 0 | AA39: - | AB39: 2 | AC39: =IF(ISBLANK($G39)=TRUE,"",IF(SIGN(Z39-AB39)=SIGN($G39-$I39),1,0)+IF(Z39=$G39,IF(AB39=$I39,2,0),0)) | AD39: 0 | AE39: - | AF39: 2 | AG39: =IF(ISBLANK($G39)=TRUE,"",IF(SIGN(AD39-AF39)=SIGN($G39-$I39),1,0)+IF(AD39=$G39,IF(AF39=$I39,2,0),0))
B40: 46193 | C40: 19:00 | D40: Nederland | E40: - | F40: Sverige | H40: - | J40: 2 | K40: - | L40: 0 | M40: =IF(ISBLANK($G40)=TRUE,"",IF(SIGN(J40-L40)=SIGN($G40-$I40),1,0)+IF(J40=$G40,IF(L40=$I40,2,0),0)) | N40: 2 | O40: - | P40: 1 | Q40: =IF(ISBLANK($G40)=TRUE,"",IF(SIGN(N40-P40)=SIGN($G40-$I40),1,0)+IF(N40=$G40,IF(P40=$I40,2,0),0)) | R40: 3 | S40: - | T40: 1 | U40: =IF(ISBLANK($G40)=TRUE,"",IF(SIGN(R40-T40)=SIGN($G40-$I40),1,0)+IF(R40=$G40,IF(T40=$I40,2,0),0)) | W40: - | Y40: =IF(ISBLANK($G40)=TRUE,"",IF(SIGN(V40-X40)=SIGN($G40-$I40),1,0)+IF(V40=$G40,IF(X40=$I40,2,0),0)) | Z40: 3 | AA40: - | AB40: 1 | AC40: =IF(ISBLANK($G40)=TRUE,"",IF(SIGN(Z40-AB40)=SIGN($G40-$I40),1,0)+IF(Z40=$G40,IF(AB40=$I40,2,0),0)) | AD40: 2 | AE40: - | AF40: 0 | AG40: =IF(ISBLANK($G40)=TRUE,"",IF(SIGN(AD40-AF40)=SIGN($G40-$I40),1,0)+IF(AD40=$G40,IF(AF40=$I40,2,0),0))
B41: 46194 | C41: 06:00 | D41: Tunisia | E41: - | F41: Japan | H41: - | J41: 1 | K41: - | L41: 2 | M41: =IF(ISBLANK($G41)=TRUE,"",IF(SIGN(J41-L41)=SIGN($G41-$I41),1,0)+IF(J41=$G41,IF(L41=$I41,2,0),0)) | N41: 1 | O41: - | P41: 2 | Q41: =IF(ISBLANK($G41)=TRUE,"",IF(SIGN(N41-P41)=SIGN($G41-$I41),1,0)+IF(N41=$G41,IF(P41=$I41,2,0),0)) | R41: 1 | S41: - | T41: 2 | U41: =IF(ISBLANK($G41)=TRUE,"",IF(SIGN(R41-T41)=SIGN($G41-$I41),1,0)+IF(R41=$G41,IF(T41=$I41,2,0),0)) | W41: - | Y41: =IF(ISBLANK($G41)=TRUE,"",IF(SIGN(V41-X41)=SIGN($G41-$I41),1,0)+IF(V41=$G41,IF(X41=$I41,2,0),0)) | Z41: 0 | AA41: - | AB41: 0 | AC41: =IF(ISBLANK($G41)=TRUE,"",IF(SIGN(Z41-AB41)=SIGN($G41-$I41),1,0)+IF(Z41=$G41,IF(AB41=$I41,2,0),0)) | AD41: 2 | AE41: - | AF41: 2 | AG41: =IF(ISBLANK($G41)=TRUE,"",IF(SIGN(AD41-AF41)=SIGN($G41-$I41),1,0)+IF(AD41=$G41,IF(AF41=$I41,2,0),0))
...

Sheet Utslagsrunder
B2: Dato | C2: Kl. | D2: Sekstendelsfinaler | G2: Resultat | J2: Erling | N2: Rune | R2: Håkon | V2: Geir | Z2: Tore | AD2: Tor Arne
B3: 46201 | C3: 21:00 | E3: - | H3: - | K3: - | M3: =IF(ISBLANK($I3)=TRUE,"",IF(SIGN(J3-L3)=SIGN($G3-$I3),1,0)+IF(J3=$G3,IF(L3=$I3,2,0),0)) | O3: - | Q3: =IF(ISBLANK($I3)=TRUE,"",IF(SIGN(N3-P3)=SIGN($G3-$I3),1,0)+IF(N3=$G3,IF(P3=$I3,2,0),0)) | S3: - | U3: =IF(ISBLANK($I3)=TRUE,"",IF(SIGN(R3-T3)=SIGN($G3-$I3),1,0)+IF(R3=$G3,IF(T3=$I3,2,0),0)) | W3: - | Y3: =IF(ISBLANK($I3)=TRUE,"",IF(SIGN(V3-X3)=SIGN($G3-$I3),1,0)+IF(V3=$G3,IF(X3=$I3,2,0),0)) | AA3: - | AC3: =IF(ISBLANK($I3)=TRUE,"",IF(SIGN(Z3-AB3)=SIGN($G3-$I3),1,0)+IF(Z3=$G3,IF(AB3=$I3,2,0),0)) | AE3: - | AG3: =IF(ISBLANK($I3)=TRUE,"",IF(SIGN(AD3-AF3)=SIGN($G3-$I3),1,0)+IF(AD3=$G3,IF(AF3=$I3,2,0),0))
B4: 46202 | C4: 0.79166667 | E4: - | H4: - | K4: - | M4: =IF(ISBLANK($G4)=TRUE,"",IF(SIGN(J4-L4)=SIGN($G4-$I4),1,0)+IF(J4=$G4,IF(L4=$I4,2,0),0)) | O4: - | Q4: =IF(ISBLANK($G4)=TRUE,"",IF(SIGN(N4-P4)=SIGN($G4-$I4),1,0)+IF(N4=$G4,IF(P4=$I4,2,0),0)) | S4: - | U4: =IF(ISBLANK($G4)=TRUE,"",IF(SIGN(R4-T4)=SIGN($G4-$I4),1,0)+IF(R4=$G4,IF(T4=$I4,2,0),0)) | W4: - | Y4: =IF(ISBLANK($G4)=TRUE,"",IF(SIGN(V4-X4)=SIGN($G4-$I4),1,0)+IF(V4=$G4,IF(X4=$I4,2,0),0)) | AA4: - | AC4: =IF(ISBLANK($G4)=TRUE,"",IF(SIGN(Z4-AB4)=SIGN($G4-$I4),1,0)+IF(Z4=$G4,IF(AB4=$I4,2,0),0)) | AE4: - | AG4: =IF(ISBLANK($G4)=TRUE,"",IF(SIGN(AD4-AF4)=SIGN($G4-$I4),1,0)+IF(AD4=$G4,IF(AF4=$I4,2,0),0))
B5: 46202 | C5: 0.9375 | E5: - | H5: - | K5: - | M5: =IF(ISBLANK($G5)=TRUE,"",IF(SIGN(J5-L5)=SIGN($G5-$I5),1,0)+IF(J5=$G5,IF(L5=$I5,2,0),0)) | O5: - | Q5: =IF(ISBLANK($G5)=TRUE,"",IF(SIGN(N5-P5)=SIGN($G5-$I5),1,0)+IF(N5=$G5,IF(P5=$I5,2,0),0)) | S5: - | U5: =IF(ISBLANK($G5)=TRUE,"",IF(SIGN(R5-T5)=SIGN($G5-$I5),1,0)+IF(R5=$G5,IF(T5=$I5,2,0),0)) | W5: - | Y5: =IF(ISBLANK($G5)=TRUE,"",IF(SIGN(V5-X5)=SIGN($G5-$I5),1,0)+IF(V5=$G5,IF(X5=$I5,2,0),0)) | AA5: - | AC5: =IF(ISBLANK($G5)=TRUE,"",IF(SIGN(Z5-AB5)=SIGN($G5-$I5),1,0)+IF(Z5=$G5,IF(AB5=$I5,2,0),0)) | AE5: - | AG5: =IF(ISBLANK($G5)=TRUE,"",IF(SIGN(AD5-AF5)=SIGN($G5-$I5),1,0)+IF(AD5=$G5,IF(AF5=$I5,2,0),0))
B6: 46203 | C6: 03:00 | E6: - | H6: - | K6: - | M6: =IF(ISBLANK($G6)=TRUE,"",IF(SIGN(J6-L6)=SIGN($G6-$I6),1,0)+IF(J6=$G6,IF(L6=$I6,2,0),0)) | O6: - | Q6: =IF(ISBLANK($G6)=TRUE,"",IF(SIGN(N6-P6)=SIGN($G6-$I6),1,0)+IF(N6=$G6,IF(P6=$I6,2,0),0)) | S6: - | U6: =IF(ISBLANK($G6)=TRUE,"",IF(SIGN(R6-T6)=SIGN($G6-$I6),1,0)+IF(R6=$G6,IF(T6=$I6,2,0),0)) | W6: - | Y6: =IF(ISBLANK($G6)=TRUE,"",IF(SIGN(V6-X6)=SIGN($G6-$I6),1,0)+IF(V6=$G6,IF(X6=$I6,2,0),0)) | AA6: - | AC6: =IF(ISBLANK($G6)=TRUE,"",IF(SIGN(Z6-AB6)=SIGN($G6-$I6),1,0)+IF(Z6=$G6,IF(AB6=$I6,2,0),0)) | AE6: - | AG6: =IF(ISBLANK($G6)=TRUE,"",IF(SIGN(AD6-AF6)=SIGN($G6-$I6),1,0)+IF(AD6=$G6,IF(AF6=$I6,2,0),0))
B7: 46203 | C7: 0.79166667 | E7: - | H7: - | K7: - | M7: =IF(ISBLANK($G7)=TRUE,"",IF(SIGN(J7-L7)=SIGN($G7-$I7),1,0)+IF(J7=$G7,IF(L7=$I7,2,0),0)) | O7: - | Q7: =IF(ISBLANK($G7)=TRUE,"",IF(SIGN(N7-P7)=SIGN($G7-$I7),1,0)+IF(N7=$G7,IF(P7=$I7,2,0),0)) | S7: - | U7: =IF(ISBLANK($G7)=TRUE,"",IF(SIGN(R7-T7)=SIGN($G7-$I7),1,0)+IF(R7=$G7,IF(T7=$I7,2,0),0)) | W7: - | Y7: =IF(ISBLANK($G7)=TRUE,"",IF(SIGN(V7-X7)=SIGN($G7-$I7),1,0)+IF(V7=$G7,IF(X7=$I7,2,0),0)) | AA7: - | AC7: =IF(ISBLANK($G7)=TRUE,"",IF(SIGN(Z7-AB7)=SIGN($G7-$I7),1,0)+IF(Z7=$G7,IF(AB7=$I7,2,0),0)) | AE7: - | AG7: =IF(ISBLANK($G7)=TRUE,"",IF(SIGN(AD7-AF7)=SIGN($G7-$I7),1,0)+IF(AD7=$G7,IF(AF7=$I7,2,0),0))
B8: 46203 | C8: 0.95833333 | E8: - | H8: - | K8: - | M8: =IF(ISBLANK($G8)=TRUE,"",IF(SIGN(J8-L8)=SIGN($G8-$I8),1,0)+IF(J8=$G8,IF(L8=$I8,2,0),0)) | O8: - | Q8: =IF(ISBLANK($G8)=TRUE,"",IF(SIGN(N8-P8)=SIGN($G8-$I8),1,0)+IF(N8=$G8,IF(P8=$I8,2,0),0)) | S8: - | U8: =IF(ISBLANK($G8)=TRUE,"",IF(SIGN(R8-T8)=SIGN($G8-$I8),1,0)+IF(R8=$G8,IF(T8=$I8,2,0),0)) | W8: - | Y8: =IF(ISBLANK($G8)=TRUE,"",IF(SIGN(V8-X8)=SIGN($G8-$I8),1,0)+IF(V8=$G8,IF(X8=$I8,2,0),0)) | AA8: - | AC8: =IF(ISBLANK($G8)=TRUE,"",IF(SIGN(Z8-AB8)=SIGN($G8-$I8),1,0)+IF(Z8=$G8,IF(AB8=$I8,2,0),0)) | AE8: - | AG8: =IF(ISBLANK($G8)=TRUE,"",IF(SIGN(AD8-AF8)=SIGN($G8-$I8),1,0)+IF(AD8=$G8,IF(AF8=$I8,2,0),0))
B9: 46204 | C9: 0.125 | E9: - | H9: - | K9: - | M9: =IF(ISBLANK($G9)=TRUE,"",IF(SIGN(J9-L9)=SIGN($G9-$I9),1,0)+IF(J9=$G9,IF(L9=$I9,2,0),0)) | O9: - | Q9: =IF(ISBLANK($G9)=TRUE,"",IF(SIGN(N9-P9)=SIGN($G9-$I9),1,0)+IF(N9=$G9,IF(P9=$I9,2,0),0)) | S9: - | U9: =IF(ISBLANK($G9)=TRUE,"",IF(SIGN(R9-T9)=SIGN($G9-$I9),1,0)+IF(R9=$G9,IF(T9=$I9,2,0),0)) | W9: - | Y9: =IF(ISBLANK($G9)=TRUE,"",IF(SIGN(V9-X9)=SIGN($G9-$I9),1,0)+IF(V9=$G9,IF(X9=$I9,2,0),0)) | AA9: - | AC9: =IF(ISBLANK($G9)=TRUE,"",IF(SIGN(Z9-AB9)=SIGN($G9-$I9),1,0)+IF(Z9=$G9,IF(AB9=$I9,2,0),0)) | AE9: - | AG9: =IF(ISBLANK($G9)=TRUE,"",IF(SIGN(AD9-AF9)=SIGN($G9-$I9),1,0)+IF(AD9=$G9,IF(AF9=$I9,2,0),0))
B10: 46204 | C10: 0.75 | E10: - | H10: - | K10: - | M10: =IF(ISBLANK($G10)=TRUE,"",IF(SIGN(J10-L10)=SIGN($G10-$I10),1,0)+IF(J10=$G10,IF(L10=$I10,2,0),0)) | O10: - | Q10: =IF(ISBLANK($G10)=TRUE,"",IF(SIGN(N10-P10)=SIGN($G10-$I10),1,0)+IF(N10=$G10,IF(P10=$I10,2,0),0)) | S10: - | U10: =IF(ISBLANK($G10)=TRUE,"",IF(SIGN(R10-T10)=SIGN($G10-$I10),1,0)+IF(R10=$G10,IF(T10=$I10,2,0),0)) | W10: - | Y10: =IF(ISBLANK($G10)=TRUE,"",IF(SIGN(V10-X10)=SIGN($G10-$I10),1,0)+IF(V10=$G10,IF(X10=$I10,2,0),0)) | AA10: - | AC10: =IF(ISBLANK($G10)=TRUE,"",IF(SIGN(Z10-AB10)=SIGN($G10-$I10),1,0)+IF(Z10=$G10,IF(AB10=$I10,2,0),0)) | AE10: - | AG10: =IF(ISBLANK($G10)=TRUE,"",IF(SIGN(AD10-AF10)=SIGN($G10-$I10),1,0)+IF(AD10=$G10,IF(AF10=$I10,2,0),0))
B11: 46204 | C11: 0.91666667 | E11: - | H11: - | K11: - | M11: =IF(ISBLANK($G11)=TRUE,"",IF(SIGN(J11-L11)=SIGN($G11-$I11),1,0)+IF(J11=$G11,IF(L11=$I11,2,0),0)) | O11: - | Q11: =IF(ISBLANK($G11)=TRUE,"",IF(SIGN(N11-P11)=SIGN($G11-$I11),1,0)+IF(N11=$G11,IF(P11=$I11,2,0),0)) | S11: - | U11: =IF(ISBLANK($G11)=TRUE,"",IF(SIGN(R11-T11)=SIGN($G11-$I11),1,0)+IF(R11=$G11,IF(T11=$I11,2,0),0)) | W11: - | Y11: =IF(ISBLANK($G11)=TRUE,"",IF(SIGN(V11-X11)=SIGN($G11-$I11),1,0)+IF(V11=$G11,IF(X11=$I11,2,0),0)) | AA11: - | AC11: =IF(ISBLANK($G11)=TRUE,"",IF(SIGN(Z11-AB11)=SIGN($G11-$I11),1,0)+IF(Z11=$G11,IF(AB11=$I11,2,0),0)) | AE11: - | AG11: =IF(ISBLANK($G11)=TRUE,"",IF(SIGN(AD11-AF11)=SIGN($G11-$I11),1,0)+IF(AD11=$G11,IF(AF11=$I11,2,0),0))
B12: 46205 | C12: 0.083333333 | E12: - | H12: - | K12: - | M12: =IF(ISBLANK($G12)=TRUE,"",IF(SIGN(J12-L12)=SIGN($G12-$I12),1,0)+IF(J12=$G12,IF(L12=$I12,2,0),0)) | O12: - | Q12: =IF(ISBLANK($G12)=TRUE,"",IF(SIGN(N12-P12)=SIGN($G12-$I12),1,0)+IF(N12=$G12,IF(P12=$I12,2,0),0)) | S12: - | U12: =IF(ISBLANK($G12)=TRUE,"",IF(SIGN(R12-T12)=SIGN($G12-$I12),1,0)+IF(R12=$G12,IF(T12=$I12,2,0),0)) | W12: - | Y12: =IF(ISBLANK($G12)=TRUE,"",IF(SIGN(V12-X12)=SIGN($G12-$I12),1,0)+IF(V12=$G12,IF(X12=$I12,2,0),0)) | AA12: - | AC12: =IF(ISBLANK($G12)=TRUE,"",IF(SIGN(Z12-AB12)=SIGN($G12-$I12),1,0)+IF(Z12=$G12,IF(AB12=$I12,2,0),0)) | AE12: - | AG12: =IF(ISBLANK($G12)=TRUE,"",IF(SIGN(AD12-AF12)=SIGN($G12-$I12),1,0)+IF(AD12=$G12,IF(AF12=$I12,2,0),0))
B13: 46205 | C13: 0.875 | E13: - | H13: - | K13: - | M13: =IF(ISBLANK($I13)=TRUE,"",IF(SIGN(J13-L13)=SIGN($G13-$I13),1,0)+IF(J13=$G13,IF(L13=$I13,2,0),0)) | O13: - | Q13: =IF(ISBLANK($I13)=TRUE,"",IF(SIGN(N13-P13)=SIGN($G13-$I13),1,0)+IF(N13=$G13,IF(P13=$I13,2,0),0)) | S13: - | U13: =IF(ISBLANK($I13)=TRUE,"",IF(SIGN(R13-T13)=SIGN($G13-$I13),1,0)+IF(R13=$G13,IF(T13=$I13,2,0),0)) | W13: - | Y13: =IF(ISBLANK($I13)=TRUE,"",IF(SIGN(V13-X13)=SIGN($G13-$I13),1,0)+IF(V13=$G13,IF(X13=$I13,2,0),0)) | AA13: - | AC13: =IF(ISBLANK($I13)=TRUE,"",IF(SIGN(Z13-AB13)=SIGN($G13-$I13),1,0)+IF(Z13=$G13,IF(AB13=$I13,2,0),0)) | AE13: - | AG13: =IF(ISBLANK($I13)=TRUE,"",IF(SIGN(AD13-AF13)=SIGN($G13-$I13),1,0)+IF(AD13=$G13,IF(AF13=$I13,2,0),0))
B14: 46206 | C14: 0.041666667 | E14: - | H14: - | K14: - | M14: =IF(ISBLANK($G14)=TRUE,"",IF(SIGN(J14-L14)=SIGN($G14-$I14),1,0)+IF(J14=$G14,IF(L14=$I14,2,0),0)) | O14: - | Q14: =IF(ISBLANK($G14)=TRUE,"",IF(SIGN(N14-P14)=SIGN($G14-$I14),1,0)+IF(N14=$G14,IF(P14=$I14,2,0),0)) | S14: - | U14: =IF(ISBLANK($G14)=TRUE,"",IF(SIGN(R14-T14)=SIGN($G14-$I14),1,0)+IF(R14=$G14,IF(T14=$I14,2,0),0)) | W14: - | Y14: =IF(ISBLANK($G14)=TRUE,"",IF(SIGN(V14-X14)=SIGN($G14-$I14),1,0)+IF(V14=$G14,IF(X14=$I14,2,0),0)) | AA14: - | AC14: =IF(ISBLANK($G14)=TRUE,"",IF(SIGN(Z14-AB14)=SIGN($G14-$I14),1,0)+IF(Z14=$G14,IF(AB14=$I14,2,0),0)) | AE14: - | AG14: =IF(ISBLANK($G14)=TRUE,"",IF(SIGN(AD14-AF14)=SIGN($G14-$I14),1,0)+IF(AD14=$G14,IF(AF14=$I14,2,0),0))
B15: 46206 | C15: 0.20833333 | E15: - | H15: - | K15: - | M15: =IF(ISBLANK($G15)=TRUE,"",IF(SIGN(J15-L15)=SIGN($G15-$I15),1,0)+IF(J15=$G15,IF(L15=$I15,2,0),0)) | O15: - | Q15: =IF(ISBLANK($G15)=TRUE,"",IF(SIGN(N15-P15)=SIGN($G15-$I15),1,0)+IF(N15=$G15,IF(P15=$I15,2,0),0)) | S15: - | U15: =IF(ISBLANK($G15)=TRUE,"",IF(SIGN(R15-T15)=SIGN($G15-$I15),1,0)+IF(R15=$G15,IF(T15=$I15,2,0),0)) | W15: - | Y15: =IF(ISBLANK($G15)=TRUE,"",IF(SIGN(V15-X15)=SIGN($G15-$I15),1,0)+IF(V15=$G15,IF(X15=$I15,2,0),0)) | AA15: - | AC15: =IF(ISBLANK($G15)=TRUE,"",IF(SIGN(Z15-AB15)=SIGN($G15-$I15),1,0)+IF(Z15=$G15,IF(AB15=$I15,2,0),0)) | AE15: - | AG15: =IF(ISBLANK($G15)=TRUE,"",IF(SIGN(AD15-AF15)=SIGN($G15-$I15),1,0)+IF(AD15=$G15,IF(AF15=$I15,2,0),0))
B16: 46206 | C16: 0.83333333 | E16: - | H16: - | K16: - | M16: =IF(ISBLANK($G16)=TRUE,"",IF(SIGN(J16-L16)=SIGN($G16-$I16),1,0)+IF(J16=$G16,IF(L16=$I16,2,0),0)) | O16: - | Q16: =IF(ISBLANK($G16)=TRUE,"",IF(SIGN(N16-P16)=SIGN($G16-$I16),1,0)+IF(N16=$G16,IF(P16=$I16,2,0),0)) | S16: - | U16: =IF(ISBLANK($G16)=TRUE,"",IF(SIGN(R16-T16)=SIGN($G16-$I16),1,0)+IF(R16=$G16,IF(T16=$I16,2,0),0)) | W16: - | Y16: =IF(ISBLANK($G16)=TRUE,"",IF(SIGN(V16-X16)=SIGN($G16-$I16),1,0)+IF(V16=$G16,IF(X16=$I16,2,0),0)) | AA16: - | AC16: =IF(ISBLANK($G16)=TRUE,"",IF(SIGN(Z16-AB16)=SIGN($G16-$I16),1,0)+IF(Z16=$G16,IF(AB16=$I16,2,0),0)) | AE16: - | AG16: =IF(ISBLANK($G16)=TRUE,"",IF(SIGN(AD16-AF16)=SIGN($G16-$I16),1,0)+IF(AD16=$G16,IF(AF16=$I16,2,0),0))
B17: 46207 | C17: 0 | E17: - | H17: - | K17: - | M17: =IF(ISBLANK($G17)=TRUE,"",IF(SIGN(J17-L17)=SIGN($G17-$I17),1,0)+IF(J17=$G17,IF(L17=$I17,2,0),0)) | O17: - | Q17: =IF(ISBLANK($G17)=TRUE,"",IF(SIGN(N17-P17)=SIGN($G17-$I17),1,0)+IF(N17=$G17,IF(P17=$I17,2,0),0)) | S17: - | U17: =IF(ISBLANK($G17)=TRUE,"",IF(SIGN(R17-T17)=SIGN($G17-$I17),1,0)+IF(R17=$G17,IF(T17=$I17,2,0),0)) | W17: - | Y17: =IF(ISBLANK($G17)=TRUE,"",IF(SIGN(V17-X17)=SIGN($G17-$I17),1,0)+IF(V17=$G17,IF(X17=$I17,2,0),0)) | AA17: - | AC17: =IF(ISBLANK($G17)=TRUE,"",IF(SIGN(Z17-AB17)=SIGN($G17-$I17),1,0)+IF(Z17=$G17,IF(AB17=$I17,2,0),0)) | AE17: - | AG17: =IF(ISBLANK($G17)=TRUE,"",IF(SIGN(AD17-AF17)=SIGN($G17-$I17),1,0)+IF(AD17=$G17,IF(AF17=$I17,2,0),0))
B18: 46207 | C18: 0.14583333 | E18: - | H18: - | K18: - | M18: =IF(ISBLANK($G18)=TRUE,"",IF(SIGN(J18-L18)=SIGN($G18-$I18),1,0)+IF(J18=$G18,IF(L18=$I18,2,0),0)) | O18: - | Q18: =IF(ISBLANK($G18)=TRUE,"",IF(SIGN(N18-P18)=SIGN($G18-$I18),1,0)+IF(N18=$G18,IF(P18=$I18,2,0),0)) | S18: - | U18: =IF(ISBLANK($G18)=TRUE,"",IF(SIGN(R18-T18)=SIGN($G18-$I18),1,0)+IF(R18=$G18,IF(T18=$I18,2,0),0)) | W18: - | Y18: =IF(ISBLANK($G18)=TRUE,"",IF(SIGN(V18-X18)=SIGN($G18-$I18),1,0)+IF(V18=$G18,IF(X18=$I18,2,0),0)) | AA18: - | AC18: =IF(ISBLANK($G18)=TRUE,"",IF(SIGN(Z18-AB18)=SIGN($G18-$I18),1,0)+IF(Z18=$G18,IF(AB18=$I18,2,0),0)) | AE18: - | AG18: =IF(ISBLANK($G18)=TRUE,"",IF(SIGN(AD18-AF18)=SIGN($G18-$I18),1,0)+IF(AD18=$G18,IF(AF18=$I18,2,0),0))
B19: Dato | C19: Kl. | D19: Åttendelsfinaler | G19: Resultat
B20: 46207 | C20: 0.79166667 | E20: - | H20: - | K20: - | M20: =IF(ISBLANK($I20)=TRUE,"",IF(SIGN(J20-L20)=SIGN($G20-$I20),1,0)+IF(J20=$G20,IF(L20=$I20,2,0),0)) | O20: - | Q20: =IF(ISBLANK($I20)=TRUE,"",IF(SIGN(N20-P20)=SIGN($G20-$I20),1,0)+IF(N20=$G20,IF(P20=$I20,2,0),0)) | S20: - | U20: =IF(ISBLANK($I20)=TRUE,"",IF(SIGN(R20-T20)=SIGN($G20-$I20),1,0)+IF(R20=$G20,IF(T20=$I20,2,0),0)) | W20: - | Y20: =IF(ISBLANK($I20)=TRUE,"",IF(SIGN(V20-X20)=SIGN($G20-$I20),1,0)+IF(V20=$G20,IF(X20=$I20,2,0),0)) | AA20: - | AC20: =IF(ISBLANK($I20)=TRUE,"",IF(SIGN(Z20-AB20)=SIGN($G20-$I20),1,0)+IF(Z20=$G20,IF(AB20=$I20,2,0),0)) | AE20: - | AG20: =IF(ISBLANK($I20)=TRUE,"",IF(SIGN(AD20-AF20)=SIGN($G20-$I20),1,0)+IF(AD20=$G20,IF(AF20=$I20,2,0),0))
B21: 46207 | C21: 0.95833333 | E21: - | H21: - | K21: - | M21: =IF(ISBLANK($G21)=TRUE,"",IF(SIGN(J21-L21)=SIGN($G21-$I21),1,0)+IF(J21=$G21,IF(L21=$I21,2,0),0)) | O21: - | Q21: =IF(ISBLANK($G21)=TRUE,"",IF(SIGN(N21-P21)=SIGN($G21-$I21),1,0)+IF(N21=$G21,IF(P21=$I21,2,0),0)) | S21: - | U21: =IF(ISBLANK($G21)=TRUE,"",IF(SIGN(R21-T21)=SIGN($G21-$I21),1,0)+IF(R21=$G21,IF(T21=$I21,2,0),0)) | W21: - | Y21: =IF(ISBLANK($G21)=TRUE,"",IF(SIGN(V21-X21)=SIGN($G21-$I21),1,0)+IF(V21=$G21,IF(X21=$I21,2,0),0)) | AA21: - | AC21: =IF(ISBLANK($G21)=TRUE,"",IF(SIGN(Z21-AB21)=SIGN($G21-$I21),1,0)+IF(Z21=$G21,IF(AB21=$I21,2,0),0)) | AE21: - | AG21: =IF(ISBLANK($G21)=TRUE,"",IF(SIGN(AD21-AF21)=SIGN($G21-$I21),1,0)+IF(AD21=$G21,IF(AF21=$I21,2,0),0))
B22: 46208 | C22: 0.91666667 | E22: - | H22: - | K22: - | M22: =IF(ISBLANK($G22)=TRUE,"",IF(SIGN(J22-L22)=SIGN($G22-$I22),1,0)+IF(J22=$G22,IF(L22=$I22,2,0),0)) | O22: - | Q22: =IF(ISBLANK($G22)=TRUE,"",IF(SIGN(N22-P22)=SIGN($G22-$I22),1,0)+IF(N22=$G22,IF(P22=$I22,2,0),0)) | S22: - | U22: =IF(ISBLANK($G22)=TRUE,"",IF(SIGN(R22-T22)=SIGN($G22-$I22),1,0)+IF(R22=$G22,IF(T22=$I22,2,0),0)) | W22: - | Y22: =IF(ISBLANK($G22)=TRUE,"",IF(SIGN(V22-X22)=SIGN($G22-$I22),1,0)+IF(V22=$G22,IF(X22=$I22,2,0),0)) | AA22: - | AC22: =IF(ISBLANK($G22)=TRUE,"",IF(SIGN(Z22-AB22)=SIGN($G22-$I22),1,0)+IF(Z22=$G22,IF(AB22=$I22,2,0),0)) | AE22: - | AG22: =IF(ISBLANK($G22)=TRUE,"",IF(SIGN(AD22-AF22)=SIGN($G22-$I22),1,0)+IF(AD22=$G22,IF(AF22=$I22,2,0),0))
B23: 46209 | C23: 0.083333333 | E23: - | H23: - | K23: - | M23: =IF(ISBLANK($G23)=TRUE,"",IF(SIGN(J23-L23)=SIGN($G23-$I23),1,0)+IF(J23=$G23,IF(L23=$I23,2,0),0)) | O23: - | Q23: =IF(ISBLANK($G23)=TRUE,"",IF(SIGN(N23-P23)=SIGN($G23-$I23),1,0)+IF(N23=$G23,IF(P23=$I23,2,0),0)) | S23: - | U23: =IF(ISBLANK($G23)=TRUE,"",IF(SIGN(R23-T23)=SIGN($G23-$I23),1,0)+IF(R23=$G23,IF(T23=$I23,2,0),0)) | W23: - | Y23: =IF(ISBLANK($G23)=TRUE,"",IF(SIGN(V23-X23)=SIGN($G23-$I23),1,0)+IF(V23=$G23,IF(X23=$I23,2,0),0)) | AA23: - | AC23: =IF(ISBLANK($G23)=TRUE,"",IF(SIGN(Z23-AB23)=SIGN($G23-$I23),1,0)+IF(Z23=$G23,IF(AB23=$I23,2,0),0)) | AE23: - | AG23: =IF(ISBLANK($G23)=TRUE,"",IF(SIGN(AD23-AF23)=SIGN($G23-$I23),1,0)+IF(AD23=$G23,IF(AF23=$I23,2,0),0))
B24: 46209 | C24: 0.875 | E24: - | H24: - | K24: - | M24: =IF(ISBLANK($G24)=TRUE,"",IF(SIGN(J24-L24)=SIGN($G24-$I24),1,0)+IF(J24=$G24,IF(L24=$I24,2,0),0)) | O24: - | Q24: =IF(ISBLANK($G24)=TRUE,"",IF(SIGN(N24-P24)=SIGN($G24-$I24),1,0)+IF(N24=$G24,IF(P24=$I24,2,0),0)) | S24: - | U24: =IF(ISBLANK($G24)=TRUE,"",IF(SIGN(R24-T24)=SIGN($G24-$I24),1,0)+IF(R24=$G24,IF(T24=$I24,2,0),0)) | W24: - | Y24: =IF(ISBLANK($G24)=TRUE,"",IF(SIGN(V24-X24)=SIGN($G24-$I24),1,0)+IF(V24=$G24,IF(X24=$I24,2,0),0)) | AA24: - | AC24: =IF(ISBLANK($G24)=TRUE,"",IF(SIGN(Z24-AB24)=SIGN($G24-$I24),1,0)+IF(Z24=$G24,IF(AB24=$I24,2,0),0)) | AE24: - | AG24: =IF(ISBLANK($G24)=TRUE,"",IF(SIGN(AD24-AF24)=SIGN($G24-$I24),1,0)+IF(AD24=$G24,IF(AF24=$I24,2,0),0))
B25: 46210 | C25: 0.083333333 | E25: - | H25: - | K25: - | M25: =IF(ISBLANK($G25)=TRUE,"",IF(SIGN(J25-L25)=SIGN($G25-$I25),1,0)+IF(J25=$G25,IF(L25=$I25,2,0),0)) | O25: - | Q25: =IF(ISBLANK($G25)=TRUE,"",IF(SIGN(N25-P25)=SIGN($G25-$I25),1,0)+IF(N25=$G25,IF(P25=$I25,2,0),0)) | S25: - | U25: =IF(ISBLANK($G25)=TRUE,"",IF(SIGN(R25-T25)=SIGN($G25-$I25),1,0)+IF(R25=$G25,IF(T25=$I25,2,0),0)) | W25: - | Y25: =IF(ISBLANK($G25)=TRUE,"",IF(SIGN(V25-X25)=SIGN($G25-$I25),1,0)+IF(V25=$G25,IF(X25=$I25,2,0),0)) | AA25: - | AC25: =IF(ISBLANK($G25)=TRUE,"",IF(SIGN(Z25-AB25)=SIGN($G25-$I25),1,0)+IF(Z25=$G25,IF(AB25=$I25,2,0),0)) | AE25: - | AG25: =IF(ISBLANK($G25)=TRUE,"",IF(SIGN(AD25-AF25)=SIGN($G25-$I25),1,0)+IF(AD25=$G25,IF(AF25=$I25,2,0),0))
B26: 46210 | C26: 0.75 | E26: - | H26: - | K26: - | M26: =IF(ISBLANK($G26)=TRUE,"",IF(SIGN(J26-L26)=SIGN($G26-$I26),1,0)+IF(J26=$G26,IF(L26=$I26,2,0),0)) | O26: - | Q26: =IF(ISBLANK($G26)=TRUE,"",IF(SIGN(N26-P26)=SIGN($G26-$I26),1,0)+IF(N26=$G26,IF(P26=$I26,2,0),0)) | S26: - | U26: =IF(ISBLANK($G26)=TRUE,"",IF(SIGN(R26-T26)=SIGN($G26-$I26),1,0)+IF(R26=$G26,IF(T26=$I26,2,0),0)) | W26: - | Y26: =IF(ISBLANK($G26)=TRUE,"",IF(SIGN(V26-X26)=SIGN($G26-$I26),1,0)+IF(V26=$G26,IF(X26=$I26,2,0),0)) | AA26: - | AC26: =IF(ISBLANK($G26)=TRUE,"",IF(SIGN(Z26-AB26)=SIGN($G26-$I26),1,0)+IF(Z26=$G26,IF(AB26=$I26,2,0),0)) | AE26: - | AG26: =IF(ISBLANK($G26)=TRUE,"",IF(SIGN(AD26-AF26)=SIGN($G26-$I26),1,0)+IF(AD26=$G26,IF(AF26=$I26,2,0),0))
B27: 46210 | C27: 0.91666667 | E27: - | H27: - | K27: - | M27: =IF(ISBLANK($G27)=TRUE,"",IF(SIGN(J27-L27)=SIGN($G27-$I27),1,0)+IF(J27=$G27,IF(L27=$I27,2,0),0)) | O27: - | Q27: =IF(ISBLANK($G27)=TRUE,"",IF(SIGN(N27-P27)=SIGN($G27-$I27),1,0)+IF(N27=$G27,IF(P27=$I27,2,0),0)) | S27: - | U27: =IF(ISBLANK($G27)=TRUE,"",IF(SIGN(R27-T27)=SIGN($G27-$I27),1,0)+IF(R27=$G27,IF(T27=$I27,2,0),0)) | W27: - | Y27: =IF(ISBLANK($G27)=TRUE,"",IF(SIGN(V27-X27)=SIGN($G27-$I27),1,0)+IF(V27=$G27,IF(X27=$I27,2,0),0)) | AA27: - | AC27: =IF(ISBLANK($G27)=TRUE,"",IF(SIGN(Z27-AB27)=SIGN($G27-$I27),1,0)+IF(Z27=$G27,IF(AB27=$I27,2,0),0)) | AE27: - | AG27: =IF(ISBLANK($G27)=TRUE,"",IF(SIGN(AD27-AF27)=SIGN($G27-$I27),1,0)+IF(AD27=$G27,IF(AF27=$I27,2,0),0))
B28: Dato | C28: Kl. | D28: Kvartfinaler | G28: Resultat
B29: 46212 | C29: 0.91666667 | E29: - | H29: - | K29: - | M29: =IF(ISBLANK($I29)=TRUE,"",IF(SIGN(J29-L29)=SIGN($G29-$I29),1,0)+IF(J29=$G29,IF(L29=$I29,2,0),0)) | O29: - | Q29: =IF(ISBLANK($I29)=TRUE,"",IF(SIGN(N29-P29)=SIGN($G29-$I29),1,0)+IF(N29=$G29,IF(P29=$I29,2,0),0)) | S29: - | U29: =IF(ISBLANK($I29)=TRUE,"",IF(SIGN(R29-T29)=SIGN($G29-$I29),1,0)+IF(R29=$G29,IF(T29=$I29,2,0),0)) | W29: - | Y29: =IF(ISBLANK($I29)=TRUE,"",IF(SIGN(V29-X29)=SIGN($G29-$I29),1,0)+IF(V29=$G29,IF(X29=$I29,2,0),0)) | AA29: - | AC29: =IF(ISBLANK($I29)=TRUE,"",IF(SIGN(Z29-AB29)=SIGN($G29-$I29),1,0)+IF(Z29=$G29,IF(AB29=$I29,2,0),0)) | AE29: - | AG29: =IF(ISBLANK($I29)=TRUE,"",IF(SIGN(AD29-AF29)=SIGN($G29-$I29),1,0)+IF(AD29=$G29,IF(AF29=$I29,2,0),0))
B30: 46213 | C30: 0.875 | E30: - | H30: - | K30: - | M30: =IF(ISBLANK($G30)=TRUE,"",IF(SIGN(J30-L30)=SIGN($G30-$I30),1,0)+IF(J30=$G30,IF(L30=$I30,2,0),0)) | O30: - | Q30: =IF(ISBLANK($G30)=TRUE,"",IF(SIGN(N30-P30)=SIGN($G30-$I30),1,0)+IF(N30=$G30,IF(P30=$I30,2,0),0)) | S30: - | U30: =IF(ISBLANK($G30)=TRUE,"",IF(SIGN(R30-T30)=SIGN($G30-$I30),1,0)+IF(R30=$G30,IF(T30=$I30,2,0),0)) | W30: - | Y30: =IF(ISBLANK($G30)=TRUE,"",IF(SIGN(V30-X30)=SIGN($G30-$I30),1,0)+IF(V30=$G30,IF(X30=$I30,2,0),0)) | AA30: - | AC30: =IF(ISBLANK($G30)=TRUE,"",IF(SIGN(Z30-AB30)=SIGN($G30-$I30),1,0)+IF(Z30=$G30,IF(AB30=$I30,2,0),0)) | AE30: - | AG30: =IF(ISBLANK($G30)=TRUE,"",IF(SIGN(AD30-AF30)=SIGN($G30-$I30),1,0)+IF(AD30=$G30,IF(AF30=$I30,2,0),0))
B31: 46214 | C31: 0.95833333 | E31: - | H31: - | K31: - | M31: =IF(ISBLANK($G31)=TRUE,"",IF(SIGN(J31-L31)=SIGN($G31-$I31),1,0)+IF(J31=$G31,IF(L31=$I31,2,0),0)) | O31: - | Q31: =IF(ISBLANK($G31)=TRUE,"",IF(SIGN(N31-P31)=SIGN($G31-$I31),1,0)+IF(N31=$G31,IF(P31=$I31,2,0),0)) | S31: - | U31: =IF(ISBLANK($G31)=TRUE,"",IF(SIGN(R31-T31)=SIGN($G31-$I31),1,0)+IF(R31=$G31,IF(T31=$I31,2,0),0)) | W31: - | Y31: =IF(ISBLANK($G31)=TRUE,"",IF(SIGN(V31-X31)=SIGN($G31-$I31),1,0)+IF(V31=$G31,IF(X31=$I31,2,0),0)) | AA31: - | AC31: =IF(ISBLANK($G31)=TRUE,"",IF(SIGN(Z31-AB31)=SIGN($G31-$I31),1,0)+IF(Z31=$G31,IF(AB31=$I31,2,0),0)) | AE31: - | AG31: =IF(ISBLANK($G31)=TRUE,"",IF(SIGN(AD31-AF31)=SIGN($G31-$I31),1,0)+IF(AD31=$G31,IF(AF31=$I31,2,0),0))
B32: 46215 | C32: 0.125 | E32: - | H32: - | K32: - | M32: =IF(ISBLANK($G32)=TRUE,"",IF(SIGN(J32-L32)=SIGN($G32-$I32),1,0)+IF(J32=$G32,IF(L32=$I32,2,0),0)) | O32: - | Q32: =IF(ISBLANK($G32)=TRUE,"",IF(SIGN(N32-P32)=SIGN($G32-$I32),1,0)+IF(N32=$G32,IF(P32=$I32,2,0),0)) | S32: - | U32: =IF(ISBLANK($G32)=TRUE,"",IF(SIGN(R32-T32)=SIGN($G32-$I32),1,0)+IF(R32=$G32,IF(T32=$I32,2,0),0)) | W32: - | Y32: =IF(ISBLANK($G32)=TRUE,"",IF(SIGN(V32-X32)=SIGN($G32-$I32),1,0)+IF(V32=$G32,IF(X32=$I32,2,0),0)) | AA32: - | AC32: =IF(ISBLANK($G32)=TRUE,"",IF(SIGN(Z32-AB32)=SIGN($G32-$I32),1,0)+IF(Z32=$G32,IF(AB32=$I32,2,0),0)) | AE32: - | AG32: =IF(ISBLANK($G32)=TRUE,"",IF(SIGN(AD32-AF32)=SIGN($G32-$I32),1,0)+IF(AD32=$G32,IF(AF32=$I32,2,0),0))
B33: Dato | C33: Kl. | D33: Semifinaler | G33: Resultat
B34: 46217 | C34: 0.875 | E34: - | H34: - | K34: - | M34: =IF(ISBLANK($I34)=TRUE,"",IF(SIGN(J34-L34)=SIGN($G34-$I34),1,0)+IF(J34=$G34,IF(L34=$I34,2,0),0)) | O34: - | Q34: =IF(ISBLANK($I34)=TRUE,"",IF(SIGN(N34-P34)=SIGN($G34-$I34),1,0)+IF(N34=$G34,IF(P34=$I34,2,0),0)) | S34: - | U34: =IF(ISBLANK($I34)=TRUE,"",IF(SIGN(R34-T34)=SIGN($G34-$I34),1,0)+IF(R34=$G34,IF(T34=$I34,2,0),0)) | W34: - | Y34: =IF(ISBLANK($I34)=TRUE,"",IF(SIGN(V34-X34)=SIGN($G34-$I34),1,0)+IF(V34=$G34,IF(X34=$I34,2,0),0)) | AA34: - | AC34: =IF(ISBLANK($I34)=TRUE,"",IF(SIGN(Z34-AB34)=SIGN($G34-$I34),1,0)+IF(Z34=$G34,IF(AB34=$I34,2,0),0)) | AE34: - | AG34: =IF(ISBLANK($I34)=TRUE,"",IF(SIGN(AD34-AF34)=SIGN($G34-$I34),1,0)+IF(AD34=$G34,IF(AF34=$I34,2,0),0))
B35: 46218 | C35: 0.875 | E35: - | H35: - | K35: - | M35: =IF(ISBLANK($G35)=TRUE,"",IF(SIGN(J35-L35)=SIGN($G35-$I35),1,0)+IF(J35=$G35,IF(L35=$I35,2,0),0)) | O35: - | Q35: =IF(ISBLANK($G35)=TRUE,"",IF(SIGN(N35-P35)=SIGN($G35-$I35),1,0)+IF(N35=$G35,IF(P35=$I35,2,0),0)) | S35: - | U35: =IF(ISBLANK($G35)=TRUE,"",IF(SIGN(R35-T35)=SIGN($G35-$I35),1,0)+IF(R35=$G35,IF(T35=$I35,2,0),0)) | W35: - | Y35: =IF(ISBLANK($G35)=TRUE,"",IF(SIGN(V35-X35)=SIGN($G35-$I35),1,0)+IF(V35=$G35,IF(X35=$I35,2,0),0)) | AA35: - | AC35: =IF(ISBLANK($G35)=TRUE,"",IF(SIGN(Z35-AB35)=SIGN($G35-$I35),1,0)+IF(Z35=$G35,IF(AB35=$I35,2,0),0)) | AE35: - | AG35: =IF(ISBLANK($G35)=TRUE,"",IF(SIGN(AD35-AF35)=SIGN($G35-$I35),1,0)+IF(AD35=$G35,IF(AF35=$I35,2,0),0))
B36: Dato | C36: Kl. | D36: Bronsefinale | G36: Resultat
B37: 46221 | C37: 0.95833333 | E37: - | H37: - | K37: - | M37: =IF(ISBLANK($I37)=TRUE,"",IF(SIGN(J37-L37)=SIGN($G37-$I37),1,0)+IF(J37=$G37,IF(L37=$I37,2,0),0)) | O37: - | Q37: =IF(ISBLANK($I37)=TRUE,"",IF(SIGN(N37-P37)=SIGN($G37-$I37),1,0)+IF(N37=$G37,IF(P37=$I37,2,0),0)) | S37: - | U37: =IF(ISBLANK($I37)=TRUE,"",IF(SIGN(R37-T37)=SIGN($G37-$I37),1,0)+IF(R37=$G37,IF(T37=$I37,2,0),0)) | W37: - | Y37: =IF(ISBLANK($I37)=TRUE,"",IF(SIGN(V37-X37)=SIGN($G37-$I37),1,0)+IF(V37=$G37,IF(X37=$I37,2,0),0)) | AA37: - | AC37: =IF(ISBLANK($I37)=TRUE,"",IF(SIGN(Z37-AB37)=SIGN($G37-$I37),1,0)+IF(Z37=$G37,IF(AB37=$I37,2,0),0)) | AE37: - | AG37: =IF(ISBLANK($I37)=TRUE,"",IF(SIGN(AD37-AF37)=SIGN($G37-$I37),1,0)+IF(AD37=$G37,IF(AF37=$I37,2,0),0))
B38: Dato | C38: Kl. | D38: Finale | G38: Resultat
B39: 46222 | C39: 0.875 | E39: - | H39: - | K39: - | M39: =IF(ISBLANK($I39)=TRUE,"",IF(SIGN(J39-L39)=SIGN($G39-$I39),1,0)+IF(J39=$G39,IF(L39=$I39,2,0),0)) | O39: - | Q39: =IF(ISBLANK($I39)=TRUE,"",IF(SIGN(N39-P39)=SIGN($G39-$I39),1,0)+IF(N39=$G39,IF(P39=$I39,2,0),0)) | S39: - | U39: =IF(ISBLANK($I39)=TRUE,"",IF(SIGN(R39-T39)=SIGN($G39-$I39),1,0)+IF(R39=$G39,IF(T39=$I39,2,0),0)) | W39: - | Y39: =IF(ISBLANK($I39)=TRUE,"",IF(SIGN(V39-X39)=SIGN($G39-$I39),1,0)+IF(V39=$G39,IF(X39=$I39,2,0),0)) | AA39: - | AC39: =IF(ISBLANK($I39)=TRUE,"",IF(SIGN(Z39-AB39)=SIGN($G39-$I39),1,0)+IF(Z39=$G39,IF(AB39=$I39,2,0),0)) | AE39: - | AG39: =IF(ISBLANK($I39)=TRUE,"",IF(SIGN(AD39-AF39)=SIGN($G39-$I39),1,0)+IF(AD39=$G39,IF(AF39=$I39,2,0),0))
B40: Poeng utslagsrunder | J40: =SUM(M3:M39) -> 0 | N40: =SUM(Q3:Q39) -> 0 | R40: =SUM(U3:U39) -> 0 | V40: =SUM(Y3:Y39) -> 0 | Z40: =SUM(AC3:AC39) -> 0 | AD40: =SUM(AG3:AG39) -> 0

Sheet Krydderspørsmål
B2: Krydderspørsmål | E2: Fasit | G2: Erling | I2: Rune | K2: Håkon | M2: Geir | O2: Tore | Q2: Tor Arne
B3: 1. | C3: Hvem vinner VM? | D3: 5p | G3: Frankrike | H3: =IF(ISBLANK($E3)=TRUE,"",IF($E3=G3,5,0)) | I3: Spania | J3: =IF(ISBLANK($E3)=TRUE,"",IF($E3=I3,5,0)) | K3: Frankrike | L3: =IF(ISBLANK($E3)=TRUE,"",IF($E3=K3,5,0)) | N3: =IF(ISBLANK($E3)=TRUE,"",IF($E3=M3,5,0)) | O3: Frankrike | P3: =IF(ISBLANK($E3)=TRUE,"",IF($E3=O3,5,0)) | Q3: England | R3: =IF(ISBLANK($E3)=TRUE,"",IF($E3=Q3,5,0))
B4: 2. | C4: Hvem vinner Gullballen (beste spiller)? | D4: 5p | G4: Mbappe | H4: =IF(ISBLANK($E4)=TRUE,"",IF($E4=G4,5,0)) | I4: Yamal | J4: =IF(ISBLANK($E4)=TRUE,"",IF($E4=I4,5,0)) | K4: Mbappe | L4: =IF(ISBLANK($E4)=TRUE,"",IF($E4=K4,5,0)) | N4: =IF(ISBLANK($E4)=TRUE,"",IF($E4=M4,5,0)) | O4: Haaland | P4: =IF(ISBLANK($E4)=TRUE,"",IF($E4=O4,5,0)) | Q4: Harry Kane | R4: =IF(ISBLANK($E4)=TRUE,"",IF($E4=Q4,5,0))
B5: 3. | C5: Hvem vinner Gullstøvelen (toppscorer)? | D5: 5p | G5: Mbappe | H5: =IF(ISBLANK($E5)=TRUE,"",IF($E5=G5,5,0)) | I5: Mbappe | J5: =IF(ISBLANK($E5)=TRUE,"",IF($E5=I5,5,0)) | K5: Kane | L5: =IF(ISBLANK($E5)=TRUE,"",IF($E5=K5,5,0)) | N5: =IF(ISBLANK($E5)=TRUE,"",IF($E5=M5,5,0)) | O5: Bellingham | P5: =IF(ISBLANK($E5)=TRUE,"",IF($E5=O5,5,0)) | Q5: Harry Kane | R5: =IF(ISBLANK($E5)=TRUE,"",IF($E5=Q5,5,0))
B6: 4. | C6: Hvem vinner FIFA Young player of the Tournament? | D6: 3p | G6: Yamal | H6: =IF(ISBLANK($E6)=TRUE,"",IF($E6=G6,3,0)) | I6: Yamal | J6: =IF(ISBLANK($E6)=TRUE,"",IF($E6=I6,3,0)) | K6: Yamal | L6: =IF(ISBLANK($E6)=TRUE,"",IF($E6=K6,3,0)) | N6: =IF(ISBLANK($E6)=TRUE,"",IF($E6=M6,3,0)) | O6: Yamal | P6: =IF(ISBLANK($E6)=TRUE,"",IF($E6=O6,3,0)) | Q6: Antonio Nusa | R6: =IF(ISBLANK($E6)=TRUE,"",IF($E6=Q6,3,0))
B7: 5. | C7: Hvor mange mål scores det totalt i VM? | D7: 2p | G7: 241 | H7: =IF(ISBLANK($E7)=TRUE,"",IF($E7=G7,2,0)) | I7: 168 | J7: =IF(ISBLANK($E7)=TRUE,"",IF($E7=I7,2,0)) | K7: 335 | L7: =IF(ISBLANK($E7)=TRUE,"",IF($E7=K7,2,0)) | N7: =IF(ISBLANK($E7)=TRUE,"",IF($E7=M7,2,0)) | O7: 299 | P7: =IF(ISBLANK($E7)=TRUE,"",IF($E7=O7,2,0)) | Q7: 333 | R7: =IF(ISBLANK($E7)=TRUE,"",IF($E7=Q7,2,0))
E8: Antall mål scoret så langt | F8: =SUM(Gruppespill!G3:G85,Gruppespill!I3:I85,Utslagsrunder!G3:G39,Utslagsrunder!I3:I39) -> 0
E9: Estimert antall mål i VM | F9: =IF(ISBLANK(Gruppespill!G3),"",(F8/(COUNT(Gruppespill!G3:G85,Utslagsrunder!G3:G39)))*104)
B10: 6. | C10: Hvilket tidspunkt scores det raskeste målet? (±15 sek.) | D10: 2p | G10: 0.00040509259 | H10: =IF(ISBLANK($E10),"",IF(ABS($E10-G10)<TIME(0,0,16),2,0)) | I10: 0.00060185185 | J10: =IF(ISBLANK($E10),"",IF(ABS($E10-I10)<TIME(0,0,16),2,0)) | K10: 0.0023842593 | L10: =IF(ISBLANK($E10),"",IF(ABS($E10-K10)<TIME(0,0,16),2,0)) | N10: =IF(ISBLANK($E10),"",IF(ABS($E10-M10)<TIME(0,0,16),2,0)) | O10: 0.0017361111 | P10: =IF(ISBLANK($E10),"",IF(ABS($E10-O10)<TIME(0,0,16),2,0)) | Q10: 0.0041666667 | R10: =IF(ISBLANK($E10),"",IF(ABS($E10-Q10)<TIME(0,0,16),2,0))
B11: 7. | C11: Nevn to lag som får rødt kort i løpet av VM. | D11: 2p | G11: Nederland | H11: =IF(ISBLANK($E11)=TRUE,"",IF(ISNUMBER(SEARCH(G11,$E11)),2,0)) | I11: Marokko | J11: =IF(ISBLANK($E11)=TRUE,"",IF(ISNUMBER(SEARCH(I11,$E11)),2,0)) | K11: Irak | L11: =IF(ISBLANK($E11)=TRUE,"",IF(ISNUMBER(SEARCH(K11,$E11)),2,0)) | N11: =IF(ISBLANK($E11)=TRUE,"",IF(ISNUMBER(SEARCH(M11,$E11)),2,0)) | O11: Tyrkia | P11: =IF(ISBLANK($E11)=TRUE,"",IF(ISNUMBER(SEARCH(O11,$E11)),2,0)) | Q11: Haiti | R11: =IF(ISBLANK($E11)=TRUE,"",IF(ISNUMBER(SEARCH(Q11,$E11)),2,0))
G12: Portugal | H12: =IF(ISBLANK($E11)=TRUE,"",IF(ISNUMBER(SEARCH(G12,$E11)),2,0)) | I12: Argentina | J12: =IF(ISBLANK($E11)=TRUE,"",IF(ISNUMBER(SEARCH(I12,$E11)),2,0)) | K12: Iran | L12: =IF(ISBLANK($E11)=TRUE,"",IF(ISNUMBER(SEARCH(K12,$E11)),2,0)) | N12: =IF(ISBLANK($E11)=TRUE,"",IF(ISNUMBER(SEARCH(M12,$E11)),2,0)) | O12: Ecuador | P12: =IF(ISBLANK($E11)=TRUE,"",IF(ISNUMBER(SEARCH(O12,$E11)),2,0)) | Q12: Elfenbenskysten | R12: =IF(ISBLANK($E11)=TRUE,"",IF(ISNUMBER(SEARCH(Q12,$E11)),2,0))
B13: 8. | C13: Nevn to lag som scorer selvmål i løpet av VM. | D13: 2p | G13: Curacao | H13: =IF(ISBLANK($E13)=TRUE,"",IF(ISNUMBER(SEARCH(G13,$E13)),2,0)) | I13: Brasil | J13: =IF(ISBLANK($E13)=TRUE,"",IF(ISNUMBER(SEARCH(I13,$E13)),2,0)) | K13: Norge | L13: =IF(ISBLANK($E13)=TRUE,"",IF(ISNUMBER(SEARCH(K13,$E13)),2,0)) | N13: =IF(ISBLANK($E13)=TRUE,"",IF(ISNUMBER(SEARCH(M13,$E13)),2,0)) | O13: Sør-Afrika | P13: =IF(ISBLANK($E13)=TRUE,"",IF(ISNUMBER(SEARCH(O13,$E13)),2,0)) | Q13: Sverige | R13: =IF(ISBLANK($E13)=TRUE,"",IF(ISNUMBER(SEARCH(Q13,$E13)),2,0))
G14: Kapp Verde | H14: =IF(ISBLANK($E13)=TRUE,"",IF(ISNUMBER(SEARCH(G14,$E13)),2,0)) | I14: England | J14: =IF(ISBLANK($E13)=TRUE,"",IF(ISNUMBER(SEARCH(I14,$E13)),2,0)) | K14: USA | L14: =IF(ISBLANK($E13)=TRUE,"",IF(ISNUMBER(SEARCH(K14,$E13)),2,0)) | N14: =IF(ISBLANK($E13)=TRUE,"",IF(ISNUMBER(SEARCH(M14,$E13)),2,0)) | O14: Skottland | P14: =IF(ISBLANK($E13)=TRUE,"",IF(ISNUMBER(SEARCH(O14,$E13)),2,0)) | Q14: Skottland | R14: =IF(ISBLANK($E13)=TRUE,"",IF(ISNUMBER(SEARCH(Q14,$E13)),2,0))
B15: 9. | C15: I hvilken gruppe scores det flest mål? | D15: 2p | G15: E | H15: =IF(ISBLANK($E15)=TRUE,"",IF($E15=G15,2,0)) | I15: E | J15: =IF(ISBLANK($E15)=TRUE,"",IF($E15=I15,2,0)) | K15: E | L15: =IF(ISBLANK($E15)=TRUE,"",IF($E15=K15,2,0)) | N15: =IF(ISBLANK($E15)=TRUE,"",IF($E15=M15,2,0)) | O15: E | P15: =IF(ISBLANK($E15)=TRUE,"",IF($E15=O15,2,0)) | Q15: Gruppe E | R15: =IF(ISBLANK($E15)=TRUE,"",IF($E15=Q15,2,0))
B16: 10. | C16: Hvilket lag blir VMs dårligste? | D16: 2p | G16: Curacao | H16: =IF(ISBLANK($E16)=TRUE,"",IF($E16=G16,2,0)) | I16: Kapp Verde | J16: =IF(ISBLANK($E16)=TRUE,"",IF($E16=I16,2,0)) | K16: Curacao | L16: =IF(ISBLANK($E16)=TRUE,"",IF($E16=K16,2,0)) | N16: =IF(ISBLANK($E16)=TRUE,"",IF($E16=M16,2,0)) | O16: Haiti | P16: =IF(ISBLANK($E16)=TRUE,"",IF($E16=O16,2,0)) | Q16: Curacao | R16: =IF(ISBLANK($E16)=TRUE,"",IF($E16=Q16,2,0))
B17: 11. | C17: Hvem dømmer finalen? | D17: 4p | G17: Schärer | H17: =IF(ISBLANK($E17)=TRUE,"",IF($E17=G17,4,0)) | I17: Marciniak | J17: =IF(ISBLANK($E17)=TRUE,"",IF($E17=I17,4,0)) | K17: Marciniak | L17: =IF(ISBLANK($E17)=TRUE,"",IF($E17=K17,4,0)) | N17: =IF(ISBLANK($E17)=TRUE,"",IF($E17=M17,4,0)) | O17: Nyberg | P17: =IF(ISBLANK($E17)=TRUE,"",IF($E17=O17,4,0)) | Q17: Khalid Al-Turais | R17: =IF(ISBLANK($E17)=TRUE,"",IF($E17=Q17,4,0))
B18: 12. | C18: Hvilken øynasjon kommer lengst? | D18: 2p | G18: Japan | H18: =IF(ISBLANK($E18)=TRUE,"",IF($E18=G18,2,0)) | I18: Australia | J18: =IF(ISBLANK($E18)=TRUE,"",IF($E18=I18,2,0)) | K18: Japan | L18: =IF(ISBLANK($E18)=TRUE,"",IF($E18=K18,2,0)) | N18: =IF(ISBLANK($E18)=TRUE,"",IF($E18=M18,2,0)) | O18: Japan | P18: =IF(ISBLANK($E18)=TRUE,"",IF($E18=O18,2,0)) | Q18: Japan | R18: =IF(ISBLANK($E18)=TRUE,"",IF($E18=Q18,2,0))
B19: 13. | C19: Hvem scorer flest mål av Cristiano Ronaldo og Lionel Messi? | D19: 1p | G19: Messi | H19: =IF(ISBLANK($E19)=TRUE,"",IF($E19=G19,1,0)) | I19: Messi | J19: =IF(ISBLANK($E19)=TRUE,"",IF($E19=I19,1,0)) | K19: Messi | L19: =IF(ISBLANK($E19)=TRUE,"",IF($E19=K19,1,0)) | N19: =IF(ISBLANK($E19)=TRUE,"",IF($E19=M19,1,0)) | O19: Messi | P19: =IF(ISBLANK($E19)=TRUE,"",IF($E19=O19,1,0)) | Q19: Messi | R19: =IF(ISBLANK($E19)=TRUE,"",IF($E19=Q19,1,0))
