Workbook

Sheet Gruppespill
B2: Dato | C2: Kl. | D2: Gruppe A | G2: Resultat | J2: Skjalg | N2: Sindre | R2: Anne Marte | V2: Ole | Z2: Eirik | AD2: Margret | AH2: Håkon Emil | AL2: Morten | AP2: Hilde | AT2: Sofia | AX2: Nicholas | BB2: Trond | BF2: Anders | BJ2: Ida | BN2: Erling | BR2: Håkon M | BV2: Bent Arne | BZ2: Gunvor | CD2: Lisa | CH2: Espen | CL2: Jonas G | CP2: Kay Robin | CT2: Magnus | CX2: Jonas W | DB2: Viktor | DF2: Kajsa
B3: 46184 | C3: 21:00 | D3: Mexico | E3: - | F3: Sør-Afrika | G3: 2 | H3: - | I3: 0 | J3: 2 | K3: - | L3: 0 | M3: =IF(ISBLANK($I3)=TRUE,"",IF(SIGN(J3-L3)=SIGN($G3-$I3),1,0)+IF(J3=$G3,IF(L3=$I3,2,0),0)) -> 3 | N3: 2 | O3: - | P3: 0 | Q3: =IF(ISBLANK($I3)=TRUE,"",IF(SIGN(N3-P3)=SIGN($G3-$I3),1,0)+IF(N3=$G3,IF(P3=$I3,2,0),0)) -> 3 | R3: 2 | S3: - | T3: 1 | U3: =IF(ISBLANK($I3)=TRUE,"",IF(SIGN(R3-T3)=SIGN($G3-$I3),1,0)+IF(R3=$G3,IF(T3=$I3,2,0),0)) -> 1 | V3: 3 | W3: - | X3: 0 | Y3: =IF(ISBLANK($I3)=TRUE,"",IF(SIGN(V3-X3)=SIGN($G3-$I3),1,0)+IF(V3=$G3,IF(X3=$I3,2,0),0)) -> 1 | Z3: 2 | AA3: - | AB3: 0 | AC3: =IF(ISBLANK($I3)=TRUE,"",IF(SIGN(Z3-AB3)=SIGN($G3-$I3),1,0)+IF(Z3=$G3,IF(AB3=$I3,2,0),0)) -> 3 | AD3: 3 | AE3: - | AF3: 0 | AG3: =IF(ISBLANK($I3)=TRUE,"",IF(SIGN(AD3-AF3)=SIGN($G3-$I3),1,0)+IF(AD3=$G3,IF(AF3=$I3,2,0),0)) -> 1 | AH3: 1 | AI3: - | AJ3: 0 | AK3: =IF(ISBLANK($I3)=TRUE,"",IF(SIGN(AH3-AJ3)=SIGN($G3-$I3),1,0)+IF(AH3=$G3,IF(AJ3=$I3,2,0),0)) -> 1 | AL3: 1 | AM3: - | AN3: 0 | AO3: =IF(ISBLANK($I3)=TRUE,"",IF(SIGN(AL3-AN3)=SIGN($G3-$I3),1,0)+IF(AL3=$G3,IF(AN3=$I3,2,0),0)) -> 1 | AP3: 1 | AQ3: - | AR3: 0 | AS3: =IF(ISBLANK($I3)=TRUE,"",IF(SIGN(AP3-AR3)=SIGN($G3-$I3),1,0)+IF(AP3=$G3,IF(AR3=$I3,2,0),0)) -> 1 | AT3: 2 | AU3: - | AV3: 0 | AW3: =IF(ISBLANK($I3)=TRUE,"",IF(SIGN(AT3-AV3)=SIGN($G3-$I3),1,0)+IF(AT3=$G3,IF(AV3=$I3,2,0),0)) -> 3 | AX3: 3 | AY3: - | AZ3: 1 | BA3: =IF(ISBLANK($I3)=TRUE,"",IF(SIGN(AX3-AZ3)=SIGN($G3-$I3),1,0)+IF(AX3=$G3,IF(AZ3=$I3,2,0),0)) -> 1 | BB3: 3 | BC3: - | BD3: 1 | BE3: =IF(ISBLANK($I3)=TRUE,"",IF(SIGN(BB3-BD3)=SIGN($G3-$I3),1,0)+IF(BB3=$G3,IF(BD3=$I3,2,0),0)) -> 1 | BF3: 2 | BG3: - | BH3: 0 | BI3: =IF(ISBLANK($I3)=TRUE,"",IF(SIGN(BF3-BH3)=SIGN($G3-$I3),1,0)+IF(BF3=$G3,IF(BH3=$I3,2,0),0)) -> 3 | BJ3: 1 | BK3: - | BL3: 0 | BM3: =IF(ISBLANK($I3)=TRUE,"",IF(SIGN(BJ3-BL3)=SIGN($G3-$I3),1,0)+IF(BJ3=$G3,IF(BL3=$I3,2,0),0)) -> 1 | BN3: 2 | BO3: - | BP3: 0 | BQ3: =IF(ISBLANK($I3)=TRUE,"",IF(SIGN(BN3-BP3)=SIGN($G3-$I3),1,0)+IF(BN3=$G3,IF(BP3=$I3,2,0),0)) -> 3 | BR3: 2 | BS3: - | BT3: 0 | BU3: =IF(ISBLANK($I3)=TRUE,"",IF(SIGN(BR3-BT3)=SIGN($G3-$I3),1,0)+IF(BR3=$G3,IF(BT3=$I3,2,0),0)) -> 3 | BV3: 2 | BW3: - | BX3: 0 | BY3: =IF(ISBLANK($I3)=TRUE,"",IF(SIGN(BV3-BX3)=SIGN($G3-$I3),1,0)+IF(BV3=$G3,IF(BX3=$I3,2,0),0)) -> 3 | BZ3: 3 | CA3: - | CB3: 1 | CC3: =IF(ISBLANK($I3)=TRUE,"",IF(SIGN(BZ3-CB3)=SIGN($G3-$I3),1,0)+IF(BZ3=$G3,IF(CB3=$I3,2,0),0)) -> 1 | CD3: 2 | CE3: - | CF3: 0 | CG3: =IF(ISBLANK($I3)=TRUE,"",IF(SIGN(CD3-CF3)=SIGN($G3-$I3),1,0)+IF(CD3=$G3,IF(CF3=$I3,2,0),0)) -> 3 | CH3: 3 | CI3: - | CJ3: 1 | CK3: =IF(ISBLANK($I3)=TRUE,"",IF(SIGN(CH3-CJ3)=SIGN($G3-$I3),1,0)+IF(CH3=$G3,IF(CJ3=$I3,2,0),0)) -> 1 | CL3: 2 | CM3: - | CN3: 1 | CO3: =IF(ISBLANK($I3)=TRUE,"",IF(SIGN(CL3-CN3)=SIGN($G3-$I3),1,0)+IF(CL3=$G3,IF(CN3=$I3,2,0),0)) -> 1 | CP3: 3 | CQ3: - | CR3: 1 | CS3: =IF(ISBLANK($I3)=TRUE,"",IF(SIGN(CP3-CR3)=SIGN($G3-$I3),1,0)+IF(CP3=$G3,IF(CR3=$I3,2,0),0)) -> 1 | CT3: 2 | CU3: - | CV3: 0 | CW3: =IF(ISBLANK($I3)=TRUE,"",IF(SIGN(CT3-CV3)=SIGN($G3-$I3),1,0)+IF(CT3=$G3,IF(CV3=$I3,2,0),0)) -> 3 | CX3: 1 | CY3: - | CZ3: 0 | DA3: =IF(ISBLANK($I3)=TRUE,"",IF(SIGN(CX3-CZ3)=SIGN($G3-$I3),1,0)+IF(CX3=$G3,IF(CZ3=$I3,2,0),0)) -> 1 | DB3: 2 | DC3: - | DD3: 1 | DE3: =IF(ISBLANK($I3)=TRUE,"",IF(SIGN(DB3-DD3)=SIGN($G3-$I3),1,0)+IF(DB3=$G3,IF(DD3=$I3,2,0),0)) -> 1 | DF3: 1 | DG3: - | DH3: 0 | DI3: =IF(ISBLANK($I3)=TRUE,"",IF(SIGN(DF3-DH3)=SIGN($G3-$I3),1,0)+IF(DF3=$G3,IF(DH3=$I3,2,0),0)) -> 1
B4: 46185 | C4: 04:00 | D4: Sør-Korea | E4: - | F4: Tsjekkia | G4: 2 | H4: - | I4: 1 | J4: 1 | K4: - | L4: 1 | M4: =IF(ISBLANK($G4)=TRUE,"",IF(SIGN(J4-L4)=SIGN($G4-$I4),1,0)+IF(J4=$G4,IF(L4=$I4,2,0),0)) -> 0 | N4: 1 | O4: - | P4: 1 | Q4: =IF(ISBLANK($G4)=TRUE,"",IF(SIGN(N4-P4)=SIGN($G4-$I4),1,0)+IF(N4=$G4,IF(P4=$I4,2,0),0)) -> 0 | R4: 1 | S4: - | T4: 1 | U4: =IF(ISBLANK($G4)=TRUE,"",IF(SIGN(R4-T4)=SIGN($G4-$I4),1,0)+IF(R4=$G4,IF(T4=$I4,2,0),0)) -> 0 | V4: 2 | W4: - | X4: 1 | Y4: =IF(ISBLANK($G4)=TRUE,"",IF(SIGN(V4-X4)=SIGN($G4-$I4),1,0)+IF(V4=$G4,IF(X4=$I4,2,0),0)) -> 3 | Z4: 1 | AA4: - | AB4: 1 | AC4: =IF(ISBLANK($G4)=TRUE,"",IF(SIGN(Z4-AB4)=SIGN($G4-$I4),1,0)+IF(Z4=$G4,IF(AB4=$I4,2,0),0)) -> 0 | AD4: 2 | AE4: - | AF4: 1 | AG4: =IF(ISBLANK($G4)=TRUE,"",IF(SIGN(AD4-AF4)=SIGN($G4-$I4),1,0)+IF(AD4=$G4,IF(AF4=$I4,2,0),0)) -> 3 | AH4: 0 | AI4: - | AJ4: 1 | AK4: =IF(ISBLANK($G4)=TRUE,"",IF(SIGN(AH4-AJ4)=SIGN($G4-$I4),1,0)+IF(AH4=$G4,IF(AJ4=$I4,2,0),0)) -> 0 | AL4: 0 | AM4: - | AN4: 0 | AO4: =IF(ISBLANK($G4)=TRUE,"",IF(SIGN(AL4-AN4)=SIGN($G4-$I4),1,0)+IF(AL4=$G4,IF(AN4=$I4,2,0),0)) -> 0 | AP4: 1 | AQ4: - | AR4: 2 | AS4: =IF(ISBLANK($G4)=TRUE,"",IF(SIGN(AP4-AR4)=SIGN($G4-$I4),1,0)+IF(AP4=$G4,IF(AR4=$I4,2,0),0)) -> 0 | AT4: 1 | AU4: - | AV4: 1 | AW4: =IF(ISBLANK($G4)=TRUE,"",IF(SIGN(AT4-AV4)=SIGN($G4-$I4),1,0)+IF(AT4=$G4,IF(AV4=$I4,2,0),0)) -> 0 | AX4: 0 | AY4: - | AZ4: 2 | BA4: =IF(ISBLANK($G4)=TRUE,"",IF(SIGN(AX4-AZ4)=SIGN($G4-$I4),1,0)+IF(AX4=$G4,IF(AZ4=$I4,2,0),0)) -> 0 | BB4: 1 | BC4: - | BD4: 1 | BE4: =IF(ISBLANK($G4)=TRUE,"",IF(SIGN(BB4-BD4)=SIGN($G4-$I4),1,0)+IF(BB4=$G4,IF(BD4=$I4,2,0),0)) -> 0 | BF4: 2 | BG4: - | BH4: 0 | BI4: =IF(ISBLANK($G4)=TRUE,"",IF(SIGN(BF4-BH4)=SIGN($G4-$I4),1,0)+IF(BF4=$G4,IF(BH4=$I4,2,0),0)) -> 1 | BJ4: 1 | BK4: - | BL4: 1 | BM4: =IF(ISBLANK($G4)=TRUE,"",IF(SIGN(BJ4-BL4)=SIGN($G4-$I4),1,0)+IF(BJ4=$G4,IF(BL4=$I4,2,0),0)) -> 0 | BN4: 1 | BO4: - | BP4: 1 | BQ4: =IF(ISBLANK($G4)=TRUE,"",IF(SIGN(BN4-BP4)=SIGN($G4-$I4),1,0)+IF(BN4=$G4,IF(BP4=$I4,2,0),0)) -> 0 | BR4: 2 | BS4: - | BT4: 1 | BU4: =IF(ISBLANK($G4)=TRUE,"",IF(SIGN(BR4-BT4)=SIGN($G4-$I4),1,0)+IF(BR4=$G4,IF(BT4=$I4,2,0),0)) -> 3 | BV4: 2 | BW4: - | BX4: 1 | BY4: =IF(ISBLANK($G4)=TRUE,"",IF(SIGN(BV4-BX4)=SIGN($G4-$I4),1,0)+IF(BV4=$G4,IF(BX4=$I4,2,0),0)) -> 3 | BZ4: 2 | CA4: - | CB4: 3 | CC4: =IF(ISBLANK($G4)=TRUE,"",IF(SIGN(BZ4-CB4)=SIGN($G4-$I4),1,0)+IF(BZ4=$G4,IF(CB4=$I4,2,0),0)) -> 0 | CD4: 1 | CE4: - | CF4: 1 | CG4: =IF(ISBLANK($G4)=TRUE,"",IF(SIGN(CD4-CF4)=SIGN($G4-$I4),1,0)+IF(CD4=$G4,IF(CF4=$I4,2,0),0)) -> 0 | CH4: 2 | CI4: - | CJ4: 2 | CK4: =IF(ISBLANK($G4)=TRUE,"",IF(SIGN(CH4-CJ4)=SIGN($G4-$I4),1,0)+IF(CH4=$G4,IF(CJ4=$I4,2,0),0)) -> 0 | CL4: 1 | CM4: - | CN4: 1 | CO4: =IF(ISBLANK($G4)=TRUE,"",IF(SIGN(CL4-CN4)=SIGN($G4-$I4),1,0)+IF(CL4=$G4,IF(CN4=$I4,2,0),0)) -> 0 | CP4: 1 | CQ4: - | CR4: 2 | CS4: =IF(ISBLANK($G4)=TRUE,"",IF(SIGN(CP4-CR4)=SIGN($G4-$I4),1,0)+IF(CP4=$G4,IF(CR4=$I4,2,0),0)) -> 0 | CT4: 2 | CU4: - | CV4: 1 | CW4: =IF(ISBLANK($G4)=TRUE,"",IF(SIGN(CT4-CV4)=SIGN($G4-$I4),1,0)+IF(CT4=$G4,IF(CV4=$I4,2,0),0)) -> 3 | CX4: 1 | CY4: - | CZ4: 1 | DA4: =IF(ISBLANK($G4)=TRUE,"",IF(SIGN(CX4-CZ4)=SIGN($G4-$I4),1,0)+IF(CX4=$G4,IF(CZ4=$I4,2,0),0)) -> 0 | DB4: 3 | DC4: - | DD4: 1 | DE4: =IF(ISBLANK($G4)=TRUE,"",IF(SIGN(DB4-DD4)=SIGN($G4-$I4),1,0)+IF(DB4=$G4,IF(DD4=$I4,2,0),0)) -> 1 | DF4: 0 | DG4: - | DH4: 2 | DI4: =IF(ISBLANK($G4)=TRUE,"",IF(SIGN(DF4-DH4)=SIGN($G4-$I4),1,0)+IF(DF4=$G4,IF(DH4=$I4,2,0),0)) -> 0
B5: 46191 | C5: 18:00 | D5: Tsjekkia | E5: - | F5: Sør-Afrika | H5: - | J5: 2 | K5: - | L5: 1 | M5: =IF(ISBLANK($G5)=TRUE,"",IF(SIGN(J5-L5)=SIGN($G5-$I5),1,0)+IF(J5=$G5,IF(L5=$I5,2,0),0)) | N5: 1 | O5: - | P5: 0 | Q5: =IF(ISBLANK($G5)=TRUE,"",IF(SIGN(N5-P5)=SIGN($G5-$I5),1,0)+IF(N5=$G5,IF(P5=$I5,2,0),0)) | R5: 1 | S5: - | T5: 0 | U5: =IF(ISBLANK($G5)=TRUE,"",IF(SIGN(R5-T5)=SIGN($G5-$I5),1,0)+IF(R5=$G5,IF(T5=$I5,2,0),0)) | V5: 2 | W5: - | X5: 0 | Y5: =IF(ISBLANK($G5)=TRUE,"",IF(SIGN(V5-X5)=SIGN($G5-$I5),1,0)+IF(V5=$G5,IF(X5=$I5,2,0),0)) | Z5: 2 | AA5: - | AB5: 0 | AC5: =IF(ISBLANK($G5)=TRUE,"",IF(SIGN(Z5-AB5)=SIGN($G5-$I5),1,0)+IF(Z5=$G5,IF(AB5=$I5,2,0),0)) | AD5: 1 | AE5: - | AF5: 1 | AG5: =IF(ISBLANK($G5)=TRUE,"",IF(SIGN(AD5-AF5)=SIGN($G5-$I5),1,0)+IF(AD5=$G5,IF(AF5=$I5,2,0),0)) | AH5: 1 | AI5: - | AJ5: 0 | AK5: =IF(ISBLANK($G5)=TRUE,"",IF(SIGN(AH5-AJ5)=SIGN($G5-$I5),1,0)+IF(AH5=$G5,IF(AJ5=$I5,2,0),0)) | AL5: 1 | AM5: - | AN5: 0 | AO5: =IF(ISBLANK($G5)=TRUE,"",IF(SIGN(AL5-AN5)=SIGN($G5-$I5),1,0)+IF(AL5=$G5,IF(AN5=$I5,2,0),0)) | AP5: 2 | AQ5: - | AR5: 1 | AS5: =IF(ISBLANK($G5)=TRUE,"",IF(SIGN(AP5-AR5)=SIGN($G5-$I5),1,0)+IF(AP5=$G5,IF(AR5=$I5,2,0),0)) | AT5: 2 | AU5: - | AV5: 1 | AW5: =IF(ISBLANK($G5)=TRUE,"",IF(SIGN(AT5-AV5)=SIGN($G5-$I5),1,0)+IF(AT5=$G5,IF(AV5=$I5,2,0),0)) | AX5: 2 | AY5: - | AZ5: 1 | BA5: =IF(ISBLANK($G5)=TRUE,"",IF(SIGN(AX5-AZ5)=SIGN($G5-$I5),1,0)+IF(AX5=$G5,IF(AZ5=$I5,2,0),0)) | BB5: 1 | BC5: - | BD5: 1 | BE5: =IF(ISBLANK($G5)=TRUE,"",IF(SIGN(BB5-BD5)=SIGN($G5-$I5),1,0)+IF(BB5=$G5,IF(BD5=$I5,2,0),0)) | BF5: 1 | BG5: - | BH5: 1 | BI5: =IF(ISBLANK($G5)=TRUE,"",IF(SIGN(BF5-BH5)=SIGN($G5-$I5),1,0)+IF(BF5=$G5,IF(BH5=$I5,2,0),0)) | BJ5: 2 | BK5: - | BL5: 1 | BM5: =IF(ISBLANK($G5)=TRUE,"",IF(SIGN(BJ5-BL5)=SIGN($G5-$I5),1,0)+IF(BJ5=$G5,IF(BL5=$I5,2,0),0)) | BN5: 2 | BO5: - | BP5: 0 | BQ5: =IF(ISBLANK($G5)=TRUE,"",IF(SIGN(BN5-BP5)=SIGN($G5-$I5),1,0)+IF(BN5=$G5,IF(BP5=$I5,2,0),0)) | BR5: 1 | BS5: - | BT5: 1 | BU5: =IF(ISBLANK($G5)=TRUE,"",IF(SIGN(BR5-BT5)=SIGN($G5-$I5),1,0)+IF(BR5=$G5,IF(BT5=$I5,2,0),0)) | BV5: 3 | BW5: - | BX5: 1 | BY5: =IF(ISBLANK($G5)=TRUE,"",IF(SIGN(BV5-BX5)=SIGN($G5-$I5),1,0)+IF(BV5=$G5,IF(BX5=$I5,2,0),0)) | BZ5: 2 | CA5: - | CB5: 1 | CC5: =IF(ISBLANK($G5)=TRUE,"",IF(SIGN(BZ5-CB5)=SIGN($G5-$I5),1,0)+IF(BZ5=$G5,IF(CB5=$I5,2,0),0)) | CD5: 2 | CE5: - | CF5: 0 | CG5: =IF(ISBLANK($G5)=TRUE,"",IF(SIGN(CD5-CF5)=SIGN($G5-$I5),1,0)+IF(CD5=$G5,IF(CF5=$I5,2,0),0)) | CH5: 2 | CI5: - | CJ5: 0 | CK5: =IF(ISBLANK($G5)=TRUE,"",IF(SIGN(CH5-CJ5)=SIGN($G5-$I5),1,0)+IF(CH5=$G5,IF(CJ5=$I5,2,0),0)) | CL5: 2 | CM5: - | CN5: 0 | CO5: =IF(ISBLANK($G5)=TRUE,"",IF(SIGN(CL5-CN5)=SIGN($G5-$I5),1,0)+IF(CL5=$G5,IF(CN5=$I5,2,0),0)) | CP5: 2 | CQ5: - | CR5: 0 | CS5: =IF(ISBLANK($G5)=TRUE,"",IF(SIGN(CP5-CR5)=SIGN($G5-$I5),1,0)+IF(CP5=$G5,IF(CR5=$I5,2,0),0)) | CT5: 2 | CU5: - | CV5: 0 | CW5: =IF(ISBLANK($G5)=TRUE,"",IF(SIGN(CT5-CV5)=SIGN($G5-$I5),1,0)+IF(CT5=$G5,IF(CV5=$I5,2,0),0)) | CX5: 1 | CY5: - | CZ5: 0 | DA5: =IF(ISBLANK($G5)=TRUE,"",IF(SIGN(CX5-CZ5)=SIGN($G5-$I5),1,0)+IF(CX5=$G5,IF(CZ5=$I5,2,0),0)) | DB5: 2 | DC5: - | DD5: 1 | DE5: =IF(ISBLANK($G5)=TRUE,"",IF(SIGN(DB5-DD5)=SIGN($G5-$I5),1,0)+IF(DB5=$G5,IF(DD5=$I5,2,0),0)) | DF5: 1 | DG5: - | DH5: 1 | DI5: =IF(ISBLANK($G5)=TRUE,"",IF(SIGN(DF5-DH5)=SIGN($G5-$I5),1,0)+IF(DF5=$G5,IF(DH5=$I5,2,0),0))
B6: 46192 | C6: 03:00 | D6: Mexico | E6: - | F6: Sør-Korea | H6: - | J6: 1 | K6: - | L6: 1 | M6: =IF(ISBLANK($G6)=TRUE,"",IF(SIGN(J6-L6)=SIGN($G6-$I6),1,0)+IF(J6=$G6,IF(L6=$I6,2,0),0)) | N6: 2 | O6: - | P6: 1 | Q6: =IF(ISBLANK($G6)=TRUE,"",IF(SIGN(N6-P6)=SIGN($G6-$I6),1,0)+IF(N6=$G6,IF(P6=$I6,2,0),0)) | R6: 2 | S6: - | T6: 0 | U6: =IF(ISBLANK($G6)=TRUE,"",IF(SIGN(R6-T6)=SIGN($G6-$I6),1,0)+IF(R6=$G6,IF(T6=$I6,2,0),0)) | V6: 2 | W6: - | X6: 1 | Y6: =IF(ISBLANK($G6)=TRUE,"",IF(SIGN(V6-X6)=SIGN($G6-$I6),1,0)+IF(V6=$G6,IF(X6=$I6,2,0),0)) | Z6: 1 | AA6: - | AB6: 1 | AC6: =IF(ISBLANK($G6)=TRUE,"",IF(SIGN(Z6-AB6)=SIGN($G6-$I6),1,0)+IF(Z6=$G6,IF(AB6=$I6,2,0),0)) | AD6: 2 | AE6: - | AF6: 1 | AG6: =IF(ISBLANK($G6)=TRUE,"",IF(SIGN(AD6-AF6)=SIGN($G6-$I6),1,0)+IF(AD6=$G6,IF(AF6=$I6,2,0),0)) | AH6: 1 | AI6: - | AJ6: 0 | AK6: =IF(ISBLANK($G6)=TRUE,"",IF(SIGN(AH6-AJ6)=SIGN($G6-$I6),1,0)+IF(AH6=$G6,IF(AJ6=$I6,2,0),0)) | AL6: 1 | AM6: - | AN6: 0 | AO6: =IF(ISBLANK($G6)=TRUE,"",IF(SIGN(AL6-AN6)=SIGN($G6-$I6),1,0)+IF(AL6=$G6,IF(AN6=$I6,2,0),0)) | AP6: 1 | AQ6: - | AR6: 1 | AS6: =IF(ISBLANK($G6)=TRUE,"",IF(SIGN(AP6-AR6)=SIGN($G6-$I6),1,0)+IF(AP6=$G6,IF(AR6=$I6,2,0),0)) | AT6: 3 | AU6: - | AV6: 1 | AW6: =IF(ISBLANK($G6)=TRUE,"",IF(SIGN(AT6-AV6)=SIGN($G6-$I6),1,0)+IF(AT6=$G6,IF(AV6=$I6,2,0),0)) | AX6: 1 | AY6: - | AZ6: 0 | BA6: =IF(ISBLANK($G6)=TRUE,"",IF(SIGN(AX6-AZ6)=SIGN($G6-$I6),1,0)+IF(AX6=$G6,IF(AZ6=$I6,2,0),0)) | BB6: 1 | BC6: - | BD6: 1 | BE6: =IF(ISBLANK($G6)=TRUE,"",IF(SIGN(BB6-BD6)=SIGN($G6-$I6),1,0)+IF(BB6=$G6,IF(BD6=$I6,2,0),0)) | BF6: 1 | BG6: - | BH6: 0 | BI6: =IF(ISBLANK($G6)=TRUE,"",IF(SIGN(BF6-BH6)=SIGN($G6-$I6),1,0)+IF(BF6=$G6,IF(BH6=$I6,2,0),0)) | BJ6: 1 | BK6: - | BL6: 0 | BM6: =IF(ISBLANK($G6)=TRUE,"",IF(SIGN(BJ6-BL6)=SIGN($G6-$I6),1,0)+IF(BJ6=$G6,IF(BL6=$I6,2,0),0)) | BN6: 1 | BO6: - | BP6: 0 | BQ6: =IF(ISBLANK($G6)=TRUE,"",IF(SIGN(BN6-BP6)=SIGN($G6-$I6),1,0)+IF(BN6=$G6,IF(BP6=$I6,2,0),0)) | BR6: 2 | BS6: - | BT6: 1 | BU6: =IF(ISBLANK($G6)=TRUE,"",IF(SIGN(BR6-BT6)=SIGN($G6-$I6),1,0)+IF(BR6=$G6,IF(BT6=$I6,2,0),0)) | BV6: 1 | BW6: - | BX6: 1 | BY6: =IF(ISBLANK($G6)=TRUE,"",IF(SIGN(BV6-BX6)=SIGN($G6-$I6),1,0)+IF(BV6=$G6,IF(BX6=$I6,2,0),0)) | BZ6: 1 | CA6: - | CB6: 1 | CC6: =IF(ISBLANK($G6)=TRUE,"",IF(SIGN(BZ6-CB6)=SIGN($G6-$I6),1,0)+IF(BZ6=$G6,IF(CB6=$I6,2,0),0)) | CD6: 2 | CE6: - | CF6: 1 | CG6: =IF(ISBLANK($G6)=TRUE,"",IF(SIGN(CD6-CF6)=SIGN($G6-$I6),1,0)+IF(CD6=$G6,IF(CF6=$I6,2,0),0)) | CH6: 2 | CI6: - | CJ6: 1 | CK6: =IF(ISBLANK($G6)=TRUE,"",IF(SIGN(CH6-CJ6)=SIGN($G6-$I6),1,0)+IF(CH6=$G6,IF(CJ6=$I6,2,0),0)) | CL6: 3 | CM6: - | CN6: 1 | CO6: =IF(ISBLANK($G6)=TRUE,"",IF(SIGN(CL6-CN6)=SIGN($G6-$I6),1,0)+IF(CL6=$G6,IF(CN6=$I6,2,0),0)) | CP6: 1 | CQ6: - | CR6: 0 | CS6: =IF(ISBLANK($G6)=TRUE,"",IF(SIGN(CP6-CR6)=SIGN($G6-$I6),1,0)+IF(CP6=$G6,IF(CR6=$I6,2,0),0)) | CT6: 2 | CU6: - | CV6: 1 | CW6: =IF(ISBLANK($G6)=TRUE,"",IF(SIGN(CT6-CV6)=SIGN($G6-$I6),1,0)+IF(CT6=$G6,IF(CV6=$I6,2,0),0)) | CX6: 1 | CY6: - | CZ6: 2 | DA6: =IF(ISBLANK($G6)=TRUE,"",IF(SIGN(CX6-CZ6)=SIGN($G6-$I6),1,0)+IF(CX6=$G6,IF(CZ6=$I6,2,0),0)) | DB6: 3 | DC6: - | DD6: 2 | DE6: =IF(ISBLANK($G6)=TRUE,"",IF(SIGN(DB6-DD6)=SIGN($G6-$I6),1,0)+IF(DB6=$G6,IF(DD6=$I6,2,0),0)) | DF6: 2 | DG6: - | DH6: 0 | DI6: =IF(ISBLANK($G6)=TRUE,"",IF(SIGN(DF6-DH6)=SIGN($G6-$I6),1,0)+IF(DF6=$G6,IF(DH6=$I6,2,0),0))
B7: 46198 | C7: 03:00 | D7: Tsjekkia | E7: - | F7: Mexico | H7: - | J7: 1 | K7: - | L7: 2 | M7: =IF(ISBLANK($G7)=TRUE,"",IF(SIGN(J7-L7)=SIGN($G7-$I7),1,0)+IF(J7=$G7,IF(L7=$I7,2,0),0)) | N7: 0 | O7: - | P7: 1 | Q7: =IF(ISBLANK($G7)=TRUE,"",IF(SIGN(N7-P7)=SIGN($G7-$I7),1,0)+IF(N7=$G7,IF(P7=$I7,2,0),0)) | R7: 1 | S7: - | T7: 1 | U7: =IF(ISBLANK($G7)=TRUE,"",IF(SIGN(R7-T7)=SIGN($G7-$I7),1,0)+IF(R7=$G7,IF(T7=$I7,2,0),0)) | V7: 0 | W7: - | X7: 2 | Y7: =IF(ISBLANK($G7)=TRUE,"",IF(SIGN(V7-X7)=SIGN($G7-$I7),1,0)+IF(V7=$G7,IF(X7=$I7,2,0),0)) | Z7: 1 | AA7: - | AB7: 1 | AC7: =IF(ISBLANK($G7)=TRUE,"",IF(SIGN(Z7-AB7)=SIGN($G7-$I7),1,0)+IF(Z7=$G7,IF(AB7=$I7,2,0),0)) | AD7: 0 | AE7: - | AF7: 2 | AG7: =IF(ISBLANK($G7)=TRUE,"",IF(SIGN(AD7-AF7)=SIGN($G7-$I7),1,0)+IF(AD7=$G7,IF(AF7=$I7,2,0),0)) | AH7: 1 | AI7: - | AJ7: 1 | AK7: =IF(ISBLANK($G7)=TRUE,"",IF(SIGN(AH7-AJ7)=SIGN($G7-$I7),1,0)+IF(AH7=$G7,IF(AJ7=$I7,2,0),0)) | AL7: 1 | AM7: - | AN7: 0 | AO7: =IF(ISBLANK($G7)=TRUE,"",IF(SIGN(AL7-AN7)=SIGN($G7-$I7),1,0)+IF(AL7=$G7,IF(AN7=$I7,2,0),0)) | AP7: 1 | AQ7: - | AR7: 0 | AS7: =IF(ISBLANK($G7)=TRUE,"",IF(SIGN(AP7-AR7)=SIGN($G7-$I7),1,0)+IF(AP7=$G7,IF(AR7=$I7,2,0),0)) | AT7: 1 | AU7: - | AV7: 2 | AW7: =IF(ISBLANK($G7)=TRUE,"",IF(SIGN(AT7-AV7)=SIGN($G7-$I7),1,0)+IF(AT7=$G7,IF(AV7=$I7,2,0),0)) | AX7: 1 | AY7: - | AZ7: 1 | BA7: =IF(ISBLANK($G7)=TRUE,"",IF(SIGN(AX7-AZ7)=SIGN($G7-$I7),1,0)+IF(AX7=$G7,IF(AZ7=$I7,2,0),0)) | BB7: 1 | BC7: - | BD7: 1 | BE7: =IF(ISBLANK($G7)=TRUE,"",IF(SIGN(BB7-BD7)=SIGN($G7-$I7),1,0)+IF(BB7=$G7,IF(BD7=$I7,2,0),0)) | BF7: 0 | BG7: - | BH7: 2 | BI7: =IF(ISBLANK($G7)=TRUE,"",IF(SIGN(BF7-BH7)=SIGN($G7-$I7),1,0)+IF(BF7=$G7,IF(BH7=$I7,2,0),0)) | BJ7: 0 | BK7: - | BL7: 1 | BM7: =IF(ISBLANK($G7)=TRUE,"",IF(SIGN(BJ7-BL7)=SIGN($G7-$I7),1,0)+IF(BJ7=$G7,IF(BL7=$I7,2,0),0)) | BN7: 1 | BO7: - | BP7: 2 | BQ7: =IF(ISBLANK($G7)=TRUE,"",IF(SIGN(BN7-BP7)=SIGN($G7-$I7),1,0)+IF(BN7=$G7,IF(BP7=$I7,2,0),0)) | BR7: 0 | BS7: - | BT7: 3 | BU7: =IF(ISBLANK($G7)=TRUE,"",IF(SIGN(BR7-BT7)=SIGN($G7-$I7),1,0)+IF(BR7=$G7,IF(BT7=$I7,2,0),0)) | BV7: 0 | BW7: - | BX7: 1 | BY7: =IF(ISBLANK($G7)=TRUE,"",IF(SIGN(BV7-BX7)=SIGN($G7-$I7),1,0)+IF(BV7=$G7,IF(BX7=$I7,2,0),0)) | BZ7: 3 | CA7: - | CB7: 2 | CC7: =IF(ISBLANK($G7)=TRUE,"",IF(SIGN(BZ7-CB7)=SIGN($G7-$I7),1,0)+IF(BZ7=$G7,IF(CB7=$I7,2,0),0)) | CD7: 0 | CE7: - | CF7: 1 | CG7: =IF(ISBLANK($G7)=TRUE,"",IF(SIGN(CD7-CF7)=SIGN($G7-$I7),1,0)+IF(CD7=$G7,IF(CF7=$I7,2,0),0)) | CH7: 1 | CI7: - | CJ7: 1 | CK7: =IF(ISBLANK($G7)=TRUE,"",IF(SIGN(CH7-CJ7)=SIGN($G7-$I7),1,0)+IF(CH7=$G7,IF(CJ7=$I7,2,0),0)) | CL7: 1 | CM7: - | CN7: 2 | CO7: =IF(ISBLANK($G7)=TRUE,"",IF(SIGN(CL7-CN7)=SIGN($G7-$I7),1,0)+IF(CL7=$G7,IF(CN7=$I7,2,0),0)) | CP7: 1 | CQ7: - | CR7: 1 | CS7: =IF(ISBLANK($G7)=TRUE,"",IF(SIGN(CP7-CR7)=SIGN($G7-$I7),1,0)+IF(CP7=$G7,IF(CR7=$I7,2,0),0)) | CT7: 1 | CU7: - | CV7: 1 | CW7: =IF(ISBLANK($G7)=TRUE,"",IF(SIGN(CT7-CV7)=SIGN($G7-$I7),1,0)+IF(CT7=$G7,IF(CV7=$I7,2,0),0)) | CX7: 1 | CY7: - | CZ7: 2 | DA7: =IF(ISBLANK($G7)=TRUE,"",IF(SIGN(CX7-CZ7)=SIGN($G7-$I7),1,0)+IF(CX7=$G7,IF(CZ7=$I7,2,0),0)) | DB7: 2 | DC7: - | DD7: 2 | DE7: =IF(ISBLANK($G7)=TRUE,"",IF(SIGN(DB7-DD7)=SIGN($G7-$I7),1,0)+IF(DB7=$G7,IF(DD7=$I7,2,0),0)) | DF7: 1 | DG7: - | DH7: 1 | DI7: =IF(ISBLANK($G7)=TRUE,"",IF(SIGN(DF7-DH7)=SIGN($G7-$I7),1,0)+IF(DF7=$G7,IF(DH7=$I7,2,0),0))
B8: 46198 | C8: 03:00 | D8: Sør-Afrika | E8: - | F8: Sør-Korea | H8: - | J8: 1 | K8: - | L8: 2 | M8: =IF(ISBLANK($G8)=TRUE,"",IF(SIGN(J8-L8)=SIGN($G8-$I8),1,0)+IF(J8=$G8,IF(L8=$I8,2,0),0)) | N8: 0 | O8: - | P8: 1 | Q8: =IF(ISBLANK($G8)=TRUE,"",IF(SIGN(N8-P8)=SIGN($G8-$I8),1,0)+IF(N8=$G8,IF(P8=$I8,2,0),0)) | R8: 1 | S8: - | T8: 2 | U8: =IF(ISBLANK($G8)=TRUE,"",IF(SIGN(R8-T8)=SIGN($G8-$I8),1,0)+IF(R8=$G8,IF(T8=$I8,2,0),0)) | V8: 0 | W8: - | X8: 0 | Y8: =IF(ISBLANK($G8)=TRUE,"",IF(SIGN(V8-X8)=SIGN($G8-$I8),1,0)+IF(V8=$G8,IF(X8=$I8,2,0),0)) | Z8: 0 | AA8: - | AB8: 1 | AC8: =IF(ISBLANK($G8)=TRUE,"",IF(SIGN(Z8-AB8)=SIGN($G8-$I8),1,0)+IF(Z8=$G8,IF(AB8=$I8,2,0),0)) | AD8: 1 | AE8: - | AF8: 2 | AG8: =IF(ISBLANK($G8)=TRUE,"",IF(SIGN(AD8-AF8)=SIGN($G8-$I8),1,0)+IF(AD8=$G8,IF(AF8=$I8,2,0),0)) | AH8: 1 | AI8: - | AJ8: 1 | AK8: =IF(ISBLANK($G8)=TRUE,"",IF(SIGN(AH8-AJ8)=SIGN($G8-$I8),1,0)+IF(AH8=$G8,IF(AJ8=$I8,2,0),0)) | AL8: 0 | AM8: - | AN8: 0 | AO8: =IF(ISBLANK($G8)=TRUE,"",IF(SIGN(AL8-AN8)=SIGN($G8-$I8),1,0)+IF(AL8=$G8,IF(AN8=$I8,2,0),0)) | AP8: 1 | AQ8: - | AR8: 2 | AS8: =IF(ISBLANK($G8)=TRUE,"",IF(SIGN(AP8-AR8)=SIGN($G8-$I8),1,0)+IF(AP8=$G8,IF(AR8=$I8,2,0),0)) | AT8: 0 | AU8: - | AV8: 0 | AW8: =IF(ISBLANK($G8)=TRUE,"",IF(SIGN(AT8-AV8)=SIGN($G8-$I8),1,0)+IF(AT8=$G8,IF(AV8=$I8,2,0),0)) | AX8: 2 | AY8: - | AZ8: 2 | BA8: =IF(ISBLANK($G8)=TRUE,"",IF(SIGN(AX8-AZ8)=SIGN($G8-$I8),1,0)+IF(AX8=$G8,IF(AZ8=$I8,2,0),0)) | BB8: 1 | BC8: - | BD8: 2 | BE8: =IF(ISBLANK($G8)=TRUE,"",IF(SIGN(BB8-BD8)=SIGN($G8-$I8),1,0)+IF(BB8=$G8,IF(BD8=$I8,2,0),0)) | BF8: 1 | BG8: - | BH8: 2 | BI8: =IF(ISBLANK($G8)=TRUE,"",IF(SIGN(BF8-BH8)=SIGN($G8-$I8),1,0)+IF(BF8=$G8,IF(BH8=$I8,2,0),0)) | BJ8: 1 | BK8: - | BL8: 2 | BM8: =IF(ISBLANK($G8)=TRUE,"",IF(SIGN(BJ8-BL8)=SIGN($G8-$I8),1,0)+IF(BJ8=$G8,IF(BL8=$I8,2,0),0)) | BN8: 1 | BO8: - | BP8: 2 | BQ8: =IF(ISBLANK($G8)=TRUE,"",IF(SIGN(BN8-BP8)=SIGN($G8-$I8),1,0)+IF(BN8=$G8,IF(BP8=$I8,2,0),0)) | BR8: 1 | BS8: - | BT8: 2 | BU8: =IF(ISBLANK($G8)=TRUE,"",IF(SIGN(BR8-BT8)=SIGN($G8-$I8),1,0)+IF(BR8=$G8,IF(BT8=$I8,2,0),0)) | BV8: 1 | BW8: - | BX8: 1 | BY8: =IF(ISBLANK($G8)=TRUE,"",IF(SIGN(BV8-BX8)=SIGN($G8-$I8),1,0)+IF(BV8=$G8,IF(BX8=$I8,2,0),0)) | BZ8: 0 | CA8: - | CB8: 1 | CC8: =IF(ISBLANK($G8)=TRUE,"",IF(SIGN(BZ8-CB8)=SIGN($G8-$I8),1,0)+IF(BZ8=$G8,IF(CB8=$I8,2,0),0)) | CD8: 0 | CE8: - | CF8: 2 | CG8: =IF(ISBLANK($G8)=TRUE,"",IF(SIGN(CD8-CF8)=SIGN($G8-$I8),1,0)+IF(CD8=$G8,IF(CF8=$I8,2,0),0)) | CH8: 0 | CI8: - | CJ8: 2 | CK8: =IF(ISBLANK($G8)=TRUE,"",IF(SIGN(CH8-CJ8)=SIGN($G8-$I8),1,0)+IF(CH8=$G8,IF(CJ8=$I8,2,0),0)) | CL8: 1 | CM8: - | CN8: 2 | CO8: =IF(ISBLANK($G8)=TRUE,"",IF(SIGN(CL8-CN8)=SIGN($G8-$I8),1,0)+IF(CL8=$G8,IF(CN8=$I8,2,0),0)) | CP8: 2 | CQ8: - | CR8: 3 | CS8: =IF(ISBLANK($G8)=TRUE,"",IF(SIGN(CP8-CR8)=SIGN($G8-$I8),1,0)+IF(CP8=$G8,IF(CR8=$I8,2,0),0)) | CT8: 1 | CU8: - | CV8: 3 | CW8: =IF(ISBLANK($G8)=TRUE,"",IF(SIGN(CT8-CV8)=SIGN($G8-$I8),1,0)+IF(CT8=$G8,IF(CV8=$I8,2,0),0)) | CX8: 0 | CY8: - | CZ8: 2 | DA8: =IF(ISBLANK($G8)=TRUE,"",IF(SIGN(CX8-CZ8)=SIGN($G8-$I8),1,0)+IF(CX8=$G8,IF(CZ8=$I8,2,0),0)) | DB8: 4 | DC8: - | DD8: 0 | DE8: =IF(ISBLANK($G8)=TRUE,"",IF(SIGN(DB8-DD8)=SIGN($G8-$I8),1,0)+IF(DB8=$G8,IF(DD8=$I8,2,0),0)) | DF8: 3 | DG8: - | DH8: 1 | DI8: =IF(ISBLANK($G8)=TRUE,"",IF(SIGN(DF8-DH8)=SIGN($G8-$I8),1,0)+IF(DF8=$G8,IF(DH8=$I8,2,0),0))
B9: Dato | C9: Kl. | D9: Gruppe B | G9: Resultat
B10: 46185 | C10: 21:00 | D10: Canada | E10: - | F10: Bosnia-Hercegovina | G10: 1 | H10: - | I10: 1 | J10: 1 | K10: - | L10: 1 | M10: =IF(ISBLANK($I10)=TRUE,"",IF(SIGN(J10-L10)=SIGN($G10-$I10),1,0)+IF(J10=$G10,IF(L10=$I10,2,0),0)) -> 3 | N10: 1 | O10: - | P10: 1 | Q10: =IF(ISBLANK($I10)=TRUE,"",IF(SIGN(N10-P10)=SIGN($G10-$I10),1,0)+IF(N10=$G10,IF(P10=$I10,2,0),0)) -> 3 | R10: 2 | S10: - | T10: 0 | U10: =IF(ISBLANK($I10)=TRUE,"",IF(SIGN(R10-T10)=SIGN($G10-$I10),1,0)+IF(R10=$G10,IF(T10=$I10,2,0),0)) -> 0 | V10: 2 | W10: - | X10: 1 | Y10: =IF(ISBLANK($I10)=TRUE,"",IF(SIGN(V10-X10)=SIGN($G10-$I10),1,0)+IF(V10=$G10,IF(X10=$I10,2,0),0)) -> 0 | Z10: 1 | AA10: - | AB10: 0 | AC10: =IF(ISBLANK($I10)=TRUE,"",IF(SIGN(Z10-AB10)=SIGN($G10-$I10),1,0)+IF(Z10=$G10,IF(AB10=$I10,2,0),0)) -> 0 | AD10: 2 | AE10: - | AF10: 0 | AG10: =IF(ISBLANK($I10)=TRUE,"",IF(SIGN(AD10-AF10)=SIGN($G10-$I10),1,0)+IF(AD10=$G10,IF(AF10=$I10,2,0),0)) -> 0 | AH10: 0 | AI10: - | AJ10: 1 | AK10: =IF(ISBLANK($I10)=TRUE,"",IF(SIGN(AH10-AJ10)=SIGN($G10-$I10),1,0)+IF(AH10=$G10,IF(AJ10=$I10,2,0),0)) -> 0 | AL10: 1 | AM10: - | AN10: 0 | AO10: =IF(ISBLANK($I10)=TRUE,"",IF(SIGN(AL10-AN10)=SIGN($G10-$I10),1,0)+IF(AL10=$G10,IF(AN10=$I10,2,0),0)) -> 0 | AP10: 0 | AQ10: - | AR10: 1 | AS10: =IF(ISBLANK($I10)=TRUE,"",IF(SIGN(AP10-AR10)=SIGN($G10-$I10),1,0)+IF(AP10=$G10,IF(AR10=$I10,2,0),0)) -> 0 | AT10: 1 | AU10: - | AV10: 0 | AW10: =IF(ISBLANK($I10)=TRUE,"",IF(SIGN(AT10-AV10)=SIGN($G10-$I10),1,0)+IF(AT10=$G10,IF(AV10=$I10,2,0),0)) -> 0 | AX10: 2 | AY10: - | AZ10: 1 | BA10: =IF(ISBLANK($I10)=TRUE,"",IF(SIGN(AX10-AZ10)=SIGN($G10-$I10),1,0)+IF(AX10=$G10,IF(AZ10=$I10,2,0),0)) -> 0 | BB10: 1 | BC10: - | BD10: 1 | BE10: =IF(ISBLANK($I10)=TRUE,"",IF(SIGN(BB10-BD10)=SIGN($G10-$I10),1,0)+IF(BB10=$G10,IF(BD10=$I10,2,0),0)) -> 3 | BF10: 0 | BG10: - | BH10: 1 | BI10: =IF(ISBLANK($I10)=TRUE,"",IF(SIGN(BF10-BH10)=SIGN($G10-$I10),1,0)+IF(BF10=$G10,IF(BH10=$I10,2,0),0)) -> 0 | BJ10: 0 | BK10: - | BL10: 1 | BM10: =IF(ISBLANK($I10)=TRUE,"",IF(SIGN(BJ10-BL10)=SIGN($G10-$I10),1,0)+IF(BJ10=$G10,IF(BL10=$I10,2,0),0)) -> 0 | BN10: 2 | BO10: - | BP10: 1 | BQ10: =IF(ISBLANK($I10)=TRUE,"",IF(SIGN(BN10-BP10)=SIGN($G10-$I10),1,0)+IF(BN10=$G10,IF(BP10=$I10,2,0),0)) -> 0 | BR10: 1 | BS10: - | BT10: 1 | BU10: =IF(ISBLANK($I10)=TRUE,"",IF(SIGN(BR10-BT10)=SIGN($G10-$I10),1,0)+IF(BR10=$G10,IF(BT10=$I10,2,0),0)) -> 3 | BV10: 2 | BW10: - | BX10: 0 | BY10: =IF(ISBLANK($I10)=TRUE,"",IF(SIGN(BV10-BX10)=SIGN($G10-$I10),1,0)+IF(BV10=$G10,IF(BX10=$I10,2,0),0)) -> 0 | BZ10: 2 | CA10: - | CB10: 0 | CC10: =IF(ISBLANK($I10)=TRUE,"",IF(SIGN(BZ10-CB10)=SIGN($G10-$I10),1,0)+IF(BZ10=$G10,IF(CB10=$I10,2,0),0)) -> 0 | CD10: 1 | CE10: - | CF10: 0 | CG10: =IF(ISBLANK($I10)=TRUE,"",IF(SIGN(CD10-CF10)=SIGN($G10-$I10),1,0)+IF(CD10=$G10,IF(CF10=$I10,2,0),0)) -> 0 | CH10: 2 | CI10: - | CJ10: 1 | CK10: =IF(ISBLANK($I10)=TRUE,"",IF(SIGN(CH10-CJ10)=SIGN($G10-$I10),1,0)+IF(CH10=$G10,IF(CJ10=$I10,2,0),0)) -> 0 | CL10: 2 | CM10: - | CN10: 1 | CO10: =IF(ISBLANK($I10)=TRUE,"",IF(SIGN(CL10-CN10)=SIGN($G10-$I10),1,0)+IF(CL10=$G10,IF(CN10=$I10,2,0),0)) -> 0 | CP10: 3 | CQ10: - | CR10: 2 | CS10: =IF(ISBLANK($I10)=TRUE,"",IF(SIGN(CP10-CR10)=SIGN($G10-$I10),1,0)+IF(CP10=$G10,IF(CR10=$I10,2,0),0)) -> 0 | CT10: 1 | CU10: - | CV10: 1 | CW10: =IF(ISBLANK($I10)=TRUE,"",IF(SIGN(CT10-CV10)=SIGN($G10-$I10),1,0)+IF(CT10=$G10,IF(CV10=$I10,2,0),0)) -> 3 | CX10: 0 | CY10: - | CZ10: 2 | DA10: =IF(ISBLANK($I10)=TRUE,"",IF(SIGN(CX10-CZ10)=SIGN($G10-$I10),1,0)+IF(CX10=$G10,IF(CZ10=$I10,2,0),0)) -> 0 | DB10: 2 | DC10: - | DD10: 3 | DE10: =IF(ISBLANK($I10)=TRUE,"",IF(SIGN(DB10-DD10)=SIGN($G10-$I10),1,0)+IF(DB10=$G10,IF(DD10=$I10,2,0),0)) -> 0 | DF10: 2 | DG10: - | DH10: 1 | DI10: =IF(ISBLANK($I10)=TRUE,"",IF(SIGN(DF10-DH10)=SIGN($G10-$I10),1,0)+IF(DF10=$G10,IF(DH10=$I10,2,0),0)) -> 0
B11: 46186 | C11: 21:00 | D11: Qatar | E11: - | F11: Sveits | H11: - | J11: 0 | K11: - | L11: 2 | M11: =IF(ISBLANK($G11)=TRUE,"",IF(SIGN(J11-L11)=SIGN($G11-$I11),1,0)+IF(J11=$G11,IF(L11=$I11,2,0),0)) | N11: 0 | O11: - | P11: 1 | Q11: =IF(ISBLANK($G11)=TRUE,"",IF(SIGN(N11-P11)=SIGN($G11-$I11),1,0)+IF(N11=$G11,IF(P11=$I11,2,0),0)) | R11: 0 | S11: - | T11: 2 | U11: =IF(ISBLANK($G11)=TRUE,"",IF(SIGN(R11-T11)=SIGN($G11-$I11),1,0)+IF(R11=$G11,IF(T11=$I11,2,0),0)) | V11: 0 | W11: - | X11: 2 | Y11: =IF(ISBLANK($G11)=TRUE,"",IF(SIGN(V11-X11)=SIGN($G11-$I11),1,0)+IF(V11=$G11,IF(X11=$I11,2,0),0)) | Z11: 0 | AA11: - | AB11: 2 | AC11: =IF(ISBLANK($G11)=TRUE,"",IF(SIGN(Z11-AB11)=SIGN($G11-$I11),1,0)+IF(Z11=$G11,IF(AB11=$I11,2,0),0)) | AD11: 1 | AE11: - | AF11: 3 | AG11: =IF(ISBLANK($G11)=TRUE,"",IF(SIGN(AD11-AF11)=SIGN($G11-$I11),1,0)+IF(AD11=$G11,IF(AF11=$I11,2,0),0)) | AH11: 0 | AI11: - | AJ11: 2 | AK11: =IF(ISBLANK($G11)=TRUE,"",IF(SIGN(AH11-AJ11)=SIGN($G11-$I11),1,0)+IF(AH11=$G11,IF(AJ11=$I11,2,0),0)) | AL11: 0 | AM11: - | AN11: 2 | AO11: =IF(ISBLANK($G11)=TRUE,"",IF(SIGN(AL11-AN11)=SIGN($G11-$I11),1,0)+IF(AL11=$G11,IF(AN11=$I11,2,0),0)) | AP11: 1 | AQ11: - | AR11: 3 | AS11: =IF(ISBLANK($G11)=TRUE,"",IF(SIGN(AP11-AR11)=SIGN($G11-$I11),1,0)+IF(AP11=$G11,IF(AR11=$I11,2,0),0)) | AT11: 1 | AU11: - | AV11: 2 | AW11: =IF(ISBLANK($G11)=TRUE,"",IF(SIGN(AT11-AV11)=SIGN($G11-$I11),1,0)+IF(AT11=$G11,IF(AV11=$I11,2,0),0)) | AX11: 1 | AY11: - | AZ11: 3 | BA11: =IF(ISBLANK($G11)=TRUE,"",IF(SIGN(AX11-AZ11)=SIGN($G11-$I11),1,0)+IF(AX11=$G11,IF(AZ11=$I11,2,0),0)) | BB11: 1 | BC11: - | BD11: 2 | BE11: =IF(ISBLANK($G11)=TRUE,"",IF(SIGN(BB11-BD11)=SIGN($G11-$I11),1,0)+IF(BB11=$G11,IF(BD11=$I11,2,0),0)) | BF11: 0 | BG11: - | BH11: 3 | BI11: =IF(ISBLANK($G11)=TRUE,"",IF(SIGN(BF11-BH11)=SIGN($G11-$I11),1,0)+IF(BF11=$G11,IF(BH11=$I11,2,0),0)) | BJ11: 0 | BK11: - | BL11: 3 | BM11: =IF(ISBLANK($G11)=TRUE,"",IF(SIGN(BJ11-BL11)=SIGN($G11-$I11),1,0)+IF(BJ11=$G11,IF(BL11=$I11,2,0),0)) | BN11: 0 | BO11: - | BP11: 2 | BQ11: =IF(ISBLANK($G11)=TRUE,"",IF(SIGN(BN11-BP11)=SIGN($G11-$I11),1,0)+IF(BN11=$G11,IF(BP11=$I11,2,0),0)) | BR11: 0 | BS11: - | BT11: 2 | BU11: =IF(ISBLANK($G11)=TRUE,"",IF(SIGN(BR11-BT11)=SIGN($G11-$I11),1,0)+IF(BR11=$G11,IF(BT11=$I11,2,0),0)) | BV11: 1 | BW11: - | BX11: 4 | BY11: =IF(ISBLANK($G11)=TRUE,"",IF(SIGN(BV11-BX11)=SIGN($G11-$I11),1,0)+IF(BV11=$G11,IF(BX11=$I11,2,0),0)) | BZ11: 1 | CA11: - | CB11: 2 | CC11: =IF(ISBLANK($G11)=TRUE,"",IF(SIGN(BZ11-CB11)=SIGN($G11-$I11),1,0)+IF(BZ11=$G11,IF(CB11=$I11,2,0),0)) | CD11: 0 | CE11: - | CF11: 2 | CG11: =IF(ISBLANK($G11)=TRUE,"",IF(SIGN(CD11-CF11)=SIGN($G11-$I11),1,0)+IF(CD11=$G11,IF(CF11=$I11,2,0),0)) | CH11: 0 | CI11: - | CJ11: 4 | CK11: =IF(ISBLANK($G11)=TRUE,"",IF(SIGN(CH11-CJ11)=SIGN($G11-$I11),1,0)+IF(CH11=$G11,IF(CJ11=$I11,2,0),0)) | CL11: 0 | CM11: - | CN11: 1 | CO11: =IF(ISBLANK($G11)=TRUE,"",IF(SIGN(CL11-CN11)=SIGN($G11-$I11),1,0)+IF(CL11=$G11,IF(CN11=$I11,2,0),0)) | CP11: 0 | CQ11: - | CR11: 3 | CS11: =IF(ISBLANK($G11)=TRUE,"",IF(SIGN(CP11-CR11)=SIGN($G11-$I11),1,0)+IF(CP11=$G11,IF(CR11=$I11,2,0),0)) | CT11: 0 | CU11: - | CV11: 2 | CW11: =IF(ISBLANK($G11)=TRUE,"",IF(SIGN(CT11-CV11)=SIGN($G11-$I11),1,0)+IF(CT11=$G11,IF(CV11=$I11,2,0),0)) | CX11: 1 | CY11: - | CZ11: 3 | DA11: =IF(ISBLANK($G11)=TRUE,"",IF(SIGN(CX11-CZ11)=SIGN($G11-$I11),1,0)+IF(CX11=$G11,IF(CZ11=$I11,2,0),0)) | DB11: 1 | DC11: - | DD11: 2 | DE11: =IF(ISBLANK($G11)=TRUE,"",IF(SIGN(DB11-DD11)=SIGN($G11-$I11),1,0)+IF(DB11=$G11,IF(DD11=$I11,2,0),0)) | DF11: 3 | DG11: - | DH11: 2 | DI11: =IF(ISBLANK($G11)=TRUE,"",IF(SIGN(DF11-DH11)=SIGN($G11-$I11),1,0)+IF(DF11=$G11,IF(DH11=$I11,2,0),0))
B12: 46191 | C12: 21:00 | D12: Sveits | E12: - | F12: Bosnia-Hercegovina | H12: - | J12: 2 | K12: - | L12: 0 | M12: =IF(ISBLANK($G12)=TRUE,"",IF(SIGN(J12-L12)=SIGN($G12-$I12),1,0)+IF(J12=$G12,IF(L12=$I12,2,0),0)) | N12: 1 | O12: - | P12: 0 | Q12: =IF(ISBLANK($G12)=TRUE,"",IF(SIGN(N12-P12)=SIGN($G12-$I12),1,0)+IF(N12=$G12,IF(P12=$I12,2,0),0)) | R12: 2 | S12: - | T12: 0 | U12: =IF(ISBLANK($G12)=TRUE,"",IF(SIGN(R12-T12)=SIGN($G12-$I12),1,0)+IF(R12=$G12,IF(T12=$I12,2,0),0)) | V12: 2 | W12: - | X12: 1 | Y12: =IF(ISBLANK($G12)=TRUE,"",IF(SIGN(V12-X12)=SIGN($G12-$I12),1,0)+IF(V12=$G12,IF(X12=$I12,2,0),0)) | Z12: 2 | AA12: - | AB12: 1 | AC12: =IF(ISBLANK($G12)=TRUE,"",IF(SIGN(Z12-AB12)=SIGN($G12-$I12),1,0)+IF(Z12=$G12,IF(AB12=$I12,2,0),0)) | AD12: 2 | AE12: - | AF12: 1 | AG12: =IF(ISBLANK($G12)=TRUE,"",IF(SIGN(AD12-AF12)=SIGN($G12-$I12),1,0)+IF(AD12=$G12,IF(AF12=$I12,2,0),0)) | AH12: 1 | AI12: - | AJ12: 1 | AK12: =IF(ISBLANK($G12)=TRUE,"",IF(SIGN(AH12-AJ12)=SIGN($G12-$I12),1,0)+IF(AH12=$G12,IF(AJ12=$I12,2,0),0)) | AL12: 1 | AM12: - | AN12: 0 | AO12: =IF(ISBLANK($G12)=TRUE,"",IF(SIGN(AL12-AN12)=SIGN($G12-$I12),1,0)+IF(AL12=$G12,IF(AN12=$I12,2,0),0)) | AP12: 2 | AQ12: - | AR12: 0 | AS12: =IF(ISBLANK($G12)=TRUE,"",IF(SIGN(AP12-AR12)=SIGN($G12-$I12),1,0)+IF(AP12=$G12,IF(AR12=$I12,2,0),0)) | AT12: 1 | AU12: - | AV12: 0 | AW12: =IF(ISBLANK($G12)=TRUE,"",IF(SIGN(AT12-AV12)=SIGN($G12-$I12),1,0)+IF(AT12=$G12,IF(AV12=$I12,2,0),0)) | AX12: 2 | AY12: - | AZ12: 0 | BA12: =IF(ISBLANK($G12)=TRUE,"",IF(SIGN(AX12-AZ12)=SIGN($G12-$I12),1,0)+IF(AX12=$G12,IF(AZ12=$I12,2,0),0)) | BB12: 2 | BC12: - | BD12: 1 | BE12: =IF(ISBLANK($G12)=TRUE,"",IF(SIGN(BB12-BD12)=SIGN($G12-$I12),1,0)+IF(BB12=$G12,IF(BD12=$I12,2,0),0)) | BF12: 1 | BG12: - | BH12: 0 | BI12: =IF(ISBLANK($G12)=TRUE,"",IF(SIGN(BF12-BH12)=SIGN($G12-$I12),1,0)+IF(BF12=$G12,IF(BH12=$I12,2,0),0)) | BJ12: 2 | BK12: - | BL12: 1 | BM12: =IF(ISBLANK($G12)=TRUE,"",IF(SIGN(BJ12-BL12)=SIGN($G12-$I12),1,0)+IF(BJ12=$G12,IF(BL12=$I12,2,0),0)) | BN12: 1 | BO12: - | BP12: 0 | BQ12: =IF(ISBLANK($G12)=TRUE,"",IF(SIGN(BN12-BP12)=SIGN($G12-$I12),1,0)+IF(BN12=$G12,IF(BP12=$I12,2,0),0)) | BR12: 2 | BS12: - | BT12: 1 | BU12: =IF(ISBLANK($G12)=TRUE,"",IF(SIGN(BR12-BT12)=SIGN($G12-$I12),1,0)+IF(BR12=$G12,IF(BT12=$I12,2,0),0)) | BV12: 2 | BW12: - | BX12: 0 | BY12: =IF(ISBLANK($G12)=TRUE,"",IF(SIGN(BV12-BX12)=SIGN($G12-$I12),1,0)+IF(BV12=$G12,IF(BX12=$I12,2,0),0)) | BZ12: 3 | CA12: - | CB12: 0 | CC12: =IF(ISBLANK($G12)=TRUE,"",IF(SIGN(BZ12-CB12)=SIGN($G12-$I12),1,0)+IF(BZ12=$G12,IF(CB12=$I12,2,0),0)) | CD12: 2 | CE12: - | CF12: 0 | CG12: =IF(ISBLANK($G12)=TRUE,"",IF(SIGN(CD12-CF12)=SIGN($G12-$I12),1,0)+IF(CD12=$G12,IF(CF12=$I12,2,0),0)) | CH12: 3 | CI12: - | CJ12: 1 | CK12: =IF(ISBLANK($G12)=TRUE,"",IF(SIGN(CH12-CJ12)=SIGN($G12-$I12),1,0)+IF(CH12=$G12,IF(CJ12=$I12,2,0),0)) | CL12: 1 | CM12: - | CN12: 1 | CO12: =IF(ISBLANK($G12)=TRUE,"",IF(SIGN(CL12-CN12)=SIGN($G12-$I12),1,0)+IF(CL12=$G12,IF(CN12=$I12,2,0),0)) | CP12: 2 | CQ12: - | CR12: 1 | CS12: =IF(ISBLANK($G12)=TRUE,"",IF(SIGN(CP12-CR12)=SIGN($G12-$I12),1,0)+IF(CP12=$G12,IF(CR12=$I12,2,0),0)) | CT12: 3 | CU12: - | CV12: 1 | CW12: =IF(ISBLANK($G12)=TRUE,"",IF(SIGN(CT12-CV12)=SIGN($G12-$I12),1,0)+IF(CT12=$G12,IF(CV12=$I12,2,0),0)) | CX12: 2 | CY12: - | CZ12: 1 | DA12: =IF(ISBLANK($G12)=TRUE,"",IF(SIGN(CX12-CZ12)=SIGN($G12-$I12),1,0)+IF(CX12=$G12,IF(CZ12=$I12,2,0),0)) | DB12: 3 | DC12: - | DD12: 1 | DE12: =IF(ISBLANK($G12)=TRUE,"",IF(SIGN(DB12-DD12)=SIGN($G12-$I12),1,0)+IF(DB12=$G12,IF(DD12=$I12,2,0),0)) | DF12: 1 | DG12: - | DH12: 2 | DI12: =IF(ISBLANK($G12)=TRUE,"",IF(SIGN(DF12-DH12)=SIGN($G12-$I12),1,0)+IF(DF12=$G12,IF(DH12=$I12,2,0),0))
B13: 46192 | C13: 00:00 | D13: Canada | E13: - | F13: Qatar | H13: - | J13: 2 | K13: - | L13: 0 | M13: =IF(ISBLANK($G13)=TRUE,"",IF(SIGN(J13-L13)=SIGN($G13-$I13),1,0)+IF(J13=$G13,IF(L13=$I13,2,0),0)) | N13: 1 | O13: - | P13: 0 | Q13: =IF(ISBLANK($G13)=TRUE,"",IF(SIGN(N13-P13)=SIGN($G13-$I13),1,0)+IF(N13=$G13,IF(P13=$I13,2,0),0)) | R13: 1 | S13: - | T13: 1 | U13: =IF(ISBLANK($G13)=TRUE,"",IF(SIGN(R13-T13)=SIGN($G13-$I13),1,0)+IF(R13=$G13,IF(T13=$I13,2,0),0)) | V13: 2 | W13: - | X13: 0 | Y13: =IF(ISBLANK($G13)=TRUE,"",IF(SIGN(V13-X13)=SIGN($G13-$I13),1,0)+IF(V13=$G13,IF(X13=$I13,2,0),0)) | Z13: 1 | AA13: - | AB13: 0 | AC13: =IF(ISBLANK($G13)=TRUE,"",IF(SIGN(Z13-AB13)=SIGN($G13-$I13),1,0)+IF(Z13=$G13,IF(AB13=$I13,2,0),0)) | AD13: 2 | AE13: - | AF13: 0 | AG13: =IF(ISBLANK($G13)=TRUE,"",IF(SIGN(AD13-AF13)=SIGN($G13-$I13),1,0)+IF(AD13=$G13,IF(AF13=$I13,2,0),0)) | AH13: 1 | AI13: - | AJ13: 0 | AK13: =IF(ISBLANK($G13)=TRUE,"",IF(SIGN(AH13-AJ13)=SIGN($G13-$I13),1,0)+IF(AH13=$G13,IF(AJ13=$I13,2,0),0)) | AL13: 1 | AM13: - | AN13: 0 | AO13: =IF(ISBLANK($G13)=TRUE,"",IF(SIGN(AL13-AN13)=SIGN($G13-$I13),1,0)+IF(AL13=$G13,IF(AN13=$I13,2,0),0)) | AP13: 2 | AQ13: - | AR13: 2 | AS13: =IF(ISBLANK($G13)=TRUE,"",IF(SIGN(AP13-AR13)=SIGN($G13-$I13),1,0)+IF(AP13=$G13,IF(AR13=$I13,2,0),0)) | AT13: 1 | AU13: - | AV13: 1 | AW13: =IF(ISBLANK($G13)=TRUE,"",IF(SIGN(AT13-AV13)=SIGN($G13-$I13),1,0)+IF(AT13=$G13,IF(AV13=$I13,2,0),0)) | AX13: 2 | AY13: - | AZ13: 1 | BA13: =IF(ISBLANK($G13)=TRUE,"",IF(SIGN(AX13-AZ13)=SIGN($G13-$I13),1,0)+IF(AX13=$G13,IF(AZ13=$I13,2,0),0)) | BB13: 1 | BC13: - | BD13: 1 | BE13: =IF(ISBLANK($G13)=TRUE,"",IF(SIGN(BB13-BD13)=SIGN($G13-$I13),1,0)+IF(BB13=$G13,IF(BD13=$I13,2,0),0)) | BF13: 0 | BG13: - | BH13: 0 | BI13: =IF(ISBLANK($G13)=TRUE,"",IF(SIGN(BF13-BH13)=SIGN($G13-$I13),1,0)+IF(BF13=$G13,IF(BH13=$I13,2,0),0)) | BJ13: 1 | BK13: - | BL13: 0 | BM13: =IF(ISBLANK($G13)=TRUE,"",IF(SIGN(BJ13-BL13)=SIGN($G13-$I13),1,0)+IF(BJ13=$G13,IF(BL13=$I13,2,0),0)) | BN13: 2 | BO13: - | BP13: 0 | BQ13: =IF(ISBLANK($G13)=TRUE,"",IF(SIGN(BN13-BP13)=SIGN($G13-$I13),1,0)+IF(BN13=$G13,IF(BP13=$I13,2,0),0)) | BR13: 2 | BS13: - | BT13: 1 | BU13: =IF(ISBLANK($G13)=TRUE,"",IF(SIGN(BR13-BT13)=SIGN($G13-$I13),1,0)+IF(BR13=$G13,IF(BT13=$I13,2,0),0)) | BV13: 1 | BW13: - | BX13: 0 | BY13: =IF(ISBLANK($G13)=TRUE,"",IF(SIGN(BV13-BX13)=SIGN($G13-$I13),1,0)+IF(BV13=$G13,IF(BX13=$I13,2,0),0)) | BZ13: 2 | CA13: - | CB13: 1 | CC13: =IF(ISBLANK($G13)=TRUE,"",IF(SIGN(BZ13-CB13)=SIGN($G13-$I13),1,0)+IF(BZ13=$G13,IF(CB13=$I13,2,0),0)) | CD13: 3 | CE13: - | CF13: 0 | CG13: =IF(ISBLANK($G13)=TRUE,"",IF(SIGN(CD13-CF13)=SIGN($G13-$I13),1,0)+IF(CD13=$G13,IF(CF13=$I13,2,0),0)) | CH13: 2 | CI13: - | CJ13: 0 | CK13: =IF(ISBLANK($G13)=TRUE,"",IF(SIGN(CH13-CJ13)=SIGN($G13-$I13),1,0)+IF(CH13=$G13,IF(CJ13=$I13,2,0),0)) | CL13: 2 | CM13: - | CN13: 0 | CO13: =IF(ISBLANK($G13)=TRUE,"",IF(SIGN(CL13-CN13)=SIGN($G13-$I13),1,0)+IF(CL13=$G13,IF(CN13=$I13,2,0),0)) | CP13: 2 | CQ13: - | CR13: 0 | CS13: =IF(ISBLANK($G13)=TRUE,"",IF(SIGN(CP13-CR13)=SIGN($G13-$I13),1,0)+IF(CP13=$G13,IF(CR13=$I13,2,0),0)) | CT13: 2 | CU13: - | CV13: 0 | CW13: =IF(ISBLANK($G13)=TRUE,"",IF(SIGN(CT13-CV13)=SIGN($G13-$I13),1,0)+IF(CT13=$G13,IF(CV13=$I13,2,0),0)) | CX13: 1 | CY13: - | CZ13: 1 | DA13: =IF(ISBLANK($G13)=TRUE,"",IF(SIGN(CX13-CZ13)=SIGN($G13-$I13),1,0)+IF(CX13=$G13,IF(CZ13=$I13,2,0),0)) | DB13: 2 | DC13: - | DD13: 2 | DE13: =IF(ISBLANK($G13)=TRUE,"",IF(SIGN(DB13-DD13)=SIGN($G13-$I13),1,0)+IF(DB13=$G13,IF(DD13=$I13,2,0),0)) | DF13: 1 | DG13: - | DH13: 2 | DI13: =IF(ISBLANK($G13)=TRUE,"",IF(SIGN(DF13-DH13)=SIGN($G13-$I13),1,0)+IF(DF13=$G13,IF(DH13=$I13,2,0),0))
B14: 46197 | C14: 21:00 | D14: Sveits | E14: - | F14: Canada | H14: - | J14: 2 | K14: - | L14: 1 | M14: =IF(ISBLANK($G14)=TRUE,"",IF(SIGN(J14-L14)=SIGN($G14-$I14),1,0)+IF(J14=$G14,IF(L14=$I14,2,0),0)) | N14: 1 | O14: - | P14: 0 | Q14: =IF(ISBLANK($G14)=TRUE,"",IF(SIGN(N14-P14)=SIGN($G14-$I14),1,0)+IF(N14=$G14,IF(P14=$I14,2,0),0)) | R14: 1 | S14: - | T14: 1 | U14: =IF(ISBLANK($G14)=TRUE,"",IF(SIGN(R14-T14)=SIGN($G14-$I14),1,0)+IF(R14=$G14,IF(T14=$I14,2,0),0)) | V14: 2 | W14: - | X14: 1 | Y14: =IF(ISBLANK($G14)=TRUE,"",IF(SIGN(V14-X14)=SIGN($G14-$I14),1,0)+IF(V14=$G14,IF(X14=$I14,2,0),0)) | Z14: 2 | AA14: - | AB14: 0 | AC14: =IF(ISBLANK($G14)=TRUE,"",IF(SIGN(Z14-AB14)=SIGN($G14-$I14),1,0)+IF(Z14=$G14,IF(AB14=$I14,2,0),0)) | AD14: 2 | AE14: - | AF14: 2 | AG14: =IF(ISBLANK($G14)=TRUE,"",IF(SIGN(AD14-AF14)=SIGN($G14-$I14),1,0)+IF(AD14=$G14,IF(AF14=$I14,2,0),0)) | AH14: 2 | AI14: - | AJ14: 0 | AK14: =IF(ISBLANK($G14)=TRUE,"",IF(SIGN(AH14-AJ14)=SIGN($G14-$I14),1,0)+IF(AH14=$G14,IF(AJ14=$I14,2,0),0)) | AL14: 0 | AM14: - | AN14: 0 | AO14: =IF(ISBLANK($G14)=TRUE,"",IF(SIGN(AL14-AN14)=SIGN($G14-$I14),1,0)+IF(AL14=$G14,IF(AN14=$I14,2,0),0)) | AP14: 1 | AQ14: - | AR14: 0 | AS14: =IF(ISBLANK($G14)=TRUE,"",IF(SIGN(AP14-AR14)=SIGN($G14-$I14),1,0)+IF(AP14=$G14,IF(AR14=$I14,2,0),0)) | AT14: 3 | AU14: - | AV14: 2 | AW14: =IF(ISBLANK($G14)=TRUE,"",IF(SIGN(AT14-AV14)=SIGN($G14-$I14),1,0)+IF(AT14=$G14,IF(AV14=$I14,2,0),0)) | AX14: 1 | AY14: - | AZ14: 0 | BA14: =IF(ISBLANK($G14)=TRUE,"",IF(SIGN(AX14-AZ14)=SIGN($G14-$I14),1,0)+IF(AX14=$G14,IF(AZ14=$I14,2,0),0)) | BB14: 2 | BC14: - | BD14: 1 | BE14: =IF(ISBLANK($G14)=TRUE,"",IF(SIGN(BB14-BD14)=SIGN($G14-$I14),1,0)+IF(BB14=$G14,IF(BD14=$I14,2,0),0)) | BF14: 1 | BG14: - | BH14: 1 | BI14: =IF(ISBLANK($G14)=TRUE,"",IF(SIGN(BF14-BH14)=SIGN($G14-$I14),1,0)+IF(BF14=$G14,IF(BH14=$I14,2,0),0)) | BJ14: 2 | BK14: - | BL14: 1 | BM14: =IF(ISBLANK($G14)=TRUE,"",IF(SIGN(BJ14-BL14)=SIGN($G14-$I14),1,0)+IF(BJ14=$G14,IF(BL14=$I14,2,0),0)) | BN14: 1 | BO14: - | BP14: 1 | BQ14: =IF(ISBLANK($G14)=TRUE,"",IF(SIGN(BN14-BP14)=SIGN($G14-$I14),1,0)+IF(BN14=$G14,IF(BP14=$I14,2,0),0)) | BR14: 1 | BS14: - | BT14: 1 | BU14: =IF(ISBLANK($G14)=TRUE,"",IF(SIGN(BR14-BT14)=SIGN($G14-$I14),1,0)+IF(BR14=$G14,IF(BT14=$I14,2,0),0)) | BV14: 1 | BW14: - | BX14: 1 | BY14: =IF(ISBLANK($G14)=TRUE,"",IF(SIGN(BV14-BX14)=SIGN($G14-$I14),1,0)+IF(BV14=$G14,IF(BX14=$I14,2,0),0)) | BZ14: 2 | CA14: - | CB14: 0 | CC14: =IF(ISBLANK($G14)=TRUE,"",IF(SIGN(BZ14-CB14)=SIGN($G14-$I14),1,0)+IF(BZ14=$G14,IF(CB14=$I14,2,0),0)) | CD14: 1 | CE14: - | CF14: 1 | CG14: =IF(ISBLANK($G14)=TRUE,"",IF(SIGN(CD14-CF14)=SIGN($G14-$I14),1,0)+IF(CD14=$G14,IF(CF14=$I14,2,0),0)) | CH14: 2 | CI14: - | CJ14: 1 | CK14: =IF(ISBLANK($G14)=TRUE,"",IF(SIGN(CH14-CJ14)=SIGN($G14-$I14),1,0)+IF(CH14=$G14,IF(CJ14=$I14,2,0),0)) | CL14: 1 | CM14: - | CN14: 0 | CO14: =IF(ISBLANK($G14)=TRUE,"",IF(SIGN(CL14-CN14)=SIGN($G14-$I14),1,0)+IF(CL14=$G14,IF(CN14=$I14,2,0),0)) | CP14: 1 | CQ14: - | CR14: 0 | CS14: =IF(ISBLANK($G14)=TRUE,"",IF(SIGN(CP14-CR14)=SIGN($G14-$I14),1,0)+IF(CP14=$G14,IF(CR14=$I14,2,0),0)) | CT14: 2 | CU14: - | CV14: 1 | CW14: =IF(ISBLANK($G14)=TRUE,"",IF(SIGN(CT14-CV14)=SIGN($G14-$I14),1,0)+IF(CT14=$G14,IF(CV14=$I14,2,0),0)) | CX14: 3 | CY14: - | CZ14: 0 | DA14: =IF(ISBLANK($G14)=TRUE,"",IF(SIGN(CX14-CZ14)=SIGN($G14-$I14),1,0)+IF(CX14=$G14,IF(CZ14=$I14,2,0),0)) | DB14: 3 | DC14: - | DD14: 0 | DE14: =IF(ISBLANK($G14)=TRUE,"",IF(SIGN(DB14-DD14)=SIGN($G14-$I14),1,0)+IF(DB14=$G14,IF(DD14=$I14,2,0),0)) | DF14: 1 | DG14: - | DH14: 1 | DI14: =IF(ISBLANK($G14)=TRUE,"",IF(SIGN(DF14-DH14)=SIGN($G14-$I14),1,0)+IF(DF14=$G14,IF(DH14=$I14,2,0),0))
B15: 46197 | C15: 21:00 | D15: Bosnia-Hercegovina | E15: - | F15: Qatar | H15: - | J15: 2 | K15: - | L15: 1 | M15: =IF(ISBLANK($G15)=TRUE,"",IF(SIGN(J15-L15)=SIGN($G15-$I15),1,0)+IF(J15=$G15,IF(L15=$I15,2,0),0)) | N15: 1 | O15: - | P15: 0 | Q15: =IF(ISBLANK($G15)=TRUE,"",IF(SIGN(N15-P15)=SIGN($G15-$I15),1,0)+IF(N15=$G15,IF(P15=$I15,2,0),0)) | R15: 2 | S15: - | T15: 0 | U15: =IF(ISBLANK($G15)=TRUE,"",IF(SIGN(R15-T15)=SIGN($G15-$I15),1,0)+IF(R15=$G15,IF(T15=$I15,2,0),0)) | V15: 1 | W15: - | X15: 1 | Y15: =IF(ISBLANK($G15)=TRUE,"",IF(SIGN(V15-X15)=SIGN($G15-$I15),1,0)+IF(V15=$G15,IF(X15=$I15,2,0),0)) | Z15: 1 | AA15: - | AB15: 0 | AC15: =IF(ISBLANK($G15)=TRUE,"",IF(SIGN(Z15-AB15)=SIGN($G15-$I15),1,0)+IF(Z15=$G15,IF(AB15=$I15,2,0),0)) | AD15: 1 | AE15: - | AF15: 1 | AG15: =IF(ISBLANK($G15)=TRUE,"",IF(SIGN(AD15-AF15)=SIGN($G15-$I15),1,0)+IF(AD15=$G15,IF(AF15=$I15,2,0),0)) | AH15: 2 | AI15: - | AJ15: 0 | AK15: =IF(ISBLANK($G15)=TRUE,"",IF(SIGN(AH15-AJ15)=SIGN($G15-$I15),1,0)+IF(AH15=$G15,IF(AJ15=$I15,2,0),0)) | AL15: 1 | AM15: - | AN15: 0 | AO15: =IF(ISBLANK($G15)=TRUE,"",IF(SIGN(AL15-AN15)=SIGN($G15-$I15),1,0)+IF(AL15=$G15,IF(AN15=$I15,2,0),0)) | AP15: 2 | AQ15: - | AR15: 1 | AS15: =IF(ISBLANK($G15)=TRUE,"",IF(SIGN(AP15-AR15)=SIGN($G15-$I15),1,0)+IF(AP15=$G15,IF(AR15=$I15,2,0),0)) | AT15: 2 | AU15: - | AV15: 1 | AW15: =IF(ISBLANK($G15)=TRUE,"",IF(SIGN(AT15-AV15)=SIGN($G15-$I15),1,0)+IF(AT15=$G15,IF(AV15=$I15,2,0),0)) | AX15: 0 | AY15: - | AZ15: 1 | BA15: =IF(ISBLANK($G15)=TRUE,"",IF(SIGN(AX15-AZ15)=SIGN($G15-$I15),1,0)+IF(AX15=$G15,IF(AZ15=$I15,2,0),0)) | BB15: 1 | BC15: - | BD15: 1 | BE15: =IF(ISBLANK($G15)=TRUE,"",IF(SIGN(BB15-BD15)=SIGN($G15-$I15),1,0)+IF(BB15=$G15,IF(BD15=$I15,2,0),0)) | BF15: 2 | BG15: - | BH15: 0 | BI15: =IF(ISBLANK($G15)=TRUE,"",IF(SIGN(BF15-BH15)=SIGN($G15-$I15),1,0)+IF(BF15=$G15,IF(BH15=$I15,2,0),0)) | BJ15: 1 | BK15: - | BL15: 0 | BM15: =IF(ISBLANK($G15)=TRUE,"",IF(SIGN(BJ15-BL15)=SIGN($G15-$I15),1,0)+IF(BJ15=$G15,IF(BL15=$I15,2,0),0)) | BN15: 1 | BO15: - | BP15: 0 | BQ15: =IF(ISBLANK($G15)=TRUE,"",IF(SIGN(BN15-BP15)=SIGN($G15-$I15),1,0)+IF(BN15=$G15,IF(BP15=$I15,2,0),0)) | BR15: 1 | BS15: - | BT15: 0 | BU15: =IF(ISBLANK($G15)=TRUE,"",IF(SIGN(BR15-BT15)=SIGN($G15-$I15),1,0)+IF(BR15=$G15,IF(BT15=$I15,2,0),0)) | BV15: 2 | BW15: - | BX15: 0 | BY15: =IF(ISBLANK($G15)=TRUE,"",IF(SIGN(BV15-BX15)=SIGN($G15-$I15),1,0)+IF(BV15=$G15,IF(BX15=$I15,2,0),0)) | BZ15: 1 | CA15: - | CB15: 3 | CC15: =IF(ISBLANK($G15)=TRUE,"",IF(SIGN(BZ15-CB15)=SIGN($G15-$I15),1,0)+IF(BZ15=$G15,IF(CB15=$I15,2,0),0)) | CD15: 2 | CE15: - | CF15: 1 | CG15: =IF(ISBLANK($G15)=TRUE,"",IF(SIGN(CD15-CF15)=SIGN($G15-$I15),1,0)+IF(CD15=$G15,IF(CF15=$I15,2,0),0)) | CH15: 2 | CI15: - | CJ15: 0 | CK15: =IF(ISBLANK($G15)=TRUE,"",IF(SIGN(CH15-CJ15)=SIGN($G15-$I15),1,0)+IF(CH15=$G15,IF(CJ15=$I15,2,0),0)) | CL15: 0 | CM15: - | CN15: 2 | CO15: =IF(ISBLANK($G15)=TRUE,"",IF(SIGN(CL15-CN15)=SIGN($G15-$I15),1,0)+IF(CL15=$G15,IF(CN15=$I15,2,0),0)) | CP15: 2 | CQ15: - | CR15: 1 | CS15: =IF(ISBLANK($G15)=TRUE,"",IF(SIGN(CP15-CR15)=SIGN($G15-$I15),1,0)+IF(CP15=$G15,IF(CR15=$I15,2,0),0)) | CT15: 1 | CU15: - | CV15: 0 | CW15: =IF(ISBLANK($G15)=TRUE,"",IF(SIGN(CT15-CV15)=SIGN($G15-$I15),1,0)+IF(CT15=$G15,IF(CV15=$I15,2,0),0)) | CX15: 2 | CY15: - | CZ15: 0 | DA15: =IF(ISBLANK($G15)=TRUE,"",IF(SIGN(CX15-CZ15)=SIGN($G15-$I15),1,0)+IF(CX15=$G15,IF(CZ15=$I15,2,0),0)) | DB15: 3 | DC15: - | DD15: 1 | DE15: =IF(ISBLANK($G15)=TRUE,"",IF(SIGN(DB15-DD15)=SIGN($G15-$I15),1,0)+IF(DB15=$G15,IF(DD15=$I15,2,0),0)) | DF15: 1 | DG15: - | DH15: 0 | DI15: =IF(ISBLANK($G15)=TRUE,"",IF(SIGN(DF15-DH15)=SIGN($G15-$I15),1,0)+IF(DF15=$G15,IF(DH15=$I15,2,0),0))
B16: Dato | C16: Kl. | D16: Gruppe C | G16: Resultat
B17: 46187 | C17: 00:00 | D17: Brasil | E17: - | F17: Marokko | H17: - | J17: 1 | K17: - | L17: 1 | M17: =IF(ISBLANK($I17)=TRUE,"",IF(SIGN(J17-L17)=SIGN($G17-$I17),1,0)+IF(J17=$G17,IF(L17=$I17,2,0),0)) | N17: 2 | O17: - | P17: 1 | Q17: =IF(ISBLANK($I17)=TRUE,"",IF(SIGN(N17-P17)=SIGN($G17-$I17),1,0)+IF(N17=$G17,IF(P17=$I17,2,0),0)) | R17: 2 | S17: - | T17: 1 | U17: =IF(ISBLANK($I17)=TRUE,"",IF(SIGN(R17-T17)=SIGN($G17-$I17),1,0)+IF(R17=$G17,IF(T17=$I17,2,0),0)) | V17: 2 | W17: - | X17: 2 | Y17: =IF(ISBLANK($I17)=TRUE,"",IF(SIGN(V17-X17)=SIGN($G17-$I17),1,0)+IF(V17=$G17,IF(X17=$I17,2,0),0)) | Z17: 3 | AA17: - | AB17: 1 | AC17: =IF(ISBLANK($I17)=TRUE,"",IF(SIGN(Z17-AB17)=SIGN($G17-$I17),1,0)+IF(Z17=$G17,IF(AB17=$I17,2,0),0)) | AD17: 2 | AE17: - | AF17: 1 | AG17: =IF(ISBLANK($I17)=TRUE,"",IF(SIGN(AD17-AF17)=SIGN($G17-$I17),1,0)+IF(AD17=$G17,IF(AF17=$I17,2,0),0)) | AH17: 2 | AI17: - | AJ17: 1 | AK17: =IF(ISBLANK($I17)=TRUE,"",IF(SIGN(AH17-AJ17)=SIGN($G17-$I17),1,0)+IF(AH17=$G17,IF(AJ17=$I17,2,0),0)) | AL17: 1 | AM17: - | AN17: 0 | AO17: =IF(ISBLANK($I17)=TRUE,"",IF(SIGN(AL17-AN17)=SIGN($G17-$I17),1,0)+IF(AL17=$G17,IF(AN17=$I17,2,0),0)) | AP17: 3 | AQ17: - | AR17: 1 | AS17: =IF(ISBLANK($I17)=TRUE,"",IF(SIGN(AP17-AR17)=SIGN($G17-$I17),1,0)+IF(AP17=$G17,IF(AR17=$I17,2,0),0)) | AT17: 2 | AU17: - | AV17: 0 | AW17: =IF(ISBLANK($I17)=TRUE,"",IF(SIGN(AT17-AV17)=SIGN($G17-$I17),1,0)+IF(AT17=$G17,IF(AV17=$I17,2,0),0)) | AX17: 0 | AY17: - | AZ17: 1 | BA17: =IF(ISBLANK($I17)=TRUE,"",IF(SIGN(AX17-AZ17)=SIGN($G17-$I17),1,0)+IF(AX17=$G17,IF(AZ17=$I17,2,0),0)) | BB17: 2 | BC17: - | BD17: 2 | BE17: =IF(ISBLANK($I17)=TRUE,"",IF(SIGN(BB17-BD17)=SIGN($G17-$I17),1,0)+IF(BB17=$G17,IF(BD17=$I17,2,0),0)) | BF17: 2 | BG17: - | BH17: 2 | BI17: =IF(ISBLANK($I17)=TRUE,"",IF(SIGN(BF17-BH17)=SIGN($G17-$I17),1,0)+IF(BF17=$G17,IF(BH17=$I17,2,0),0)) | BJ17: 2 | BK17: - | BL17: 1 | BM17: =IF(ISBLANK($I17)=TRUE,"",IF(SIGN(BJ17-BL17)=SIGN($G17-$I17),1,0)+IF(BJ17=$G17,IF(BL17=$I17,2,0),0)) | BN17: 2 | BO17: - | BP17: 0 | BQ17: =IF(ISBLANK($I17)=TRUE,"",IF(SIGN(BN17-BP17)=SIGN($G17-$I17),1,0)+IF(BN17=$G17,IF(BP17=$I17,2,0),0)) | BR17: 2 | BS17: - | BT17: 1 | BU17: =IF(ISBLANK($I17)=TRUE,"",IF(SIGN(BR17-BT17)=SIGN($G17-$I17),1,0)+IF(BR17=$G17,IF(BT17=$I17,2,0),0)) | BV17: 1 | BW17: - | BX17: 1 | BY17: =IF(ISBLANK($I17)=TRUE,"",IF(SIGN(BV17-BX17)=SIGN($G17-$I17),1,0)+IF(BV17=$G17,IF(BX17=$I17,2,0),0)) | BZ17: 2 | CA17: - | CB17: 1 | CC17: =IF(ISBLANK($I17)=TRUE,"",IF(SIGN(BZ17-CB17)=SIGN($G17-$I17),1,0)+IF(BZ17=$G17,IF(CB17=$I17,2,0),0)) | CD17: 2 | CE17: - | CF17: 1 | CG17: =IF(ISBLANK($I17)=TRUE,"",IF(SIGN(CD17-CF17)=SIGN($G17-$I17),1,0)+IF(CD17=$G17,IF(CF17=$I17,2,0),0)) | CH17: 2 | CI17: - | CJ17: 1 | CK17: =IF(ISBLANK($I17)=TRUE,"",IF(SIGN(CH17-CJ17)=SIGN($G17-$I17),1,0)+IF(CH17=$G17,IF(CJ17=$I17,2,0),0)) | CL17: 3 | CM17: - | CN17: 1 | CO17: =IF(ISBLANK($I17)=TRUE,"",IF(SIGN(CL17-CN17)=SIGN($G17-$I17),1,0)+IF(CL17=$G17,IF(CN17=$I17,2,0),0)) | CP17: 2 | CQ17: - | CR17: 1 | CS17: =IF(ISBLANK($I17)=TRUE,"",IF(SIGN(CP17-CR17)=SIGN($G17-$I17),1,0)+IF(CP17=$G17,IF(CR17=$I17,2,0),0)) | CT17: 1 | CU17: - | CV17: 1 | CW17: =IF(ISBLANK($I17)=TRUE,"",IF(SIGN(CT17-CV17)=SIGN($G17-$I17),1,0)+IF(CT17=$G17,IF(CV17=$I17,2,0),0)) | CX17: 1 | CY17: - | CZ17: 1 | DA17: =IF(ISBLANK($I17)=TRUE,"",IF(SIGN(CX17-CZ17)=SIGN($G17-$I17),1,0)+IF(CX17=$G17,IF(CZ17=$I17,2,0),0)) | DB17: 3 | DC17: - | DD17: 2 | DE17: =IF(ISBLANK($I17)=TRUE,"",IF(SIGN(DB17-DD17)=SIGN($G17-$I17),1,0)+IF(DB17=$G17,IF(DD17=$I17,2,0),0)) | DF17: 1 | DG17: - | DH17: 1 | DI17: =IF(ISBLANK($I17)=TRUE,"",IF(SIGN(DF17-DH17)=SIGN($G17-$I17),1,0)+IF(DF17=$G17,IF(DH17=$I17,2,0),0))
B18: 46187 | C18: 03:00 | D18: Haiti | E18: - | F18: Skottland | H18: - | J18: 0 | K18: - | L18: 2 | M18: =IF(ISBLANK($G18)=TRUE,"",IF(SIGN(J18-L18)=SIGN($G18-$I18),1,0)+IF(J18=$G18,IF(L18=$I18,2,0),0)) | N18: 0 | O18: - | P18: 2 | Q18: =IF(ISBLANK($G18)=TRUE,"",IF(SIGN(N18-P18)=SIGN($G18-$I18),1,0)+IF(N18=$G18,IF(P18=$I18,2,0),0)) | R18: 0 | S18: - | T18: 1 | U18: =IF(ISBLANK($G18)=TRUE,"",IF(SIGN(R18-T18)=SIGN($G18-$I18),1,0)+IF(R18=$G18,IF(T18=$I18,2,0),0)) | V18: 0 | W18: - | X18: 3 | Y18: =IF(ISBLANK($G18)=TRUE,"",IF(SIGN(V18-X18)=SIGN($G18-$I18),1,0)+IF(V18=$G18,IF(X18=$I18,2,0),0)) | Z18: 0 | AA18: - | AB18: 2 | AC18: =IF(ISBLANK($G18)=TRUE,"",IF(SIGN(Z18-AB18)=SIGN($G18-$I18),1,0)+IF(Z18=$G18,IF(AB18=$I18,2,0),0)) | AD18: 1 | AE18: - | AF18: 2 | AG18: =IF(ISBLANK($G18)=TRUE,"",IF(SIGN(AD18-AF18)=SIGN($G18-$I18),1,0)+IF(AD18=$G18,IF(AF18=$I18,2,0),0)) | AH18: 0 | AI18: - | AJ18: 2 | AK18: =IF(ISBLANK($G18)=TRUE,"",IF(SIGN(AH18-AJ18)=SIGN($G18-$I18),1,0)+IF(AH18=$G18,IF(AJ18=$I18,2,0),0)) | AL18: 0 | AM18: - | AN18: 1 | AO18: =IF(ISBLANK($G18)=TRUE,"",IF(SIGN(AL18-AN18)=SIGN($G18-$I18),1,0)+IF(AL18=$G18,IF(AN18=$I18,2,0),0)) | AP18: 1 | AQ18: - | AR18: 2 | AS18: =IF(ISBLANK($G18)=TRUE,"",IF(SIGN(AP18-AR18)=SIGN($G18-$I18),1,0)+IF(AP18=$G18,IF(AR18=$I18,2,0),0)) | AT18: 1 | AU18: - | AV18: 1 | AW18: =IF(ISBLANK($G18)=TRUE,"",IF(SIGN(AT18-AV18)=SIGN($G18-$I18),1,0)+IF(AT18=$G18,IF(AV18=$I18,2,0),0)) | AX18: 1 | AY18: - | AZ18: 1 | BA18: =IF(ISBLANK($G18)=TRUE,"",IF(SIGN(AX18-AZ18)=SIGN($G18-$I18),1,0)+IF(AX18=$G18,IF(AZ18=$I18,2,0),0)) | BB18: 0 | BC18: - | BD18: 2 | BE18: =IF(ISBLANK($G18)=TRUE,"",IF(SIGN(BB18-BD18)=SIGN($G18-$I18),1,0)+IF(BB18=$G18,IF(BD18=$I18,2,0),0)) | BF18: 0 | BG18: - | BH18: 1 | BI18: =IF(ISBLANK($G18)=TRUE,"",IF(SIGN(BF18-BH18)=SIGN($G18-$I18),1,0)+IF(BF18=$G18,IF(BH18=$I18,2,0),0)) | BJ18: 1 | BK18: - | BL18: 3 | BM18: =IF(ISBLANK($G18)=TRUE,"",IF(SIGN(BJ18-BL18)=SIGN($G18-$I18),1,0)+IF(BJ18=$G18,IF(BL18=$I18,2,0),0)) | BN18: 0 | BO18: - | BP18: 2 | BQ18: =IF(ISBLANK($G18)=TRUE,"",IF(SIGN(BN18-BP18)=SIGN($G18-$I18),1,0)+IF(BN18=$G18,IF(BP18=$I18,2,0),0)) | BR18: 1 | BS18: - | BT18: 4 | BU18: =IF(ISBLANK($G18)=TRUE,"",IF(SIGN(BR18-BT18)=SIGN($G18-$I18),1,0)+IF(BR18=$G18,IF(BT18=$I18,2,0),0)) | BV18: 0 | BW18: - | BX18: 3 | BY18: =IF(ISBLANK($G18)=TRUE,"",IF(SIGN(BV18-BX18)=SIGN($G18-$I18),1,0)+IF(BV18=$G18,IF(BX18=$I18,2,0),0)) | BZ18: 0 | CA18: - | CB18: 4 | CC18: =IF(ISBLANK($G18)=TRUE,"",IF(SIGN(BZ18-CB18)=SIGN($G18-$I18),1,0)+IF(BZ18=$G18,IF(CB18=$I18,2,0),0)) | CD18: 0 | CE18: - | CF18: 2 | CG18: =IF(ISBLANK($G18)=TRUE,"",IF(SIGN(CD18-CF18)=SIGN($G18-$I18),1,0)+IF(CD18=$G18,IF(CF18=$I18,2,0),0)) | CH18: 0 | CI18: - | CJ18: 3 | CK18: =IF(ISBLANK($G18)=TRUE,"",IF(SIGN(CH18-CJ18)=SIGN($G18-$I18),1,0)+IF(CH18=$G18,IF(CJ18=$I18,2,0),0)) | CL18: 1 | CM18: - | CN18: 1 | CO18: =IF(ISBLANK($G18)=TRUE,"",IF(SIGN(CL18-CN18)=SIGN($G18-$I18),1,0)+IF(CL18=$G18,IF(CN18=$I18,2,0),0)) | CP18: 0 | CQ18: - | CR18: 3 | CS18: =IF(ISBLANK($G18)=TRUE,"",IF(SIGN(CP18-CR18)=SIGN($G18-$I18),1,0)+IF(CP18=$G18,IF(CR18=$I18,2,0),0)) | CT18: 1 | CU18: - | CV18: 2 | CW18: =IF(ISBLANK($G18)=TRUE,"",IF(SIGN(CT18-CV18)=SIGN($G18-$I18),1,0)+IF(CT18=$G18,IF(CV18=$I18,2,0),0)) | CX18: 1 | CY18: - | CZ18: 2 | DA18: =IF(ISBLANK($G18)=TRUE,"",IF(SIGN(CX18-CZ18)=SIGN($G18-$I18),1,0)+IF(CX18=$G18,IF(CZ18=$I18,2,0),0)) | DB18: 1 | DC18: - | DD18: 3 | DE18: =IF(ISBLANK($G18)=TRUE,"",IF(SIGN(DB18-DD18)=SIGN($G18-$I18),1,0)+IF(DB18=$G18,IF(DD18=$I18,2,0),0)) | DF18: 0 | DG18: - | DH18: 2 | DI18: =IF(ISBLANK($G18)=TRUE,"",IF(SIGN(DF18-DH18)=SIGN($G18-$I18),1,0)+IF(DF18=$G18,IF(DH18=$I18,2,0),0))
B19: 46193 | C19: 00:00 | D19: Skottland | E19: - | F19: Marokko | H19: - | J19: 1 | K19: - | L19: 1 | M19: =IF(ISBLANK($G19)=TRUE,"",IF(SIGN(J19-L19)=SIGN($G19-$I19),1,0)+IF(J19=$G19,IF(L19=$I19,2,0),0)) | N19: 1 | O19: - | P19: 1 | Q19: =IF(ISBLANK($G19)=TRUE,"",IF(SIGN(N19-P19)=SIGN($G19-$I19),1,0)+IF(N19=$G19,IF(P19=$I19,2,0),0)) | R19: 0 | S19: - | T19: 2 | U19: =IF(ISBLANK($G19)=TRUE,"",IF(SIGN(R19-T19)=SIGN($G19-$I19),1,0)+IF(R19=$G19,IF(T19=$I19,2,0),0)) | V19: 0 | W19: - | X19: 2 | Y19: =IF(ISBLANK($G19)=TRUE,"",IF(SIGN(V19-X19)=SIGN($G19-$I19),1,0)+IF(V19=$G19,IF(X19=$I19,2,0),0)) | Z19: 1 | AA19: - | AB19: 1 | AC19: =IF(ISBLANK($G19)=TRUE,"",IF(SIGN(Z19-AB19)=SIGN($G19-$I19),1,0)+IF(Z19=$G19,IF(AB19=$I19,2,0),0)) | AD19: 1 | AE19: - | AF19: 1 | AG19: =IF(ISBLANK($G19)=TRUE,"",IF(SIGN(AD19-AF19)=SIGN($G19-$I19),1,0)+IF(AD19=$G19,IF(AF19=$I19,2,0),0)) | AH19: 1 | AI19: - | AJ19: 1 | AK19: =IF(ISBLANK($G19)=TRUE,"",IF(SIGN(AH19-AJ19)=SIGN($G19-$I19),1,0)+IF(AH19=$G19,IF(AJ19=$I19,2,0),0)) | AL19: 0 | AM19: - | AN19: 0 | AO19: =IF(ISBLANK($G19)=TRUE,"",IF(SIGN(AL19-AN19)=SIGN($G19-$I19),1,0)+IF(AL19=$G19,IF(AN19=$I19,2,0),0)) | AP19: 0 | AQ19: - | AR19: 2 | AS19: =IF(ISBLANK($G19)=TRUE,"",IF(SIGN(AP19-AR19)=SIGN($G19-$I19),1,0)+IF(AP19=$G19,IF(AR19=$I19,2,0),0)) | AT19: 1 | AU19: - | AV19: 2 | AW19: =IF(ISBLANK($G19)=TRUE,"",IF(SIGN(AT19-AV19)=SIGN($G19-$I19),1,0)+IF(AT19=$G19,IF(AV19=$I19,2,0),0)) | AX19: 0 | AY19: - | AZ19: 2 | BA19: =IF(ISBLANK($G19)=TRUE,"",IF(SIGN(AX19-AZ19)=SIGN($G19-$I19),1,0)+IF(AX19=$G19,IF(AZ19=$I19,2,0),0)) | BB19: 0 | BC19: - | BD19: 2 | BE19: =IF(ISBLANK($G19)=TRUE,"",IF(SIGN(BB19-BD19)=SIGN($G19-$I19),1,0)+IF(BB19=$G19,IF(BD19=$I19,2,0),0)) | BF19: 0 | BG19: - | BH19: 3 | BI19: =IF(ISBLANK($G19)=TRUE,"",IF(SIGN(BF19-BH19)=SIGN($G19-$I19),1,0)+IF(BF19=$G19,IF(BH19=$I19,2,0),0)) | BJ19: 1 | BK19: - | BL19: 1 | BM19: =IF(ISBLANK($G19)=TRUE,"",IF(SIGN(BJ19-BL19)=SIGN($G19-$I19),1,0)+IF(BJ19=$G19,IF(BL19=$I19,2,0),0)) | BN19: 0 | BO19: - | BP19: 1 | BQ19: =IF(ISBLANK($G19)=TRUE,"",IF(SIGN(BN19-BP19)=SIGN($G19-$I19),1,0)+IF(BN19=$G19,IF(BP19=$I19,2,0),0)) | BR19: 1 | BS19: - | BT19: 2 | BU19: =IF(ISBLANK($G19)=TRUE,"",IF(SIGN(BR19-BT19)=SIGN($G19-$I19),1,0)+IF(BR19=$G19,IF(BT19=$I19,2,0),0)) | BV19: 1 | BW19: - | BX19: 2 | BY19: =IF(ISBLANK($G19)=TRUE,"",IF(SIGN(BV19-BX19)=SIGN($G19-$I19),1,0)+IF(BV19=$G19,IF(BX19=$I19,2,0),0)) | BZ19: 1 | CA19: - | CB19: 3 | CC19: =IF(ISBLANK($G19)=TRUE,"",IF(SIGN(BZ19-CB19)=SIGN($G19-$I19),1,0)+IF(BZ19=$G19,IF(CB19=$I19,2,0),0)) | CD19: 0 | CE19: - | CF19: 1 | CG19: =IF(ISBLANK($G19)=TRUE,"",IF(SIGN(CD19-CF19)=SIGN($G19-$I19),1,0)+IF(CD19=$G19,IF(CF19=$I19,2,0),0)) | CH19: 1 | CI19: - | CJ19: 2 | CK19: =IF(ISBLANK($G19)=TRUE,"",IF(SIGN(CH19-CJ19)=SIGN($G19-$I19),1,0)+IF(CH19=$G19,IF(CJ19=$I19,2,0),0)) | CL19: 0 | CM19: - | CN19: 2 | CO19: =IF(ISBLANK($G19)=TRUE,"",IF(SIGN(CL19-CN19)=SIGN($G19-$I19),1,0)+IF(CL19=$G19,IF(CN19=$I19,2,0),0)) | CP19: 1 | CQ19: - | CR19: 2 | CS19: =IF(ISBLANK($G19)=TRUE,"",IF(SIGN(CP19-CR19)=SIGN($G19-$I19),1,0)+IF(CP19=$G19,IF(CR19=$I19,2,0),0)) | CT19: 1 | CU19: - | CV19: 2 | CW19: =IF(ISBLANK($G19)=TRUE,"",IF(SIGN(CT19-CV19)=SIGN($G19-$I19),1,0)+IF(CT19=$G19,IF(CV19=$I19,2,0),0)) | CX19: 0 | CY19: - | CZ19: 2 | DA19: =IF(ISBLANK($G19)=TRUE,"",IF(SIGN(CX19-CZ19)=SIGN($G19-$I19),1,0)+IF(CX19=$G19,IF(CZ19=$I19,2,0),0)) | DB19: 3 | DC19: - | DD19: 0 | DE19: =IF(ISBLANK($G19)=TRUE,"",IF(SIGN(DB19-DD19)=SIGN($G19-$I19),1,0)+IF(DB19=$G19,IF(DD19=$I19,2,0),0)) | DF19: 1 | DG19: - | DH19: 2 | DI19: =IF(ISBLANK($G19)=TRUE,"",IF(SIGN(DF19-DH19)=SIGN($G19-$I19),1,0)+IF(DF19=$G19,IF(DH19=$I19,2,0),0))
B20: 46193 | C20: 02:30 | D20: Brasil | E20: - | F20: Haiti | H20: - | J20: 3 | K20: - | L20: 0 | M20: =IF(ISBLANK($G20)=TRUE,"",IF(SIGN(J20-L20)=SIGN($G20-$I20),1,0)+IF(J20=$G20,IF(L20=$I20,2,0),0)) | N20: 3 | O20: - | P20: 0 | Q20: =IF(ISBLANK($G20)=TRUE,"",IF(SIGN(N20-P20)=SIGN($G20-$I20),1,0)+IF(N20=$G20,IF(P20=$I20,2,0),0)) | R20: 4 | S20: - | T20: 0 | U20: =IF(ISBLANK($G20)=TRUE,"",IF(SIGN(R20-T20)=SIGN($G20-$I20),1,0)+IF(R20=$G20,IF(T20=$I20,2,0),0)) | V20: 3 | W20: - | X20: 0 | Y20: =IF(ISBLANK($G20)=TRUE,"",IF(SIGN(V20-X20)=SIGN($G20-$I20),1,0)+IF(V20=$G20,IF(X20=$I20,2,0),0)) | Z20: 4 | AA20: - | AB20: 0 | AC20: =IF(ISBLANK($G20)=TRUE,"",IF(SIGN(Z20-AB20)=SIGN($G20-$I20),1,0)+IF(Z20=$G20,IF(AB20=$I20,2,0),0)) | AD20: 3 | AE20: - | AF20: 0 | AG20: =IF(ISBLANK($G20)=TRUE,"",IF(SIGN(AD20-AF20)=SIGN($G20-$I20),1,0)+IF(AD20=$G20,IF(AF20=$I20,2,0),0)) | AH20: 3 | AI20: - | AJ20: 0 | AK20: =IF(ISBLANK($G20)=TRUE,"",IF(SIGN(AH20-AJ20)=SIGN($G20-$I20),1,0)+IF(AH20=$G20,IF(AJ20=$I20,2,0),0)) | AL20: 2 | AM20: - | AN20: 0 | AO20: =IF(ISBLANK($G20)=TRUE,"",IF(SIGN(AL20-AN20)=SIGN($G20-$I20),1,0)+IF(AL20=$G20,IF(AN20=$I20,2,0),0)) | AP20: 4 | AQ20: - | AR20: 2 | AS20: =IF(ISBLANK($G20)=TRUE,"",IF(SIGN(AP20-AR20)=SIGN($G20-$I20),1,0)+IF(AP20=$G20,IF(AR20=$I20,2,0),0)) | AT20: 2 | AU20: - | AV20: 0 | AW20: =IF(ISBLANK($G20)=TRUE,"",IF(SIGN(AT20-AV20)=SIGN($G20-$I20),1,0)+IF(AT20=$G20,IF(AV20=$I20,2,0),0)) | AX20: 2 | AY20: - | AZ20: 0 | BA20: =IF(ISBLANK($G20)=TRUE,"",IF(SIGN(AX20-AZ20)=SIGN($G20-$I20),1,0)+IF(AX20=$G20,IF(AZ20=$I20,2,0),0)) | BB20: 5 | BC20: - | BD20: 0 | BE20: =IF(ISBLANK($G20)=TRUE,"",IF(SIGN(BB20-BD20)=SIGN($G20-$I20),1,0)+IF(BB20=$G20,IF(BD20=$I20,2,0),0)) | BF20: 6 | BG20: - | BH20: 0 | BI20: =IF(ISBLANK($G20)=TRUE,"",IF(SIGN(BF20-BH20)=SIGN($G20-$I20),1,0)+IF(BF20=$G20,IF(BH20=$I20,2,0),0)) | BJ20: 3 | BK20: - | BL20: 0 | BM20: =IF(ISBLANK($G20)=TRUE,"",IF(SIGN(BJ20-BL20)=SIGN($G20-$I20),1,0)+IF(BJ20=$G20,IF(BL20=$I20,2,0),0)) | BN20: 3 | BO20: - | BP20: 0 | BQ20: =IF(ISBLANK($G20)=TRUE,"",IF(SIGN(BN20-BP20)=SIGN($G20-$I20),1,0)+IF(BN20=$G20,IF(BP20=$I20,2,0),0)) | BR20: 4 | BS20: - | BT20: 0 | BU20: =IF(ISBLANK($G20)=TRUE,"",IF(SIGN(BR20-BT20)=SIGN($G20-$I20),1,0)+IF(BR20=$G20,IF(BT20=$I20,2,0),0)) | BV20: 4 | BW20: - | BX20: 0 | BY20: =IF(ISBLANK($G20)=TRUE,"",IF(SIGN(BV20-BX20)=SIGN($G20-$I20),1,0)+IF(BV20=$G20,IF(BX20=$I20,2,0),0)) | BZ20: 5 | CA20: - | CB20: 0 | CC20: =IF(ISBLANK($G20)=TRUE,"",IF(SIGN(BZ20-CB20)=SIGN($G20-$I20),1,0)+IF(BZ20=$G20,IF(CB20=$I20,2,0),0)) | CD20: 4 | CE20: - | CF20: 0 | CG20: =IF(ISBLANK($G20)=TRUE,"",IF(SIGN(CD20-CF20)=SIGN($G20-$I20),1,0)+IF(CD20=$G20,IF(CF20=$I20,2,0),0)) | CH20: 5 | CI20: - | CJ20: 0 | CK20: =IF(ISBLANK($G20)=TRUE,"",IF(SIGN(CH20-CJ20)=SIGN($G20-$I20),1,0)+IF(CH20=$G20,IF(CJ20=$I20,2,0),0)) | CL20: 4 | CM20: - | CN20: 0 | CO20: =IF(ISBLANK($G20)=TRUE,"",IF(SIGN(CL20-CN20)=SIGN($G20-$I20),1,0)+IF(CL20=$G20,IF(CN20=$I20,2,0),0)) | CP20: 6 | CQ20: - | CR20: 0 | CS20: =IF(ISBLANK($G20)=TRUE,"",IF(SIGN(CP20-CR20)=SIGN($G20-$I20),1,0)+IF(CP20=$G20,IF(CR20=$I20,2,0),0)) | CT20: 3 | CU20: - | CV20: 0 | CW20: =IF(ISBLANK($G20)=TRUE,"",IF(SIGN(CT20-CV20)=SIGN($G20-$I20),1,0)+IF(CT20=$G20,IF(CV20=$I20,2,0),0)) | CX20: 4 | CY20: - | CZ20: 0 | DA20: =IF(ISBLANK($G20)=TRUE,"",IF(SIGN(CX20-CZ20)=SIGN($G20-$I20),1,0)+IF(CX20=$G20,IF(CZ20=$I20,2,0),0)) | DB20: 5 | DC20: - | DD20: 0 | DE20: =IF(ISBLANK($G20)=TRUE,"",IF(SIGN(DB20-DD20)=SIGN($G20-$I20),1,0)+IF(DB20=$G20,IF(DD20=$I20,2,0),0)) | DF20: 2 | DG20: - | DH20: 0 | DI20: =IF(ISBLANK($G20)=TRUE,"",IF(SIGN(DF20-DH20)=SIGN($G20-$I20),1,0)+IF(DF20=$G20,IF(DH20=$I20,2,0),0))
